Workbook

Sheet COVER
B2: Raise Ready
B3: Complete Financial Model — Everything
B6: HOW TO USE THIS MODEL
B8: Step 01: ASSUMPTIONS | C8: Enter all your business inputs here. Every cell with a yellow background is yours to fill in. Pre-loaded with example values — replace with your actuals.
B9: Step 02: REVENUE | C9: Driver-based revenue model. Marketplace GMV, take rate, seller subscriptions, and SaaS subscription revenue — all calculated from your assumptions.
B10: Step 03: HEADCOUNT | C10: Monthly staff costs by department, driven by start month and salary from the Assumptions tab. Add or remove roles in Assumptions section 6.
B11: Step 04: P&L | C11: Full Profit and Loss statement — revenue, COGS, headcount, and operating expenses. Generates EBITDA and net income automatically.
B12: Step 05: CASH FLOW | C12: Operating, investing and financing cash flows. Opening balance, equity rounds, and closing cash. Runway calculated automatically.
B13: Step 06: BALANCE SHEET | C13: Assets, liabilities and equity. Includes a balance check row — it should always show zero. If not, check your inputs.
B14: Step 07: KPI DASHBOARD | C14: Annual summary of every investor-relevant metric. Use this as your model output page for board packs and investor updates.
B17: COLOR CODING
B18: Yellow background + blue text | C18: Your input — enter your numbers here
B19: White background + black text | C19: Formula — calculated automatically, do not edit
B20: Green background + green text | C20: Total or cross-sheet link — auto-populated
B21: Blue shaded column | C21: Year total — sum or closing balance of the year

Sheet ASSUMPTIONS
A1: ASSUMPTIONS — All Model Inputs
A2: Yellow cells = your inputs (blue text). Replace example values with your own data. Do not edit white/green cells — these are formulas.
A4: SECTION 1 — COMPANY INFORMATION
A5: Company Name | B5: My Marketplace Ltd | C5: Your legal trading name
A6: Reporting Currency | B6: £ | C6: Currency symbol used throughout the model
A7: Model Start Month & Year | B7: Jan 2025 | C7: Text label for display — e.g. Jan 2025
A9: SECTION 2 — MARKETPLACE REVENUE DRIVERS
A10: Parameter | B10: Year 1 | C10: Year 2 | D10: Year 3 | E10: Year 4 | F10: Year 5 | G10: Source / Research Note
A11: Initial Active Buyers (Month 0 — your starting base) | B11: 500 | G11: Existing buyers before model starts. If pre-launch, enter 0.
A12: New Buyers Added — Month 1 | B12: 50 | G12: Gross new buyers in the first month. Model grows this at the rate below.
A13: Monthly New Buyer Growth Rate % | B13: 0.1 | C13: 0.1 | D13: 0.1 | E13: 0.1 | F13: 0.1 | G13: Month-on-month growth of new buyers added. 10% = compounding adds each month.
A14: Monthly Buyer Churn Rate % | B14: 0.05 | C14: 0.05 | D14: 0.05 | E14: 0.05 | F14: 0.05 | G14: % of active buyers who stop transacting each month. Marketplace avg: 3–8%.
A15: Average Order Value (£) | B15: 150 | C15: 150 | D15: 150 | E15: 150 | F15: 150 | G15: Average basket size per transaction. Source: Shopify 2024 SMB avg £140–£180.
A16: Average Orders per Active Buyer/Month | B16: 1.2 | C16: 1.2 | D16: 1.2 | E16: 1.2 | F16: 1.2 | G16: How often buyers transact. Increases with engagement and product depth.
A17: Marketplace Take Rate (% of GMV) | B17: 0.15 | C17: 0.15 | D17: 0.15 | E17: 0.15 | F17: 0.15 | G17: Platform commission. UK marketplaces avg 12–20%. Indeed Flex: ~18%.
A18: Initial Active Sellers (Month 0) | B18: 50 | G18: Sellers listed on platform at model start.
A19: New Sellers Added — Month 1 | B19: 8 | G19: Gross new sellers in month 1.
A20: Monthly Seller Growth Rate % | B20: 0.08 | C20: 0.08 | D20: 0.08 | E20: 0.08 | F20: 0.08 | G20: Month-on-month growth of new sellers added.
A21: Monthly Seller Churn Rate % | B21: 0.03 | C21: 0.03 | D21: 0.03 | E21: 0.03 | F21: 0.03 | G21: % of active sellers who leave each month.
A22: Seller Monthly Subscription Fee (£) | B22: 50 | C22: 50 | D22: 50 | E22: 50 | F22: 50 | G22: If you charge sellers a SaaS fee to list. Enter 0 if marketplace-only model.
A23: SECTION 3 — SAAS SUBSCRIPTION REVENUE
A25: Initial SaaS Subscribers (Month 0) | B25: 20 | G25: Existing paying SaaS subscribers at model start.
A26: New Subscribers Added — Month 1 | B26: 5 | G26: New paying SaaS subscribers in month 1.
A27: Monthly New Subscriber Growth Rate % | B27: 0.15 | C27: 0.15 | D27: 0.15 | E27: 0.15 | F27: 0.15 | G27: Month-on-month growth of new SaaS subscribers. 15% = aggressive early-stage growth.
A28: Monthly SaaS Subscriber Churn Rate % | B28: 0.02 | C28: 0.02 | D28: 0.02 | E28: 0.02 | F28: 0.02 | G28: % of SaaS subscribers who cancel each month. World-class = <1%. Good = <2%.
A29: Monthly ARPU — SaaS (£) | B29: 299 | C29: 299 | D29: 299 | E29: 299 | F29: 299 | G29: Average monthly revenue per SaaS subscriber. Check vs your pricing tiers.
A31: SECTION 4 — UNIT ECONOMICS
A33: CAC — Paid Channel (£ per customer) | B33: 80 | C33: 80 | D33: 80 | E33: 80 | F33: 80 | G33: Fully loaded cost to acquire 1 customer via paid ads/sales. Include agency fees.
A34: CAC — Organic / Content (£ per customer) | B34: 20 | C34: 20 | D34: 20 | E34: 20 | F34: 20 | G34: Cost per customer via SEO/content/referral. Include team time.
A35: % of New Customers from Paid Channel | B35: 0.6 | C35: 0.6 | D35: 0.6 | E35: 0.6 | F35: 0.6 | G35: Split between paid and organic acquisition.
A36: Blended CAC (£) — calculated | B36: =ASSUMPTIONS!$B$33*ASSUMPTIONS!$B$35+ASSUMPTIONS!$B$34*(1-ASSUMPTIONS!$B$35) -> 56 | C36: =C33*C35+C34*(1-C35) -> 56 | D36: =D33*D35+D34*(1-D35) -> 56 | E36: =E33*E35+E34*(1-E35) -> 56 | F36: =F33*F35+F34*(1-F35) -> 56
A38: SECTION 5 — COST OF GOODS SOLD (COGS)
A39: Payment Processing Fee (% of GMV) | B39: 0.02 | C39: 0.02 | D39: 0.02 | E39: 0.02 | F39: 0.02 | G39: Stripe/Adyen/Checkout typically 1.4–2.5% + fixed. Model as % of GMV.
A40: Cloud / Infrastructure — Fixed (£/mo) | B40: 2000 | C40: 2000 | D40: 2000 | E40: 2000 | F40: 2000 | G40: Fixed monthly server/cloud cost at current scale. AWS/GCP/Azure baseline.
A41: Infrastructure Variable (£ per 1k transactions) | B41: 50 | C41: 50 | D41: 50 | E41: 50 | F41: 50 | G41: Variable cloud cost per 1,000 transactions processed.
A42: Customer Support Cost (£ per 100 active users/mo) | B42: 500 | C42: 500 | D42: 500 | E42: 500 | F42: 500 | G42: Combined marketplace buyers + sellers support cost per 100 active.
A43: Fraud & Risk Cost (% of GMV) | B43: 0.002 | C43: 0.002 | D43: 0.002 | E43: 0.002 | F43: 0.002 | G43: Chargebacks, fraud losses, risk ops. Typical range: 0.1–0.5% of GMV.
A45: SECTION 6 — HEADCOUNT PLAN
A46: Role / Position | B46: Department | C46: Start Month # | D46: Monthly Salary (£) | E46: Notes
A47: CTO / Head of Engineering | B47: Engineering | C47: 1 | D47: 9000 | E47: Replace with your hire plan
...

Sheet REVENUE
A1: REVENUE MODEL — Marketplace + SaaS
A2: Driver-based model. All inputs flow from ASSUMPTIONS tab. White cells = formulas (do not edit).
B4: YEAR 1 | N4: Y1 | O4: YEAR 2 | AA4: Y2 | AB4: YEAR 3 | AN4: Y3 | AO4: YEAR 4 | BA4: Y4 | BB4: YEAR 5 | BN4: Y5
B5: Jan | C5: Feb | D5: Mar | E5: Apr | F5: May | G5: Jun | H5: Jul | I5: Aug | J5: Sep | K5: Oct | L5: Nov | M5: Dec | N5: Y1 Total | O5: Jan | P5: Feb | Q5: Mar | R5: Apr | S5: May | T5: Jun | U5: Jul | V5: Aug | W5: Sep | X5: Oct | Y5: Nov | Z5: Dec | AA5: Y2 Total | AB5: Jan | AC5: Feb | AD5: Mar | AE5: Apr | AF5: May | AG5: Jun | AH5: Jul | AI5: Aug | AJ5: Sep | AK5: Oct | AL5: Nov | AM5: Dec | AN5: Y3 Total | AO5: Jan | AP5: Feb | AQ5: Mar | AR5: Apr | AS5: May | AT5: Jun | AU5: Jul | AV5: Aug | AW5: Sep | AX5: Oct | AY5: Nov | AZ5: Dec | BA5: Y4 Total | BB5: Jan | BC5: Feb | BD5: Mar | BE5: Apr | BF5: May | BG5: Jun | BH5: Jul | BI5: Aug | BJ5: Sep | BK5: Oct | BL5: Nov | BM5: Dec | BN5: Y5 Total
A6: MARKETPLACE — BUYERS & SELLERS
A7: New Buyers Added | B7: =IFERROR(ASSUMPTIONS!$B$12,0) -> 50 | C7: =IFERROR(ROUND(B7*(1+ASSUMPTIONS!$B$13),0),0) -> 55 | D7: =IFERROR(ROUND(C7*(1+ASSUMPTIONS!$B$13),0),0) -> 61 | E7: =IFERROR(ROUND(D7*(1+ASSUMPTIONS!$B$13),0),0) -> 67 | F7: =IFERROR(ROUND(E7*(1+ASSUMPTIONS!$B$13),0),0) -> 74 | G7: =IFERROR(ROUND(F7*(1+ASSUMPTIONS!$B$13),0),0) -> 81 | H7: =IFERROR(ROUND(G7*(1+ASSUMPTIONS!$B$13),0),0) -> 89 | I7: =IFERROR(ROUND(H7*(1+ASSUMPTIONS!$B$13),0),0) -> 98 | J7: =IFERROR(ROUND(I7*(1+ASSUMPTIONS!$B$13),0),0) -> 108 | ... M7: =IFERROR(ROUND(L7*(1+ASSUMPTIONS!$B$13),0),0) -> 144 | N7: =SUM(B7:M7) -> 1077 | O7: =IFERROR(ROUND(M7*(1+ASSUMPTIONS!$C$13),0),0) -> 158 | P7: =IFERROR(ROUND(O7*(1+ASSUMPTIONS!$C$13),0),0) -> 174 | Q7: =IFERROR(ROUND(P7*(1+ASSUMPTIONS!$C$13),0),0) -> 191 | R7: =IFERROR(ROUND(Q7*(1+ASSUMPTIONS!$C$13),0),0) -> 210 | S7: =IFERROR(ROUND(R7*(1+ASSUMPTIONS!$C$13),0),0) -> 231 | T7: =IFERROR(ROUND(S7*(1+ASSUMPTIONS!$C$13),0),0) -> 254 | U7: =IFERROR(ROUND(T7*(1+ASSUMPTIONS!$C$13),0),0) -> 279 | V7: =IFERROR(ROUND(U7*(1+ASSUMPTIONS!$C$13),0),0) -> 307 | W7: =IFERROR(ROUND(V7*(1+ASSUMPTIONS!$C$13),0),0) -> 338 | ... Z7: =IFERROR(ROUND(Y7*(1+ASSUMPTIONS!$C$13),0),0) -> 450 | AA7: =SUM(O7:Z7) -> 3373 | AB7: =IFERROR(ROUND(Z7*(1+ASSUMPTIONS!$D$13),0),0) -> 495 | AC7: =IFERROR(ROUND(AB7*(1+ASSUMPTIONS!$D$13),0),0) -> 545 | AD7: =IFERROR(ROUND(AC7*(1+ASSUMPTIONS!$D$13),0),0) -> 600 | AE7: =IFERROR(ROUND(AD7*(1+ASSUMPTIONS!$D$13),0),0) -> 660 | AF7: =IFERROR(ROUND(AE7*(1+ASSUMPTIONS!$D$13),0),0) -> 726 | AG7: =IFERROR(ROUND(AF7*(1+ASSUMPTIONS!$D$13),0),0) -> 799 | AH7: =IFERROR(ROUND(AG7*(1+ASSUMPTIONS!$D$13),0),0) -> 879 | AI7: =IFERROR(ROUND(AH7*(1+ASSUMPTIONS!$D$13),0),0) -> 967 | AJ7: =IFERROR(ROUND(AI7*(1+ASSUMPTIONS!$D$13),0),0) -> 1064 | ... AM7: =IFERROR(ROUND(AL7*(1+ASSUMPTIONS!$D$13),0),0) -> 1416 | AN7: =SUM(AB7:AM7) -> 10608 | AO7: =IFERROR(ROUND(AM7*(1+ASSUMPTIONS!$E$13),0),0) -> 1558 | AP7: =IFERROR(ROUND(AO7*(1+ASSUMPTIONS!$E$13),0),0) -> 1714 | AQ7: =IFERROR(ROUND(AP7*(1+ASSUMPTIONS!$E$13),0),0) -> 1885 | AR7: =IFERROR(ROUND(AQ7*(1+ASSUMPTIONS!$E$13),0),0) -> 2074 | AS7: =IFERROR(ROUND(AR7*(1+ASSUMPTIONS!$E$13),0),0) -> 2281 | AT7: =IFERROR(ROUND(AS7*(1+ASSUMPTIONS!$E$13),0),0) -> 2509 | AU7: =IFERROR(ROUND(AT7*(1+ASSUMPTIONS!$E$13),0),0) -> 2760 | AV7: =IFERROR(ROUND(AU7*(1+ASSUMPTIONS!$E$13),0),0) -> 3036 | AW7: =IFERROR(ROUND(AV7*(1+ASSUMPTIONS!$E$13),0),0) -> 3340 | ... AZ7: =IFERROR(ROUND(AY7*(1+ASSUMPTIONS!$E$13),0),0) -> 4445 | BA7: =SUM(AO7:AZ7) -> 33317 | BB7: =IFERROR(ROUND(AZ7*(1+ASSUMPTIONS!$F$13),0),0) -> 4890 | BC7: =IFERROR(ROUND(BB7*(1+ASSUMPTIONS!$F$13),0),0) -> 5379 | BD7: =IFERROR(ROUND(BC7*(1+ASSUMPTIONS!$F$13),0),0) -> 5917 | BE7: =IFERROR(ROUND(BD7*(1+ASSUMPTIONS!$F$13),0),0) -> 6509 | BF7: =IFERROR(ROUND(BE7*(1+ASSUMPTIONS!$F$13),0),0) -> 7160 | BG7: =IFERROR(ROUND(BF7*(1+ASSUMPTIONS!$F$13),0),0) -> 7876 | BH7: =IFERROR(ROUND(BG7*(1+ASSUMPTIONS!$F$13),0),0) -> 8664 | BI7: =IFERROR(ROUND(BH7*(1+ASSUMPTIONS!$F$13),0),0) -> 9530 | BJ7: =IFERROR(ROUND(BI7*(1+ASSUMPTIONS!$F$13),0),0) -> 10483 | ... BM7: =IFERROR(ROUND(BL7*(1+ASSUMPTIONS!$F$13),0),0) -> 13952 | BN7: =SUM(BB7:BM7) -> 104575
A8: Buyers Churned | B8: =IFERROR(ROUND(ASSUMPTIONS!$B$11*ASSUMPTIONS!$B$14,0),0) -> 25 | C8: =IFERROR(ROUND(B9*ASSUMPTIONS!$B$14,0),0) -> 26 | D8: =IFERROR(ROUND(C9*ASSUMPTIONS!$B$14,0),0) -> 28 | E8: =IFERROR(ROUND(D9*ASSUMPTIONS!$B$14,0),0) -> 29 | F8: =IFERROR(ROUND(E9*ASSUMPTIONS!$B$14,0),0) -> 31 | G8: =IFERROR(ROUND(F9*ASSUMPTIONS!$B$14,0),0) -> 33 | H8: =IFERROR(ROUND(G9*ASSUMPTIONS!$B$14,0),0) -> 36 | I8: =IFERROR(ROUND(H9*ASSUMPTIONS!$B$14,0),0) -> 38 | J8: =IFERROR(ROUND(I9*ASSUMPTIONS!$B$14,0),0) -> 41 | ... M8: =IFERROR(ROUND(L9*ASSUMPTIONS!$B$14,0),0) -> 53 | N8: =SUM(B8:M8) -> 434 | O8: =IFERROR(ROUND(M9*ASSUMPTIONS!$C$14,0),0) -> 57 | P8: =IFERROR(ROUND(O9*ASSUMPTIONS!$C$14,0),0) -> 62 | Q8: =IFERROR(ROUND(P9*ASSUMPTIONS!$C$14,0),0) -> 68 | R8: =IFERROR(ROUND(Q9*ASSUMPTIONS!$C$14,0),0) -> 74 | S8: =IFERROR(ROUND(R9*ASSUMPTIONS!$C$14,0),0) -> 81 | T8: =IFERROR(ROUND(S9*ASSUMPTIONS!$C$14,0),0) -> 88 | U8: =IFERROR(ROUND(T9*ASSUMPTIONS!$C$14,0),0) -> 97 | V8: =IFERROR(ROUND(U9*ASSUMPTIONS!$C$14,0),0) -> 106 | W8: =IFERROR(ROUND(V9*ASSUMPTIONS!$C$14,0),0) -> 116 | ... Z8: =IFERROR(ROUND(Y9*ASSUMPTIONS!$C$14,0),0) -> 153 | AA8: =SUM(O8:Z8) -> 1168 | AB8: =IFERROR(ROUND(Z9*ASSUMPTIONS!$D$14,0),0) -> 167 | AC8: =IFERROR(ROUND(AB9*ASSUMPTIONS!$D$14,0),0) -> 184 | AD8: =IFERROR(ROUND(AC9*ASSUMPTIONS!$D$14,0),0) -> 202 | AE8: =IFERROR(ROUND(AD9*ASSUMPTIONS!$D$14,0),0) -> 222 | AF8: =IFERROR(ROUND(AE9*ASSUMPTIONS!$D$14,0),0) -> 244 | AG8: =IFERROR(ROUND(AF9*ASSUMPTIONS!$D$14,0),0) -> 268 | AH8: =IFERROR(ROUND(AG9*ASSUMPTIONS!$D$14,0),0) -> 294 | AI8: =IFERROR(ROUND(AH9*ASSUMPTIONS!$D$14,0),0) -> 324 | AJ8: =IFERROR(ROUND(AI9*ASSUMPTIONS!$D$14,0),0) -> 356 | ... AM8: =IFERROR(ROUND(AL9*ASSUMPTIONS!$D$14,0),0) -> 473 | AN8: =SUM(AB8:AM8) -> 3555 | AO8: =IFERROR(ROUND(AM9*ASSUMPTIONS!$E$14,0),0) -> 520 | AP8: =IFERROR(ROUND(AO9*ASSUMPTIONS!$E$14,0),0) -> 572 | AQ8: =IFERROR(ROUND(AP9*ASSUMPTIONS!$E$14,0),0) -> 629 | AR8: =IFERROR(ROUND(AQ9*ASSUMPTIONS!$E$14,0),0) -> 692 | AS8: =IFERROR(ROUND(AR9*ASSUMPTIONS!$E$14,0),0) -> 761 | AT8: =IFERROR(ROUND(AS9*ASSUMPTIONS!$E$14,0),0) -> 837 | AU8: =IFERROR(ROUND(AT9*ASSUMPTIONS!$E$14,0),0) -> 921 | AV8: =IFERROR(ROUND(AU9*ASSUMPTIONS!$E$14,0),0) -> 1013 | AW8: =IFERROR(ROUND(AV9*ASSUMPTIONS!$E$14,0),0) -> 1114 | ... AZ8: =IFERROR(ROUND(AY9*ASSUMPTIONS!$E$14,0),0) -> 1482 | BA8: =SUM(AO8:AZ8) -> 11113 | BB8: =IFERROR(ROUND(AZ9*ASSUMPTIONS!$F$14,0),0) -> 1630 | BC8: =IFERROR(ROUND(BB9*ASSUMPTIONS!$F$14,0),0) -> 1793 | BD8: =IFERROR(ROUND(BC9*ASSUMPTIONS!$F$14,0),0) -> 1973 | BE8: =IFERROR(ROUND(BD9*ASSUMPTIONS!$F$14,0),0) -> 2170 | BF8: =IFERROR(ROUND(BE9*ASSUMPTIONS!$F$14,0),0) -> 2387 | BG8: =IFERROR(ROUND(BF9*ASSUMPTIONS!$F$14,0),0) -> 2625 | BH8: =IFERROR(ROUND(BG9*ASSUMPTIONS!$F$14,0),0) -> 2888 | BI8: =IFERROR(ROUND(BH9*ASSUMPTIONS!$F$14,0),0) -> 3177 | BJ8: =IFERROR(ROUND(BI9*ASSUMPTIONS!$F$14,0),0) -> 3494 | ... BM8: =IFERROR(ROUND(BL9*ASSUMPTIONS!$F$14,0),0) -> 4651 | BN8: =SUM(BB8:BM8) -> 34860
A9: Active Buyers — End of Month | B9: =IFERROR(MAX(0,ASSUMPTIONS!$B$11+B7-B8),0) -> 525 | C9: =IFERROR(MAX(0,B9+C7-C8),0) -> 554 | D9: =IFERROR(MAX(0,C9+D7-D8),0) -> 587 | E9: =IFERROR(MAX(0,D9+E7-E8),0) -> 625 | F9: =IFERROR(MAX(0,E9+F7-F8),0) -> 668 | G9: =IFERROR(MAX(0,F9+G7-G8),0) -> 716 | H9: =IFERROR(MAX(0,G9+H7-H8),0) -> 769 | I9: =IFERROR(MAX(0,H9+I7-I8),0) -> 829 | J9: =IFERROR(MAX(0,I9+J7-J8),0) -> 896 | ... M9: =IFERROR(MAX(0,L9+M7-M8),0) -> 1143 | N9: =M9 -> 1143 | O9: =IFERROR(MAX(0,M9+O7-O8),0) -> 1244 | P9: =IFERROR(MAX(0,O9+P7-P8),0) -> 1356 | Q9: =IFERROR(MAX(0,P9+Q7-Q8),0) -> 1479 | R9: =IFERROR(MAX(0,Q9+R7-R8),0) -> 1615 | S9: =IFERROR(MAX(0,R9+S7-S8),0) -> 1765 | T9: =IFERROR(MAX(0,S9+T7-T8),0) -> 1931 | U9: =IFERROR(MAX(0,T9+U7-U8),0) -> 2113 | V9: =IFERROR(MAX(0,U9+V7-V8),0) -> 2314 | W9: =IFERROR(MAX(0,V9+W7-W8),0) -> 2536 | ... Z9: =IFERROR(MAX(0,Y9+Z7-Z8),0) -> 3348 | AA9: =Z9 -> 3348 | AB9: =IFERROR(MAX(0,Z9+AB7-AB8),0) -> 3676 | AC9: =IFERROR(MAX(0,AB9+AC7-AC8),0) -> 4037 | AD9: =IFERROR(MAX(0,AC9+AD7-AD8),0) -> 4435 | AE9: =IFERROR(MAX(0,AD9+AE7-AE8),0) -> 4873 | AF9: =IFERROR(MAX(0,AE9+AF7-AF8),0) -> 5355 | AG9: =IFERROR(MAX(0,AF9+AG7-AG8),0) -> 5886 | AH9: =IFERROR(MAX(0,AG9+AH7-AH8),0) -> 6471 | AI9: =IFERROR(MAX(0,AH9+AI7-AI8),0) -> 7114 | AJ9: =IFERROR(MAX(0,AI9+AJ7-AJ8),0) -> 7822 | ... AM9: =IFERROR(MAX(0,AL9+AM7-AM8),0) -> 10401 | AN9: =AM9 -> 10401 | AO9: =IFERROR(MAX(0,AM9+AO7-AO8),0) -> 11439 | AP9: =IFERROR(MAX(0,AO9+AP7-AP8),0) -> 12581 | AQ9: =IFERROR(MAX(0,AP9+AQ7-AQ8),0) -> 13837 | AR9: =IFERROR(MAX(0,AQ9+AR7-AR8),0) -> 15219 | AS9: =IFERROR(MAX(0,AR9+AS7-AS8),0) -> 16739 | AT9: =IFERROR(MAX(0,AS9+AT7-AT8),0) -> 18411 | AU9: =IFERROR(MAX(0,AT9+AU7-AU8),0) -> 20250 | AV9: =IFERROR(MAX(0,AU9+AV7-AV8),0) -> 22273 | AW9: =IFERROR(MAX(0,AV9+AW7-AW8),0) -> 24499 | ... AZ9: =IFERROR(MAX(0,AY9+AZ7-AZ8),0) -> 32605 | BA9: =AZ9 -> 32605 | BB9: =IFERROR(MAX(0,AZ9+BB7-BB8),0) -> 35865 | BC9: =IFERROR(MAX(0,BB9+BC7-BC8),0) -> 39451 | BD9: =IFERROR(MAX(0,BC9+BD7-BD8),0) -> 43395 | BE9: =IFERROR(MAX(0,BD9+BE7-BE8),0) -> 47734 | BF9: =IFERROR(MAX(0,BE9+BF7-BF8),0) -> 52507 | BG9: =IFERROR(MAX(0,BF9+BG7-BG8),0) -> 57758 | BH9: =IFERROR(MAX(0,BG9+BH7-BH8),0) -> 63534 | BI9: =IFERROR(MAX(0,BH9+BI7-BI8),0) -> 69887 | BJ9: =IFERROR(MAX(0,BI9+BJ7-BJ8),0) -> 76876 | ... BM9: =IFERROR(MAX(0,BL9+BM7-BM8),0) -> 102320 | BN9: =BM9 -> 102320
A11: New Sellers Added | B11: =IFERROR(ASSUMPTIONS!$B$19,0) -> 8 | C11: =IFERROR(ROUND(B10*(1+ASSUMPTIONS!$B$20),0),0) -> 0 | D11: =IFERROR(ROUND(C10*(1+ASSUMPTIONS!$B$20),0),0) -> 0 | E11: =IFERROR(ROUND(D10*(1+ASSUMPTIONS!$B$20),0),0) -> 0 | F11: =IFERROR(ROUND(E10*(1+ASSUMPTIONS!$B$20),0),0) -> 0 | G11: =IFERROR(ROUND(F10*(1+ASSUMPTIONS!$B$20),0),0) -> 0 | H11: =IFERROR(ROUND(G10*(1+ASSUMPTIONS!$B$20),0),0) -> 0 | I11: =IFERROR(ROUND(H10*(1+ASSUMPTIONS!$B$20),0),0) -> 0 | J11: =IFERROR(ROUND(I10*(1+ASSUMPTIONS!$B$20),0),0) -> 0 | ... M11: =IFERROR(ROUND(L10*(1+ASSUMPTIONS!$B$20),0),0) -> 0 | N11: =SUM(B11:M11) -> 8 | O11: =IFERROR(ROUND(M10*(1+ASSUMPTIONS!$C$20),0),0) -> 0 | P11: =IFERROR(ROUND(O10*(1+ASSUMPTIONS!$C$20),0),0) -> 0 | Q11: =IFERROR(ROUND(P10*(1+ASSUMPTIONS!$C$20),0),0) -> 0 | R11: =IFERROR(ROUND(Q10*(1+ASSUMPTIONS!$C$20),0),0) -> 0 | S11: =IFERROR(ROUND(R10*(1+ASSUMPTIONS!$C$20),0),0) -> 0 | T11: =IFERROR(ROUND(S10*(1+ASSUMPTIONS!$C$20),0),0) -> 0 | U11: =IFERROR(ROUND(T10*(1+ASSUMPTIONS!$C$20),0),0) -> 0 | V11: =IFERROR(ROUND(U10*(1+ASSUMPTIONS!$C$20),0),0) -> 0 | W11: =IFERROR(ROUND(V10*(1+ASSUMPTIONS!$C$20),0),0) -> 0 | ... Z11: =IFERROR(ROUND(Y10*(1+ASSUMPTIONS!$C$20),0),0) -> 0 | AA11: =SUM(O11:Z11) -> 0 | AB11: =IFERROR(ROUND(Z10*(1+ASSUMPTIONS!$D$20),0),0) -> 0 | AC11: =IFERROR(ROUND(AB10*(1+ASSUMPTIONS!$D$20),0),0) -> 0 | AD11: =IFERROR(ROUND(AC10*(1+ASSUMPTIONS!$D$20),0),0) -> 0 | AE11: =IFERROR(ROUND(AD10*(1+ASSUMPTIONS!$D$20),0),0) -> 0 | AF11: =IFERROR(ROUND(AE10*(1+ASSUMPTIONS!$D$20),0),0) -> 0 | AG11: =IFERROR(ROUND(AF10*(1+ASSUMPTIONS!$D$20),0),0) -> 0 | AH11: =IFERROR(ROUND(AG10*(1+ASSUMPTIONS!$D$20),0),0) -> 0 | AI11: =IFERROR(ROUND(AH10*(1+ASSUMPTIONS!$D$20),0),0) -> 0 | AJ11: =IFERROR(ROUND(AI10*(1+ASSUMPTIONS!$D$20),0),0) -> 0 | ... AM11: =IFERROR(ROUND(AL10*(1+ASSUMPTIONS!$D$20),0),0) -> 0 | AN11: =SUM(AB11:AM11) -> 0 | AO11: =IFERROR(ROUND(AM10*(1+ASSUMPTIONS!$E$20),0),0) -> 0 | AP11: =IFERROR(ROUND(AO10*(1+ASSUMPTIONS!$E$20),0),0) -> 0 | AQ11: =IFERROR(ROUND(AP10*(1+ASSUMPTIONS!$E$20),0),0) -> 0 | AR11: =IFERROR(ROUND(AQ10*(1+ASSUMPTIONS!$E$20),0),0) -> 0 | AS11: =IFERROR(ROUND(AR10*(1+ASSUMPTIONS!$E$20),0),0) -> 0 | AT11: =IFERROR(ROUND(AS10*(1+ASSUMPTIONS!$E$20),0),0) -> 0 | AU11: =IFERROR(ROUND(AT10*(1+ASSUMPTIONS!$E$20),0),0) -> 0 | AV11: =IFERROR(ROUND(AU10*(1+ASSUMPTIONS!$E$20),0),0) -> 0 | AW11: =IFERROR(ROUND(AV10*(1+ASSUMPTIONS!$E$20),0),0) -> 0 | ... AZ11: =IFERROR(ROUND(AY10*(1+ASSUMPTIONS!$E$20),0),0) -> 0 | BA11: =SUM(AO11:AZ11) -> 0 | BB11: =IFERROR(ROUND(AZ10*(1+ASSUMPTIONS!$F$20),0),0) -> 0 | BC11: =IFERROR(ROUND(BB10*(1+ASSUMPTIONS!$F$20),0),0) -> 0 | BD11: =IFERROR(ROUND(BC10*(1+ASSUMPTIONS!$F$20),0),0) -> 0 | BE11: =IFERROR(ROUND(BD10*(1+ASSUMPTIONS!$F$20),0),0) -> 0 | BF11: =IFERROR(ROUND(BE10*(1+ASSUMPTIONS!$F$20),0),0) -> 0 | BG11: =IFERROR(ROUND(BF10*(1+ASSUMPTIONS!$F$20),0),0) -> 0 | BH11: =IFERROR(ROUND(BG10*(1+ASSUMPTIONS!$F$20),0),0) -> 0 | BI11: =IFERROR(ROUND(BH10*(1+ASSUMPTIONS!$F$20),0),0) -> 0 | BJ11: =IFERROR(ROUND(BI10*(1+ASSUMPTIONS!$F$20),0),0) -> 0 | ... BM11: =IFERROR(ROUND(BL10*(1+ASSUMPTIONS!$F$20),0),0) -> 0 | BN11: =SUM(BB11:BM11) -> 0
A12: Sellers Churned | B12: =IFERROR(ROUND(ASSUMPTIONS!$B$18*ASSUMPTIONS!$B$21,0),0) -> 2 | C12: =IFERROR(ROUND(B12*ASSUMPTIONS!$B$21,0),0) -> 0 | D12: =IFERROR(ROUND(C12*ASSUMPTIONS!$B$21,0),0) -> 0 | E12: =IFERROR(ROUND(D12*ASSUMPTIONS!$B$21,0),0) -> 0 | F12: =IFERROR(ROUND(E12*ASSUMPTIONS!$B$21,0),0) -> 0 | G12: =IFERROR(ROUND(F12*ASSUMPTIONS!$B$21,0),0) -> 0 | H12: =IFERROR(ROUND(G12*ASSUMPTIONS!$B$21,0),0) -> 0 | I12: =IFERROR(ROUND(H12*ASSUMPTIONS!$B$21,0),0) -> 0 | J12: =IFERROR(ROUND(I12*ASSUMPTIONS!$B$21,0),0) -> 0 | ... M12: =IFERROR(ROUND(L12*ASSUMPTIONS!$B$21,0),0) -> 0 | N12: =SUM(B12:M12) -> 2 | O12: =IFERROR(ROUND(M12*ASSUMPTIONS!$C$21,0),0) -> 0 | P12: =IFERROR(ROUND(O12*ASSUMPTIONS!$C$21,0),0) -> 0 | Q12: =IFERROR(ROUND(P12*ASSUMPTIONS!$C$21,0),0) -> 0 | R12: =IFERROR(ROUND(Q12*ASSUMPTIONS!$C$21,0),0) -> 0 | S12: =IFERROR(ROUND(R12*ASSUMPTIONS!$C$21,0),0) -> 0 | T12: =IFERROR(ROUND(S12*ASSUMPTIONS!$C$21,0),0) -> 0 | U12: =IFERROR(ROUND(T12*ASSUMPTIONS!$C$21,0),0) -> 0 | V12: =IFERROR(ROUND(U12*ASSUMPTIONS!$C$21,0),0) -> 0 | W12: =IFERROR(ROUND(V12*ASSUMPTIONS!$C$21,0),0) -> 0 | ... Z12: =IFERROR(ROUND(Y12*ASSUMPTIONS!$C$21,0),0) -> 0 | AA12: =SUM(O12:Z12) -> 0 | AB12: =IFERROR(ROUND(Z12*ASSUMPTIONS!$D$21,0),0) -> 0 | AC12: =IFERROR(ROUND(AB12*ASSUMPTIONS!$D$21,0),0) -> 0 | AD12: =IFERROR(ROUND(AC12*ASSUMPTIONS!$D$21,0),0) -> 0 | AE12: =IFERROR(ROUND(AD12*ASSUMPTIONS!$D$21,0),0) -> 0 | AF12: =IFERROR(ROUND(AE12*ASSUMPTIONS!$D$21,0),0) -> 0 | AG12: =IFERROR(ROUND(AF12*ASSUMPTIONS!$D$21,0),0) -> 0 | AH12: =IFERROR(ROUND(AG12*ASSUMPTIONS!$D$21,0),0) -> 0 | AI12: =IFERROR(ROUND(AH12*ASSUMPTIONS!$D$21,0),0) -> 0 | AJ12: =IFERROR(ROUND(AI12*ASSUMPTIONS!$D$21,0),0) -> 0 | ... AM12: =IFERROR(ROUND(AL12*ASSUMPTIONS!$D$21,0),0) -> 0 | AN12: =SUM(AB12:AM12) -> 0 | AO12: =IFERROR(ROUND(AM12*ASSUMPTIONS!$E$21,0),0) -> 0 | AP12: =IFERROR(ROUND(AO12*ASSUMPTIONS!$E$21,0),0) -> 0 | AQ12: =IFERROR(ROUND(AP12*ASSUMPTIONS!$E$21,0),0) -> 0 | AR12: =IFERROR(ROUND(AQ12*ASSUMPTIONS!$E$21,0),0) -> 0 | AS12: =IFERROR(ROUND(AR12*ASSUMPTIONS!$E$21,0),0) -> 0 | AT12: =IFERROR(ROUND(AS12*ASSUMPTIONS!$E$21,0),0) -> 0 | AU12: =IFERROR(ROUND(AT12*ASSUMPTIONS!$E$21,0),0) -> 0 | AV12: =IFERROR(ROUND(AU12*ASSUMPTIONS!$E$21,0),0) -> 0 | AW12: =IFERROR(ROUND(AV12*ASSUMPTIONS!$E$21,0),0) -> 0 | ... AZ12: =IFERROR(ROUND(AY12*ASSUMPTIONS!$E$21,0),0) -> 0 | BA12: =SUM(AO12:AZ12) -> 0 | BB12: =IFERROR(ROUND(AZ12*ASSUMPTIONS!$F$21,0),0) -> 0 | BC12: =IFERROR(ROUND(BB12*ASSUMPTIONS!$F$21,0),0) -> 0 | BD12: =IFERROR(ROUND(BC12*ASSUMPTIONS!$F$21,0),0) -> 0 | BE12: =IFERROR(ROUND(BD12*ASSUMPTIONS!$F$21,0),0) -> 0 | BF12: =IFERROR(ROUND(BE12*ASSUMPTIONS!$F$21,0),0) -> 0 | BG12: =IFERROR(ROUND(BF12*ASSUMPTIONS!$F$21,0),0) -> 0 | BH12: =IFERROR(ROUND(BG12*ASSUMPTIONS!$F$21,0),0) -> 0 | BI12: =IFERROR(ROUND(BH12*ASSUMPTIONS!$F$21,0),0) -> 0 | BJ12: =IFERROR(ROUND(BI12*ASSUMPTIONS!$F$21,0),0) -> 0 | ... BM12: =IFERROR(ROUND(BL12*ASSUMPTIONS!$F$21,0),0) -> 0 | BN12: =SUM(BB12:BM12) -> 0
A13: Active Sellers — End of Month | B13: =IFERROR(MAX(0,ASSUMPTIONS!$B$18+B10-B11),0) -> 42 | C13: =IFERROR(MAX(0,B12+C10-C11),0) -> 2 | D13: =IFERROR(MAX(0,C12+D10-D11),0) -> 0 | E13: =IFERROR(MAX(0,D12+E10-E11),0) -> 0 | F13: =IFERROR(MAX(0,E12+F10-F11),0) -> 0 | G13: =IFERROR(MAX(0,F12+G10-G11),0) -> 0 | H13: =IFERROR(MAX(0,G12+H10-H11),0) -> 0 | I13: =IFERROR(MAX(0,H12+I10-I11),0) -> 0 | J13: =IFERROR(MAX(0,I12+J10-J11),0) -> 0 | ... M13: =IFERROR(MAX(0,L12+M10-M11),0) -> 0 | N13: =M13 -> 0 | O13: =IFERROR(MAX(0,M12+O10-O11),0) -> 0 | P13: =IFERROR(MAX(0,O12+P10-P11),0) -> 0 | Q13: =IFERROR(MAX(0,P12+Q10-Q11),0) -> 0 | R13: =IFERROR(MAX(0,Q12+R10-R11),0) -> 0 | S13: =IFERROR(MAX(0,R12+S10-S11),0) -> 0 | T13: =IFERROR(MAX(0,S12+T10-T11),0) -> 0 | U13: =IFERROR(MAX(0,T12+U10-U11),0) -> 0 | V13: =IFERROR(MAX(0,U12+V10-V11),0) -> 0 | W13: =IFERROR(MAX(0,V12+W10-W11),0) -> 0 | ... Z13: =IFERROR(MAX(0,Y12+Z10-Z11),0) -> 0 | AA13: =Z13 -> 0 | AB13: =IFERROR(MAX(0,Z12+AB10-AB11),0) -> 0 | AC13: =IFERROR(MAX(0,AB12+AC10-AC11),0) -> 0 | AD13: =IFERROR(MAX(0,AC12+AD10-AD11),0) -> 0 | AE13: =IFERROR(MAX(0,AD12+AE10-AE11),0) -> 0 | AF13: =IFERROR(MAX(0,AE12+AF10-AF11),0) -> 0 | AG13: =IFERROR(MAX(0,AF12+AG10-AG11),0) -> 0 | AH13: =IFERROR(MAX(0,AG12+AH10-AH11),0) -> 0 | AI13: =IFERROR(MAX(0,AH12+AI10-AI11),0) -> 0 | AJ13: =IFERROR(MAX(0,AI12+AJ10-AJ11),0) -> 0 | ... AM13: =IFERROR(MAX(0,AL12+AM10-AM11),0) -> 0 | AN13: =AM13 -> 0 | AO13: =IFERROR(MAX(0,AM12+AO10-AO11),0) -> 0 | AP13: =IFERROR(MAX(0,AO12+AP10-AP11),0) -> 0 | AQ13: =IFERROR(MAX(0,AP12+AQ10-AQ11),0) -> 0 | AR13: =IFERROR(MAX(0,AQ12+AR10-AR11),0) -> 0 | AS13: =IFERROR(MAX(0,AR12+AS10-AS11),0) -> 0 | AT13: =IFERROR(MAX(0,AS12+AT10-AT11),0) -> 0 | AU13: =IFERROR(MAX(0,AT12+AU10-AU11),0) -> 0 | AV13: =IFERROR(MAX(0,AU12+AV10-AV11),0) -> 0 | AW13: =IFERROR(MAX(0,AV12+AW10-AW11),0) -> 0 | ... AZ13: =IFERROR(MAX(0,AY12+AZ10-AZ11),0) -> 0 | BA13: =AZ13 -> 0 | BB13: =IFERROR(MAX(0,AZ12+BB10-BB11),0) -> 0 | BC13: =IFERROR(MAX(0,BB12+BC10-BC11),0) -> 0 | BD13: =IFERROR(MAX(0,BC12+BD10-BD11),0) -> 0 | BE13: =IFERROR(MAX(0,BD12+BE10-BE11),0) -> 0 | BF13: =IFERROR(MAX(0,BE12+BF10-BF11),0) -> 0 | BG13: =IFERROR(MAX(0,BF12+BG10-BG11),0) -> 0 | BH13: =IFERROR(MAX(0,BG12+BH10-BH11),0) -> 0 | BI13: =IFERROR(MAX(0,BH12+BI10-BI11),0) -> 0 | BJ13: =IFERROR(MAX(0,BI12+BJ10-BJ11),0) -> 0 | ... BM13: =IFERROR(MAX(0,BL12+BM10-BM11),0) -> 0 | BN13: =BM13 -> 0
A15: MARKETPLACE REVENUE
A16: Gross Merchandise Value — GMV (£) | B16: =IFERROR(B9*ASSUMPTIONS!$B$16*ASSUMPTIONS!$B$15,0) -> 94500 | C16: =IFERROR(C9*ASSUMPTIONS!$B$16*ASSUMPTIONS!$B$15,0) -> 99720 | D16: =IFERROR(D9*ASSUMPTIONS!$B$16*ASSUMPTIONS!$B$15,0) -> 105660 | E16: =IFERROR(E9*ASSUMPTIONS!$B$16*ASSUMPTIONS!$B$15,0) -> 112500 | F16: =IFERROR(F9*ASSUMPTIONS!$B$16*ASSUMPTIONS!$B$15,0) -> 120240 | G16: =IFERROR(G9*ASSUMPTIONS!$B$16*ASSUMPTIONS!$B$15,0) -> 128880 | H16: =IFERROR(H9*ASSUMPTIONS!$B$16*ASSUMPTIONS!$B$15,0) -> 138420 | I16: =IFERROR(I9*ASSUMPTIONS!$B$16*ASSUMPTIONS!$B$15,0) -> 149220 | ... M16: =IFERROR(M9*ASSUMPTIONS!$B$16*ASSUMPTIONS!$B$15,0) -> 205740 | N16: =SUM(B16:M16) -> 1680120 | O16: =IFERROR(O9*ASSUMPTIONS!$C$16*ASSUMPTIONS!$C$15,0) -> 223920 | P16: =IFERROR(P9*ASSUMPTIONS!$C$16*ASSUMPTIONS!$C$15,0) -> 244080 | Q16: =IFERROR(Q9*ASSUMPTIONS!$C$16*ASSUMPTIONS!$C$15,0) -> 266220 | R16: =IFERROR(R9*ASSUMPTIONS!$C$16*ASSUMPTIONS!$C$15,0) -> 290700 | S16: =IFERROR(S9*ASSUMPTIONS!$C$16*ASSUMPTIONS!$C$15,0) -> 317700 | T16: =IFERROR(T9*ASSUMPTIONS!$C$16*ASSUMPTIONS!$C$15,0) -> 347580 | U16: =IFERROR(U9*ASSUMPTIONS!$C$16*ASSUMPTIONS!$C$15,0) -> 380340 | V16: =IFERROR(V9*ASSUMPTIONS!$C$16*ASSUMPTIONS!$C$15,0) -> 416520 | ... Z16: =IFERROR(Z9*ASSUMPTIONS!$C$16*ASSUMPTIONS!$C$15,0) -> 602640 | AA16: =SUM(O16:Z16) -> 4595940 | AB16: =IFERROR(AB9*ASSUMPTIONS!$D$16*ASSUMPTIONS!$D$15,0) -> 661680 | AC16: =IFERROR(AC9*ASSUMPTIONS!$D$16*ASSUMPTIONS!$D$15,0) -> 726660 | AD16: =IFERROR(AD9*ASSUMPTIONS!$D$16*ASSUMPTIONS!$D$15,0) -> 798300 | AE16: =IFERROR(AE9*ASSUMPTIONS!$D$16*ASSUMPTIONS!$D$15,0) -> 877140 | AF16: =IFERROR(AF9*ASSUMPTIONS!$D$16*ASSUMPTIONS!$D$15,0) -> 963900 | AG16: =IFERROR(AG9*ASSUMPTIONS!$D$16*ASSUMPTIONS!$D$15,0) -> 1059480 | AH16: =IFERROR(AH9*ASSUMPTIONS!$D$16*ASSUMPTIONS!$D$15,0) -> 1164780 | AI16: =IFERROR(AI9*ASSUMPTIONS!$D$16*ASSUMPTIONS!$D$15,0) -> 1280520 | ... AM16: =IFERROR(AM9*ASSUMPTIONS!$D$16*ASSUMPTIONS!$D$15,0) -> 1872180 | AN16: =SUM(AB16:AM16) -> 14063220 | AO16: =IFERROR(AO9*ASSUMPTIONS!$E$16*ASSUMPTIONS!$E$15,0) -> 2059020 | AP16: =IFERROR(AP9*ASSUMPTIONS!$E$16*ASSUMPTIONS!$E$15,0) -> 2264580 | AQ16: =IFERROR(AQ9*ASSUMPTIONS!$E$16*ASSUMPTIONS!$E$15,0) -> 2490660 | AR16: =IFERROR(AR9*ASSUMPTIONS!$E$16*ASSUMPTIONS!$E$15,0) -> 2739420 | AS16: =IFERROR(AS9*ASSUMPTIONS!$E$16*ASSUMPTIONS!$E$15,0) -> 3013020 | AT16: =IFERROR(AT9*ASSUMPTIONS!$E$16*ASSUMPTIONS!$E$15,0) -> 3313980 | AU16: =IFERROR(AU9*ASSUMPTIONS!$E$16*ASSUMPTIONS!$E$15,0) -> 3645000 | AV16: =IFERROR(AV9*ASSUMPTIONS!$E$16*ASSUMPTIONS!$E$15,0) -> 4009140 | ... AZ16: =IFERROR(AZ9*ASSUMPTIONS!$E$16*ASSUMPTIONS!$E$15,0) -> 5868900 | BA16: =SUM(AO16:AZ16) -> 43999740 | BB16: =IFERROR(BB9*ASSUMPTIONS!$F$16*ASSUMPTIONS!$F$15,0) -> 6455700 | BC16: =IFERROR(BC9*ASSUMPTIONS!$F$16*ASSUMPTIONS!$F$15,0) -> 7101180 | BD16: =IFERROR(BD9*ASSUMPTIONS!$F$16*ASSUMPTIONS!$F$15,0) -> 7811100 | BE16: =IFERROR(BE9*ASSUMPTIONS!$F$16*ASSUMPTIONS!$F$15,0) -> 8592120 | BF16: =IFERROR(BF9*ASSUMPTIONS!$F$16*ASSUMPTIONS!$F$15,0) -> 9451260 | BG16: =IFERROR(BG9*ASSUMPTIONS!$F$16*ASSUMPTIONS!$F$15,0) -> 10396440 | BH16: =IFERROR(BH9*ASSUMPTIONS!$F$16*ASSUMPTIONS!$F$15,0) -> 11436120 | BI16: =IFERROR(BI9*ASSUMPTIONS!$F$16*ASSUMPTIONS!$F$15,0) -> 12579660 | ... BM16: =IFERROR(BM9*ASSUMPTIONS!$F$16*ASSUMPTIONS!$F$15,0) -> 18417600 | BN16: =SUM(BB16:BM16) -> 138043620
A17: Transaction Revenue (GMV × Take Rate) | B17: =IFERROR(B16*ASSUMPTIONS!$B$17,0) -> 14175 | C17: =IFERROR(C16*ASSUMPTIONS!$B$17,0) -> 14958 | D17: =IFERROR(D16*ASSUMPTIONS!$B$17,0) -> 15849 | E17: =IFERROR(E16*ASSUMPTIONS!$B$17,0) -> 16875 | F17: =IFERROR(F16*ASSUMPTIONS!$B$17,0) -> 18036 | G17: =IFERROR(G16*ASSUMPTIONS!$B$17,0) -> 19332 | H17: =IFERROR(H16*ASSUMPTIONS!$B$17,0) -> 20763 | I17: =IFERROR(I16*ASSUMPTIONS!$B$17,0) -> 22383 | ... M17: =IFERROR(M16*ASSUMPTIONS!$B$17,0) -> 30861 | N17: =SUM(B17:M17) -> 252018 | O17: =IFERROR(O16*ASSUMPTIONS!$C$17,0) -> 33588 | P17: =IFERROR(P16*ASSUMPTIONS!$C$17,0) -> 36612 | Q17: =IFERROR(Q16*ASSUMPTIONS!$C$17,0) -> 39933 | R17: =IFERROR(R16*ASSUMPTIONS!$C$17,0) -> 43605 | S17: =IFERROR(S16*ASSUMPTIONS!$C$17,0) -> 47655 | T17: =IFERROR(T16*ASSUMPTIONS!$C$17,0) -> 52137 | U17: =IFERROR(U16*ASSUMPTIONS!$C$17,0) -> 57051 | V17: =IFERROR(V16*ASSUMPTIONS!$C$17,0) -> 62478 | ... Z17: =IFERROR(Z16*ASSUMPTIONS!$C$17,0) -> 90396 | AA17: =SUM(O17:Z17) -> 689391 | AB17: =IFERROR(AB16*ASSUMPTIONS!$D$17,0) -> 99252 | AC17: =IFERROR(AC16*ASSUMPTIONS!$D$17,0) -> 108999 | AD17: =IFERROR(AD16*ASSUMPTIONS!$D$17,0) -> 119745 | AE17: =IFERROR(AE16*ASSUMPTIONS!$D$17,0) -> 131571 | AF17: =IFERROR(AF16*ASSUMPTIONS!$D$17,0) -> 144585 | AG17: =IFERROR(AG16*ASSUMPTIONS!$D$17,0) -> 158922 | AH17: =IFERROR(AH16*ASSUMPTIONS!$D$17,0) -> 174717 | AI17: =IFERROR(AI16*ASSUMPTIONS!$D$17,0) -> 192078 | ... AM17: =IFERROR(AM16*ASSUMPTIONS!$D$17,0) -> 280827 | AN17: =SUM(AB17:AM17) -> 2109483 | AO17: =IFERROR(AO16*ASSUMPTIONS!$E$17,0) -> 308853 | AP17: =IFERROR(AP16*ASSUMPTIONS!$E$17,0) -> 339687 | AQ17: =IFERROR(AQ16*ASSUMPTIONS!$E$17,0) -> 373599 | AR17: =IFERROR(AR16*ASSUMPTIONS!$E$17,0) -> 410913 | AS17: =IFERROR(AS16*ASSUMPTIONS!$E$17,0) -> 451953 | AT17: =IFERROR(AT16*ASSUMPTIONS!$E$17,0) -> 497097 | AU17: =IFERROR(AU16*ASSUMPTIONS!$E$17,0) -> 546750 | AV17: =IFERROR(AV16*ASSUMPTIONS!$E$17,0) -> 601371 | ... AZ17: =IFERROR(AZ16*ASSUMPTIONS!$E$17,0) -> 880335 | BA17: =SUM(AO17:AZ17) -> 6599961 | BB17: =IFERROR(BB16*ASSUMPTIONS!$F$17,0) -> 968355 | BC17: =IFERROR(BC16*ASSUMPTIONS!$F$17,0) -> 1065177 | BD17: =IFERROR(BD16*ASSUMPTIONS!$F$17,0) -> 1171665 | BE17: =IFERROR(BE16*ASSUMPTIONS!$F$17,0) -> 1288818 | BF17: =IFERROR(BF16*ASSUMPTIONS!$F$17,0) -> 1417689 | BG17: =IFERROR(BG16*ASSUMPTIONS!$F$17,0) -> 1559466 | BH17: =IFERROR(BH16*ASSUMPTIONS!$F$17,0) -> 1715418 | BI17: =IFERROR(BI16*ASSUMPTIONS!$F$17,0) -> 1886949 | ... BM17: =IFERROR(BM16*ASSUMPTIONS!$F$17,0) -> 2762640 | BN17: =SUM(BB17:BM17) -> 20706543
A18: Seller Subscription Revenue (£) | B18: =IFERROR(B13*ASSUMPTIONS!$B$22,0) -> 2100 | C18: =IFERROR(C13*ASSUMPTIONS!$B$22,0) -> 100 | D18: =IFERROR(D13*ASSUMPTIONS!$B$22,0) -> 0 | E18: =IFERROR(E13*ASSUMPTIONS!$B$22,0) -> 0 | F18: =IFERROR(F13*ASSUMPTIONS!$B$22,0) -> 0 | G18: =IFERROR(G13*ASSUMPTIONS!$B$22,0) -> 0 | H18: =IFERROR(H13*ASSUMPTIONS!$B$22,0) -> 0 | I18: =IFERROR(I13*ASSUMPTIONS!$B$22,0) -> 0 | ... M18: =IFERROR(M13*ASSUMPTIONS!$B$22,0) -> 0 | N18: =SUM(B18:M18) -> 2200 | O18: =IFERROR(O13*ASSUMPTIONS!$C$22,0) -> 0 | P18: =IFERROR(P13*ASSUMPTIONS!$C$22,0) -> 0 | Q18: =IFERROR(Q13*ASSUMPTIONS!$C$22,0) -> 0 | R18: =IFERROR(R13*ASSUMPTIONS!$C$22,0) -> 0 | S18: =IFERROR(S13*ASSUMPTIONS!$C$22,0) -> 0 | T18: =IFERROR(T13*ASSUMPTIONS!$C$22,0) -> 0 | U18: =IFERROR(U13*ASSUMPTIONS!$C$22,0) -> 0 | V18: =IFERROR(V13*ASSUMPTIONS!$C$22,0) -> 0 | ... Z18: =IFERROR(Z13*ASSUMPTIONS!$C$22,0) -> 0 | AA18: =SUM(O18:Z18) -> 0 | AB18: =IFERROR(AB13*ASSUMPTIONS!$D$22,0) -> 0 | AC18: =IFERROR(AC13*ASSUMPTIONS!$D$22,0) -> 0 | AD18: =IFERROR(AD13*ASSUMPTIONS!$D$22,0) -> 0 | AE18: =IFERROR(AE13*ASSUMPTIONS!$D$22,0) -> 0 | AF18: =IFERROR(AF13*ASSUMPTIONS!$D$22,0) -> 0 | AG18: =IFERROR(AG13*ASSUMPTIONS!$D$22,0) -> 0 | AH18: =IFERROR(AH13*ASSUMPTIONS!$D$22,0) -> 0 | AI18: =IFERROR(AI13*ASSUMPTIONS!$D$22,0) -> 0 | ... AM18: =IFERROR(AM13*ASSUMPTIONS!$D$22,0) -> 0 | AN18: =SUM(AB18:AM18) -> 0 | AO18: =IFERROR(AO13*ASSUMPTIONS!$E$22,0) -> 0 | AP18: =IFERROR(AP13*ASSUMPTIONS!$E$22,0) -> 0 | AQ18: =IFERROR(AQ13*ASSUMPTIONS!$E$22,0) -> 0 | AR18: =IFERROR(AR13*ASSUMPTIONS!$E$22,0) -> 0 | AS18: =IFERROR(AS13*ASSUMPTIONS!$E$22,0) -> 0 | AT18: =IFERROR(AT13*ASSUMPTIONS!$E$22,0) -> 0 | AU18: =IFERROR(AU13*ASSUMPTIONS!$E$22,0) -> 0 | AV18: =IFERROR(AV13*ASSUMPTIONS!$E$22,0) -> 0 | ... AZ18: =IFERROR(AZ13*ASSUMPTIONS!$E$22,0) -> 0 | BA18: =SUM(AO18:AZ18) -> 0 | BB18: =IFERROR(BB13*ASSUMPTIONS!$F$22,0) -> 0 | BC18: =IFERROR(BC13*ASSUMPTIONS!$F$22,0) -> 0 | BD18: =IFERROR(BD13*ASSUMPTIONS!$F$22,0) -> 0 | BE18: =IFERROR(BE13*ASSUMPTIONS!$F$22,0) -> 0 | BF18: =IFERROR(BF13*ASSUMPTIONS!$F$22,0) -> 0 | BG18: =IFERROR(BG13*ASSUMPTIONS!$F$22,0) -> 0 | BH18: =IFERROR(BH13*ASSUMPTIONS!$F$22,0) -> 0 | BI18: =IFERROR(BI13*ASSUMPTIONS!$F$22,0) -> 0 | ... BM18: =IFERROR(BM13*ASSUMPTIONS!$F$22,0) -> 0 | BN18: =SUM(BB18:BM18) -> 0
A19: TOTAL MARKETPLACE REVENUE (£) | B19: =IFERROR(B17+B18,0) -> 16275 | C19: =IFERROR(C17+C18,0) -> 15058 | D19: =IFERROR(D17+D18,0) -> 15849 | E19: =IFERROR(E17+E18,0) -> 16875 | F19: =IFERROR(F17+F18,0) -> 18036 | G19: =IFERROR(G17+G18,0) -> 19332 | H19: =IFERROR(H17+H18,0) -> 20763 | I19: =IFERROR(I17+I18,0) -> 22383 | ... M19: =IFERROR(M17+M18,0) -> 30861 | N19: =SUM(B19:M19) -> 254218 | O19: =IFERROR(O17+O18,0) -> 33588 | P19: =IFERROR(P17+P18,0) -> 36612 | Q19: =IFERROR(Q17+Q18,0) -> 39933 | R19: =IFERROR(R17+R18,0) -> 43605 | S19: =IFERROR(S17+S18,0) -> 47655 | T19: =IFERROR(T17+T18,0) -> 52137 | U19: =IFERROR(U17+U18,0) -> 57051 | V19: =IFERROR(V17+V18,0) -> 62478 | ... Z19: =IFERROR(Z17+Z18,0) -> 90396 | AA19: =SUM(O19:Z19) -> 689391 | AB19: =IFERROR(AB17+AB18,0) -> 99252 | AC19: =IFERROR(AC17+AC18,0) -> 108999 | AD19: =IFERROR(AD17+AD18,0) -> 119745 | AE19: =IFERROR(AE17+AE18,0) -> 131571 | AF19: =IFERROR(AF17+AF18,0) -> 144585 | AG19: =IFERROR(AG17+AG18,0) -> 158922 | AH19: =IFERROR(AH17+AH18,0) -> 174717 | AI19: =IFERROR(AI17+AI18,0) -> 192078 | ... AM19: =IFERROR(AM17+AM18,0) -> 280827 | AN19: =SUM(AB19:AM19) -> 2109483 | AO19: =IFERROR(AO17+AO18,0) -> 308853 | AP19: =IFERROR(AP17+AP18,0) -> 339687 | AQ19: =IFERROR(AQ17+AQ18,0) -> 373599 | AR19: =IFERROR(AR17+AR18,0) -> 410913 | AS19: =IFERROR(AS17+AS18,0) -> 451953 | AT19: =IFERROR(AT17+AT18,0) -> 497097 | AU19: =IFERROR(AU17+AU18,0) -> 546750 | AV19: =IFERROR(AV17+AV18,0) -> 601371 | ... AZ19: =IFERROR(AZ17+AZ18,0) -> 880335 | BA19: =SUM(AO19:AZ19) -> 6599961 | BB19: =IFERROR(BB17+BB18,0) -> 968355 | BC19: =IFERROR(BC17+BC18,0) -> 1065177 | BD19: =IFERROR(BD17+BD18,0) -> 1171665 | BE19: =IFERROR(BE17+BE18,0) -> 1288818 | BF19: =IFERROR(BF17+BF18,0) -> 1417689 | BG19: =IFERROR(BG17+BG18,0) -> 1559466 | BH19: =IFERROR(BH17+BH18,0) -> 1715418 | BI19: =IFERROR(BI17+BI18,0) -> 1886949 | ... BM19: =IFERROR(BM17+BM18,0) -> 2762640 | BN19: =SUM(BB19:BM19) -> 20706543
A21: SAAS SUBSCRIPTION REVENUE
A22: New SaaS Subscribers Added | B22: =IFERROR(ASSUMPTIONS!$B$26,0) -> 5 | C22: =IFERROR(ROUND(B22*(1+ASSUMPTIONS!$B$27),0),0) -> 6 | D22: =IFERROR(ROUND(C22*(1+ASSUMPTIONS!$B$27),0),0) -> 7 | E22: =IFERROR(ROUND(D22*(1+ASSUMPTIONS!$B$27),0),0) -> 8 | F22: =IFERROR(ROUND(E22*(1+ASSUMPTIONS!$B$27),0),0) -> 9 | G22: =IFERROR(ROUND(F22*(1+ASSUMPTIONS!$B$27),0),0) -> 10 | H22: =IFERROR(ROUND(G22*(1+ASSUMPTIONS!$B$27),0),0) -> 12 | I22: =IFERROR(ROUND(H22*(1+ASSUMPTIONS!$B$27),0),0) -> 14 | J22: =IFERROR(ROUND(I22*(1+ASSUMPTIONS!$B$27),0),0) -> 16 | ... M22: =IFERROR(ROUND(L22*(1+ASSUMPTIONS!$B$27),0),0) -> 24 | N22: =SUM(B22:M22) -> 150 | O22: =IFERROR(ROUND(M22*(1+ASSUMPTIONS!$C$27),0),0) -> 28 | P22: =IFERROR(ROUND(O22*(1+ASSUMPTIONS!$C$27),0),0) -> 32 | Q22: =IFERROR(ROUND(P22*(1+ASSUMPTIONS!$C$27),0),0) -> 37 | R22: =IFERROR(ROUND(Q22*(1+ASSUMPTIONS!$C$27),0),0) -> 43 | S22: =IFERROR(ROUND(R22*(1+ASSUMPTIONS!$C$27),0),0) -> 49 | T22: =IFERROR(ROUND(S22*(1+ASSUMPTIONS!$C$27),0),0) -> 56 | U22: =IFERROR(ROUND(T22*(1+ASSUMPTIONS!$C$27),0),0) -> 64 | V22: =IFERROR(ROUND(U22*(1+ASSUMPTIONS!$C$27),0),0) -> 74 | W22: =IFERROR(ROUND(V22*(1+ASSUMPTIONS!$C$27),0),0) -> 85 | ... Z22: =IFERROR(ROUND(Y22*(1+ASSUMPTIONS!$C$27),0),0) -> 130 | AA22: =SUM(O22:Z22) -> 809 | AB22: =IFERROR(ROUND(Z22*(1+ASSUMPTIONS!$D$27),0),0) -> 150 | AC22: =IFERROR(ROUND(AB22*(1+ASSUMPTIONS!$D$27),0),0) -> 173 | AD22: =IFERROR(ROUND(AC22*(1+ASSUMPTIONS!$D$27),0),0) -> 199 | AE22: =IFERROR(ROUND(AD22*(1+ASSUMPTIONS!$D$27),0),0) -> 229 | AF22: =IFERROR(ROUND(AE22*(1+ASSUMPTIONS!$D$27),0),0) -> 263 | AG22: =IFERROR(ROUND(AF22*(1+ASSUMPTIONS!$D$27),0),0) -> 302 | AH22: =IFERROR(ROUND(AG22*(1+ASSUMPTIONS!$D$27),0),0) -> 347 | AI22: =IFERROR(ROUND(AH22*(1+ASSUMPTIONS!$D$27),0),0) -> 399 | AJ22: =IFERROR(ROUND(AI22*(1+ASSUMPTIONS!$D$27),0),0) -> 459 | ... AM22: =IFERROR(ROUND(AL22*(1+ASSUMPTIONS!$D$27),0),0) -> 698 | AN22: =SUM(AB22:AM22) -> 4354 | AO22: =IFERROR(ROUND(AM22*(1+ASSUMPTIONS!$E$27),0),0) -> 803 | AP22: =IFERROR(ROUND(AO22*(1+ASSUMPTIONS!$E$27),0),0) -> 923 | AQ22: =IFERROR(ROUND(AP22*(1+ASSUMPTIONS!$E$27),0),0) -> 1061 | AR22: =IFERROR(ROUND(AQ22*(1+ASSUMPTIONS!$E$27),0),0) -> 1220 | AS22: =IFERROR(ROUND(AR22*(1+ASSUMPTIONS!$E$27),0),0) -> 1403 | AT22: =IFERROR(ROUND(AS22*(1+ASSUMPTIONS!$E$27),0),0) -> 1613 | AU22: =IFERROR(ROUND(AT22*(1+ASSUMPTIONS!$E$27),0),0) -> 1855 | AV22: =IFERROR(ROUND(AU22*(1+ASSUMPTIONS!$E$27),0),0) -> 2133 | AW22: =IFERROR(ROUND(AV22*(1+ASSUMPTIONS!$E$27),0),0) -> 2453 | ... AZ22: =IFERROR(ROUND(AY22*(1+ASSUMPTIONS!$E$27),0),0) -> 3731 | BA22: =SUM(AO22:AZ22) -> 23260 | BB22: =IFERROR(ROUND(AZ22*(1+ASSUMPTIONS!$F$27),0),0) -> 4291 | BC22: =IFERROR(ROUND(BB22*(1+ASSUMPTIONS!$F$27),0),0) -> 4935 | BD22: =IFERROR(ROUND(BC22*(1+ASSUMPTIONS!$F$27),0),0) -> 5675 | BE22: =IFERROR(ROUND(BD22*(1+ASSUMPTIONS!$F$27),0),0) -> 6526 | BF22: =IFERROR(ROUND(BE22*(1+ASSUMPTIONS!$F$27),0),0) -> 7505 | BG22: =IFERROR(ROUND(BF22*(1+ASSUMPTIONS!$F$27),0),0) -> 8631 | BH22: =IFERROR(ROUND(BG22*(1+ASSUMPTIONS!$F$27),0),0) -> 9926 | BI22: =IFERROR(ROUND(BH22*(1+ASSUMPTIONS!$F$27),0),0) -> 11415 | BJ22: =IFERROR(ROUND(BI22*(1+ASSUMPTIONS!$F$27),0),0) -> 13127 | ... BM22: =IFERROR(ROUND(BL22*(1+ASSUMPTIONS!$F$27),0),0) -> 19964 | BN22: =SUM(BB22:BM22) -> 124451
A23: SaaS Subscribers Churned | B23: =IFERROR(ROUND(ASSUMPTIONS!$B$25*ASSUMPTIONS!$B$28,0),0) -> 0 | C23: =IFERROR(ROUND(B24*ASSUMPTIONS!$B$28,0),0) -> 1 | D23: =IFERROR(ROUND(C24*ASSUMPTIONS!$B$28,0),0) -> 1 | E23: =IFERROR(ROUND(D24*ASSUMPTIONS!$B$28,0),0) -> 1 | F23: =IFERROR(ROUND(E24*ASSUMPTIONS!$B$28,0),0) -> 1 | G23: =IFERROR(ROUND(F24*ASSUMPTIONS!$B$28,0),0) -> 1 | H23: =IFERROR(ROUND(G24*ASSUMPTIONS!$B$28,0),0) -> 1 | I23: =IFERROR(ROUND(H24*ASSUMPTIONS!$B$28,0),0) -> 1 | J23: =IFERROR(ROUND(I24*ASSUMPTIONS!$B$28,0),0) -> 2 | ... M23: =IFERROR(ROUND(L24*ASSUMPTIONS!$B$28,0),0) -> 3 | N23: =SUM(B23:M23) -> 16 | O23: =IFERROR(ROUND(M24*ASSUMPTIONS!$C$28,0),0) -> 3 | P23: =IFERROR(ROUND(O24*ASSUMPTIONS!$C$28,0),0) -> 4 | Q23: =IFERROR(ROUND(P24*ASSUMPTIONS!$C$28,0),0) -> 4 | R23: =IFERROR(ROUND(Q24*ASSUMPTIONS!$C$28,0),0) -> 5 | S23: =IFERROR(ROUND(R24*ASSUMPTIONS!$C$28,0),0) -> 6 | T23: =IFERROR(ROUND(S24*ASSUMPTIONS!$C$28,0),0) -> 6 | U23: =IFERROR(ROUND(T24*ASSUMPTIONS!$C$28,0),0) -> 7 | V23: =IFERROR(ROUND(U24*ASSUMPTIONS!$C$28,0),0) -> 9 | W23: =IFERROR(ROUND(V24*ASSUMPTIONS!$C$28,0),0) -> 10 | ... Z23: =IFERROR(ROUND(Y24*ASSUMPTIONS!$C$28,0),0) -> 15 | AA23: =SUM(O23:Z23) -> 93 | AB23: =IFERROR(ROUND(Z24*ASSUMPTIONS!$D$28,0),0) -> 17 | AC23: =IFERROR(ROUND(AB24*ASSUMPTIONS!$D$28,0),0) -> 20 | AD23: =IFERROR(ROUND(AC24*ASSUMPTIONS!$D$28,0),0) -> 23 | AE23: =IFERROR(ROUND(AD24*ASSUMPTIONS!$D$28,0),0) -> 27 | AF23: =IFERROR(ROUND(AE24*ASSUMPTIONS!$D$28,0),0) -> 31 | AG23: =IFERROR(ROUND(AF24*ASSUMPTIONS!$D$28,0),0) -> 35 | AH23: =IFERROR(ROUND(AG24*ASSUMPTIONS!$D$28,0),0) -> 41 | AI23: =IFERROR(ROUND(AH24*ASSUMPTIONS!$D$28,0),0) -> 47 | AJ23: =IFERROR(ROUND(AI24*ASSUMPTIONS!$D$28,0),0) -> 54 | ... AM23: =IFERROR(ROUND(AL24*ASSUMPTIONS!$D$28,0),0) -> 82 | AN23: =SUM(AB23:AM23) -> 510 | AO23: =IFERROR(ROUND(AM24*ASSUMPTIONS!$E$28,0),0) -> 94 | AP23: =IFERROR(ROUND(AO24*ASSUMPTIONS!$E$28,0),0) -> 108 | AQ23: =IFERROR(ROUND(AP24*ASSUMPTIONS!$E$28,0),0) -> 125 | AR23: =IFERROR(ROUND(AQ24*ASSUMPTIONS!$E$28,0),0) -> 143 | AS23: =IFERROR(ROUND(AR24*ASSUMPTIONS!$E$28,0),0) -> 165 | AT23: =IFERROR(ROUND(AS24*ASSUMPTIONS!$E$28,0),0) -> 190 | AU23: =IFERROR(ROUND(AT24*ASSUMPTIONS!$E$28,0),0) -> 218 | AV23: =IFERROR(ROUND(AU24*ASSUMPTIONS!$E$28,0),0) -> 251 | AW23: =IFERROR(ROUND(AV24*ASSUMPTIONS!$E$28,0),0) -> 289 | ... AZ23: =IFERROR(ROUND(AY24*ASSUMPTIONS!$E$28,0),0) -> 439 | BA23: =SUM(AO23:AZ23) -> 2736 | BB23: =IFERROR(ROUND(AZ24*ASSUMPTIONS!$F$28,0),0) -> 505 | BC23: =IFERROR(ROUND(BB24*ASSUMPTIONS!$F$28,0),0) -> 580 | BD23: =IFERROR(ROUND(BC24*ASSUMPTIONS!$F$28,0),0) -> 668 | BE23: =IFERROR(ROUND(BD24*ASSUMPTIONS!$F$28,0),0) -> 768 | BF23: =IFERROR(ROUND(BE24*ASSUMPTIONS!$F$28,0),0) -> 883 | BG23: =IFERROR(ROUND(BF24*ASSUMPTIONS!$F$28,0),0) -> 1015 | BH23: =IFERROR(ROUND(BG24*ASSUMPTIONS!$F$28,0),0) -> 1168 | BI23: =IFERROR(ROUND(BH24*ASSUMPTIONS!$F$28,0),0) -> 1343 | BJ23: =IFERROR(ROUND(BI24*ASSUMPTIONS!$F$28,0),0) -> 1544 | ... BM23: =IFERROR(ROUND(BL24*ASSUMPTIONS!$F$28,0),0) -> 2349 | BN23: =SUM(BB23:BM23) -> 14641
A24: Active SaaS Subscribers — End of Month | B24: =IFERROR(MAX(0,ASSUMPTIONS!$B$25+B22-B23),0) -> 25 | C24: =IFERROR(MAX(0,B24+C22-C23),0) -> 30 | D24: =IFERROR(MAX(0,C24+D22-D23),0) -> 36 | E24: =IFERROR(MAX(0,D24+E22-E23),0) -> 43 | F24: =IFERROR(MAX(0,E24+F22-F23),0) -> 51 | G24: =IFERROR(MAX(0,F24+G22-G23),0) -> 60 | H24: =IFERROR(MAX(0,G24+H22-H23),0) -> 71 | I24: =IFERROR(MAX(0,H24+I22-I23),0) -> 84 | J24: =IFERROR(MAX(0,I24+J22-J23),0) -> 98 | ... M24: =IFERROR(MAX(0,L24+M22-M23),0) -> 154 | N24: =M24 -> 154 | O24: =IFERROR(MAX(0,M24+O22-O23),0) -> 179 | P24: =IFERROR(MAX(0,O24+P22-P23),0) -> 207 | Q24: =IFERROR(MAX(0,P24+Q22-Q23),0) -> 240 | R24: =IFERROR(MAX(0,Q24+R22-R23),0) -> 278 | S24: =IFERROR(MAX(0,R24+S22-S23),0) -> 321 | T24: =IFERROR(MAX(0,S24+T22-T23),0) -> 371 | U24: =IFERROR(MAX(0,T24+U22-U23),0) -> 428 | V24: =IFERROR(MAX(0,U24+V22-V23),0) -> 493 | W24: =IFERROR(MAX(0,V24+W22-W23),0) -> 568 | ... Z24: =IFERROR(MAX(0,Y24+Z22-Z23),0) -> 870 | AA24: =Z24 -> 870 | AB24: =IFERROR(MAX(0,Z24+AB22-AB23),0) -> 1003 | AC24: =IFERROR(MAX(0,AB24+AC22-AC23),0) -> 1156 | AD24: =IFERROR(MAX(0,AC24+AD22-AD23),0) -> 1332 | AE24: =IFERROR(MAX(0,AD24+AE22-AE23),0) -> 1534 | AF24: =IFERROR(MAX(0,AE24+AF22-AF23),0) -> 1766 | AG24: =IFERROR(MAX(0,AF24+AG22-AG23),0) -> 2033 | AH24: =IFERROR(MAX(0,AG24+AH22-AH23),0) -> 2339 | AI24: =IFERROR(MAX(0,AH24+AI22-AI23),0) -> 2691 | AJ24: =IFERROR(MAX(0,AI24+AJ22-AJ23),0) -> 3096 | ... AM24: =IFERROR(MAX(0,AL24+AM22-AM23),0) -> 4714 | AN24: =AM24 -> 4714 | AO24: =IFERROR(MAX(0,AM24+AO22-AO23),0) -> 5423 | AP24: =IFERROR(MAX(0,AO24+AP22-AP23),0) -> 6238 | AQ24: =IFERROR(MAX(0,AP24+AQ22-AQ23),0) -> 7174 | AR24: =IFERROR(MAX(0,AQ24+AR22-AR23),0) -> 8251 | AS24: =IFERROR(MAX(0,AR24+AS22-AS23),0) -> 9489 | AT24: =IFERROR(MAX(0,AS24+AT22-AT23),0) -> 10912 | AU24: =IFERROR(MAX(0,AT24+AU22-AU23),0) -> 12549 | AV24: =IFERROR(MAX(0,AU24+AV22-AV23),0) -> 14431 | AW24: =IFERROR(MAX(0,AV24+AW22-AW23),0) -> 16595 | ... AZ24: =IFERROR(MAX(0,AY24+AZ22-AZ23),0) -> 25238 | BA24: =AZ24 -> 25238 | BB24: =IFERROR(MAX(0,AZ24+BB22-BB23),0) -> 29024 | BC24: =IFERROR(MAX(0,BB24+BC22-BC23),0) -> 33379 | BD24: =IFERROR(MAX(0,BC24+BD22-BD23),0) -> 38386 | BE24: =IFERROR(MAX(0,BD24+BE22-BE23),0) -> 44144 | BF24: =IFERROR(MAX(0,BE24+BF22-BF23),0) -> 50766 | BG24: =IFERROR(MAX(0,BF24+BG22-BG23),0) -> 58382 | BH24: =IFERROR(MAX(0,BG24+BH22-BH23),0) -> 67140 | BI24: =IFERROR(MAX(0,BH24+BI22-BI23),0) -> 77212 | BJ24: =IFERROR(MAX(0,BI24+BJ22-BJ23),0) -> 88795 | ... BM24: =IFERROR(MAX(0,BL24+BM22-BM23),0) -> 135048 | BN24: =BM24 -> 135048
A25: Monthly ARPU (£) | B25: =ASSUMPTIONS!$B$29 -> 299 | C25: =ASSUMPTIONS!$B$29 -> 299 | D25: =ASSUMPTIONS!$B$29 -> 299 | E25: =ASSUMPTIONS!$B$29 -> 299 | F25: =ASSUMPTIONS!$B$29 -> 299 | G25: =ASSUMPTIONS!$B$29 -> 299 | H25: =ASSUMPTIONS!$B$29 -> 299 | I25: =ASSUMPTIONS!$B$29 -> 299 | ... M25: =ASSUMPTIONS!$B$29 -> 299 | N25: =M25 -> 299 | O25: =ASSUMPTIONS!$C$29 -> 299 | P25: =ASSUMPTIONS!$C$29 -> 299 | Q25: =ASSUMPTIONS!$C$29 -> 299 | R25: =ASSUMPTIONS!$C$29 -> 299 | S25: =ASSUMPTIONS!$C$29 -> 299 | T25: =ASSUMPTIONS!$C$29 -> 299 | U25: =ASSUMPTIONS!$C$29 -> 299 | V25: =ASSUMPTIONS!$C$29 -> 299 | ... Z25: =ASSUMPTIONS!$C$29 -> 299 | AA25: =Z25 -> 299 | AB25: =ASSUMPTIONS!$D$29 -> 299 | AC25: =ASSUMPTIONS!$D$29 -> 299 | AD25: =ASSUMPTIONS!$D$29 -> 299 | AE25: =ASSUMPTIONS!$D$29 -> 299 | AF25: =ASSUMPTIONS!$D$29 -> 299 | AG25: =ASSUMPTIONS!$D$29 -> 299 | AH25: =ASSUMPTIONS!$D$29 -> 299 | AI25: =ASSUMPTIONS!$D$29 -> 299 | ... AM25: =ASSUMPTIONS!$D$29 -> 299 | AN25: =AM25 -> 299 | AO25: =ASSUMPTIONS!$E$29 -> 299 | AP25: =ASSUMPTIONS!$E$29 -> 299 | AQ25: =ASSUMPTIONS!$E$29 -> 299 | AR25: =ASSUMPTIONS!$E$29 -> 299 | AS25: =ASSUMPTIONS!$E$29 -> 299 | AT25: =ASSUMPTIONS!$E$29 -> 299 | AU25: =ASSUMPTIONS!$E$29 -> 299 | AV25: =ASSUMPTIONS!$E$29 -> 299 | ... AZ25: =ASSUMPTIONS!$E$29 -> 299 | BA25: =AZ25 -> 299 | BB25: =ASSUMPTIONS!$F$29 -> 299 | BC25: =ASSUMPTIONS!$F$29 -> 299 | BD25: =ASSUMPTIONS!$F$29 -> 299 | BE25: =ASSUMPTIONS!$F$29 -> 299 | BF25: =ASSUMPTIONS!$F$29 -> 299 | BG25: =ASSUMPTIONS!$F$29 -> 299 | BH25: =ASSUMPTIONS!$F$29 -> 299 | BI25: =ASSUMPTIONS!$F$29 -> 299 | ... BM25: =ASSUMPTIONS!$F$29 -> 299 | BN25: =BM25 -> 299
A26: TOTAL SAAS REVENUE (£) | B26: =IFERROR(B24*ASSUMPTIONS!$B$29,0) -> 7475 | C26: =IFERROR(C24*ASSUMPTIONS!$B$29,0) -> 8970 | D26: =IFERROR(D24*ASSUMPTIONS!$B$29,0) -> 10764 | E26: =IFERROR(E24*ASSUMPTIONS!$B$29,0) -> 12857 | F26: =IFERROR(F24*ASSUMPTIONS!$B$29,0) -> 15249 | G26: =IFERROR(G24*ASSUMPTIONS!$B$29,0) -> 17940 | H26: =IFERROR(H24*ASSUMPTIONS!$B$29,0) -> 21229 | I26: =IFERROR(I24*ASSUMPTIONS!$B$29,0) -> 25116 | ... M26: =IFERROR(M24*ASSUMPTIONS!$B$29,0) -> 46046 | N26: =SUM(B26:M26) -> 268801 | O26: =IFERROR(O24*ASSUMPTIONS!$C$29,0) -> 53521 | P26: =IFERROR(P24*ASSUMPTIONS!$C$29,0) -> 61893 | Q26: =IFERROR(Q24*ASSUMPTIONS!$C$29,0) -> 71760 | R26: =IFERROR(R24*ASSUMPTIONS!$C$29,0) -> 83122 | S26: =IFERROR(S24*ASSUMPTIONS!$C$29,0) -> 95979 | T26: =IFERROR(T24*ASSUMPTIONS!$C$29,0) -> 110929 | U26: =IFERROR(U24*ASSUMPTIONS!$C$29,0) -> 127972 | V26: =IFERROR(V24*ASSUMPTIONS!$C$29,0) -> 147407 | ... Z26: =IFERROR(Z24*ASSUMPTIONS!$C$29,0) -> 260130 | AA26: =SUM(O26:Z26) -> 1604135 | AB26: =IFERROR(AB24*ASSUMPTIONS!$D$29,0) -> 299897 | AC26: =IFERROR(AC24*ASSUMPTIONS!$D$29,0) -> 345644 | AD26: =IFERROR(AD24*ASSUMPTIONS!$D$29,0) -> 398268 | AE26: =IFERROR(AE24*ASSUMPTIONS!$D$29,0) -> 458666 | AF26: =IFERROR(AF24*ASSUMPTIONS!$D$29,0) -> 528034 | AG26: =IFERROR(AG24*ASSUMPTIONS!$D$29,0) -> 607867 | AH26: =IFERROR(AH24*ASSUMPTIONS!$D$29,0) -> 699361 | AI26: =IFERROR(AI24*ASSUMPTIONS!$D$29,0) -> 804609 | ... AM26: =IFERROR(AM24*ASSUMPTIONS!$D$29,0) -> 1409486 | AN26: =SUM(AB26:AM26) -> 8767876 | AO26: =IFERROR(AO24*ASSUMPTIONS!$E$29,0) -> 1621477 | AP26: =IFERROR(AP24*ASSUMPTIONS!$E$29,0) -> 1865162 | AQ26: =IFERROR(AQ24*ASSUMPTIONS!$E$29,0) -> 2145026 | AR26: =IFERROR(AR24*ASSUMPTIONS!$E$29,0) -> 2467049 | AS26: =IFERROR(AS24*ASSUMPTIONS!$E$29,0) -> 2837211 | AT26: =IFERROR(AT24*ASSUMPTIONS!$E$29,0) -> 3262688 | AU26: =IFERROR(AU24*ASSUMPTIONS!$E$29,0) -> 3752151 | AV26: =IFERROR(AV24*ASSUMPTIONS!$E$29,0) -> 4314869 | ... AZ26: =IFERROR(AZ24*ASSUMPTIONS!$E$29,0) -> 7546162 | BA26: =SUM(AO26:AZ26) -> 47041670 | BB26: =IFERROR(BB24*ASSUMPTIONS!$F$29,0) -> 8678176 | BC26: =IFERROR(BC24*ASSUMPTIONS!$F$29,0) -> 9980321 | BD26: =IFERROR(BD24*ASSUMPTIONS!$F$29,0) -> 11477414 | BE26: =IFERROR(BE24*ASSUMPTIONS!$F$29,0) -> 13199056 | BF26: =IFERROR(BF24*ASSUMPTIONS!$F$29,0) -> 15179034 | BG26: =IFERROR(BG24*ASSUMPTIONS!$F$29,0) -> 17456218 | BH26: =IFERROR(BH24*ASSUMPTIONS!$F$29,0) -> 20074860 | BI26: =IFERROR(BI24*ASSUMPTIONS!$F$29,0) -> 23086388 | ... BM26: =IFERROR(BM24*ASSUMPTIONS!$F$29,0) -> 40379352 | BN26: =SUM(BB26:BM26) -> 251705376
A28: TOTAL REVENUE SUMMARY
A29: Marketplace Revenue (£) | B29: =B19 -> 16275 | C29: =C19 -> 15058 | D29: =D19 -> 15849 | E29: =E19 -> 16875 | F29: =F19 -> 18036 | G29: =G19 -> 19332 | H29: =H19 -> 20763 | I29: =I19 -> 22383 | ... M29: =M19 -> 30861 | N29: =SUM(B29:M29) -> 254218 | O29: =O19 -> 33588 | P29: =P19 -> 36612 | Q29: =Q19 -> 39933 | R29: =R19 -> 43605 | S29: =S19 -> 47655 | T29: =T19 -> 52137 | U29: =U19 -> 57051 | V29: =V19 -> 62478 | ... Z29: =Z19 -> 90396 | AA29: =SUM(O29:Z29) -> 689391 | AB29: =AB19 -> 99252 | AC29: =AC19 -> 108999 | AD29: =AD19 -> 119745 | AE29: =AE19 -> 131571 | AF29: =AF19 -> 144585 | AG29: =AG19 -> 158922 | AH29: =AH19 -> 174717 | AI29: =AI19 -> 192078 | ... AM29: =AM19 -> 280827 | AN29: =SUM(AB29:AM29) -> 2109483 | AO29: =AO19 -> 308853 | AP29: =AP19 -> 339687 | AQ29: =AQ19 -> 373599 | AR29: =AR19 -> 410913 | AS29: =AS19 -> 451953 | AT29: =AT19 -> 497097 | AU29: =AU19 -> 546750 | AV29: =AV19 -> 601371 | ... AZ29: =AZ19 -> 880335 | BA29: =SUM(AO29:AZ29) -> 6599961 | BB29: =BB19 -> 968355 | BC29: =BC19 -> 1065177 | BD29: =BD19 -> 1171665 | BE29: =BE19 -> 1288818 | BF29: =BF19 -> 1417689 | BG29: =BG19 -> 1559466 | BH29: =BH19 -> 1715418 | BI29: =BI19 -> 1886949 | ... BM29: =BM19 -> 2762640 | BN29: =SUM(BB29:BM29) -> 20706543
A30: SaaS Revenue (£) | B30: =B26 -> 7475 | C30: =C26 -> 8970 | D30: =D26 -> 10764 | E30: =E26 -> 12857 | F30: =F26 -> 15249 | G30: =G26 -> 17940 | H30: =H26 -> 21229 | I30: =I26 -> 25116 | ... M30: =M26 -> 46046 | N30: =SUM(B30:M30) -> 268801 | O30: =O26 -> 53521 | P30: =P26 -> 61893 | Q30: =Q26 -> 71760 | R30: =R26 -> 83122 | S30: =S26 -> 95979 | T30: =T26 -> 110929 | U30: =U26 -> 127972 | V30: =V26 -> 147407 | ... Z30: =Z26 -> 260130 | AA30: =SUM(O30:Z30) -> 1604135 | AB30: =AB26 -> 299897 | AC30: =AC26 -> 345644 | AD30: =AD26 -> 398268 | AE30: =AE26 -> 458666 | AF30: =AF26 -> 528034 | AG30: =AG26 -> 607867 | AH30: =AH26 -> 699361 | AI30: =AI26 -> 804609 | ... AM30: =AM26 -> 1409486 | AN30: =SUM(AB30:AM30) -> 8767876 | AO30: =AO26 -> 1621477 | AP30: =AP26 -> 1865162 | AQ30: =AQ26 -> 2145026 | AR30: =AR26 -> 2467049 | AS30: =AS26 -> 2837211 | AT30: =AT26 -> 3262688 | AU30: =AU26 -> 3752151 | AV30: =AV26 -> 4314869 | ... AZ30: =AZ26 -> 7546162 | BA30: =SUM(AO30:AZ30) -> 47041670 | BB30: =BB26 -> 8678176 | BC30: =BC26 -> 9980321 | BD30: =BD26 -> 11477414 | BE30: =BE26 -> 13199056 | BF30: =BF26 -> 15179034 | BG30: =BG26 -> 17456218 | BH30: =BH26 -> 20074860 | BI30: =BI26 -> 23086388 | ... BM30: =BM26 -> 40379352 | BN30: =SUM(BB30:BM30) -> 251705376
A31: TOTAL REVENUE (£) | B31: =IFERROR(B19+B26,0) -> 23750 | C31: =IFERROR(C19+C26,0) -> 24028 | D31: =IFERROR(D19+D26,0) -> 26613 | E31: =IFERROR(E19+E26,0) -> 29732 | F31: =IFERROR(F19+F26,0) -> 33285 | G31: =IFERROR(G19+G26,0) -> 37272 | H31: =IFERROR(H19+H26,0) -> 41992 | I31: =IFERROR(I19+I26,0) -> 47499 | ... M31: =IFERROR(M19+M26,0) -> 76907 | N31: =SUM(B31:M31) -> 523019 | O31: =IFERROR(O19+O26,0) -> 87109 | P31: =IFERROR(P19+P26,0) -> 98505 | Q31: =IFERROR(Q19+Q26,0) -> 111693 | R31: =IFERROR(R19+R26,0) -> 126727 | S31: =IFERROR(S19+S26,0) -> 143634 | T31: =IFERROR(T19+T26,0) -> 163066 | U31: =IFERROR(U19+U26,0) -> 185023 | V31: =IFERROR(V19+V26,0) -> 209885 | ... Z31: =IFERROR(Z19+Z26,0) -> 350526 | AA31: =SUM(O31:Z31) -> 2293526 | AB31: =IFERROR(AB19+AB26,0) -> 399149 | AC31: =IFERROR(AC19+AC26,0) -> 454643 | AD31: =IFERROR(AD19+AD26,0) -> 518013 | AE31: =IFERROR(AE19+AE26,0) -> 590237 | AF31: =IFERROR(AF19+AF26,0) -> 672619 | AG31: =IFERROR(AG19+AG26,0) -> 766789 | AH31: =IFERROR(AH19+AH26,0) -> 874078 | AI31: =IFERROR(AI19+AI26,0) -> 996687 | ... AM31: =IFERROR(AM19+AM26,0) -> 1690313 | AN31: =SUM(AB31:AM31) -> 10877359 | AO31: =IFERROR(AO19+AO26,0) -> 1930330 | AP31: =IFERROR(AP19+AP26,0) -> 2204849 | AQ31: =IFERROR(AQ19+AQ26,0) -> 2518625 | AR31: =IFERROR(AR19+AR26,0) -> 2877962 | AS31: =IFERROR(AS19+AS26,0) -> 3289164 | AT31: =IFERROR(AT19+AT26,0) -> 3759785 | AU31: =IFERROR(AU19+AU26,0) -> 4298901 | AV31: =IFERROR(AV19+AV26,0) -> 4916240 | ... AZ31: =IFERROR(AZ19+AZ26,0) -> 8426497 | BA31: =SUM(AO31:AZ31) -> 53641631 | BB31: =IFERROR(BB19+BB26,0) -> 9646531 | BC31: =IFERROR(BC19+BC26,0) -> 11045498 | BD31: =IFERROR(BD19+BD26,0) -> 12649079 | BE31: =IFERROR(BE19+BE26,0) -> 14487874 | BF31: =IFERROR(BF19+BF26,0) -> 16596723 | BG31: =IFERROR(BG19+BG26,0) -> 19015684 | BH31: =IFERROR(BH19+BH26,0) -> 21790278 | BI31: =IFERROR(BI19+BI26,0) -> 24973337 | ... BM31: =IFERROR(BM19+BM26,0) -> 43141992 | BN31: =SUM(BB31:BM31) -> 272411919
A32: Month-on-Month Revenue Growth % | C32: =IFERROR((C29-B29)/B29,0) -> -0.074777266 | D32: =IFERROR((D29-C29)/C29,0) -> 0.052530216 | E32: =IFERROR((E29-D29)/D29,0) -> 0.064735945 | F32: =IFERROR((F29-E29)/E29,0) -> 0.0688 | G32: =IFERROR((G29-F29)/F29,0) -> 0.071856287 | H32: =IFERROR((H29-G29)/G29,0) -> 0.074022346 | I32: =IFERROR((I29-H29)/H29,0) -> 0.078023407 | J32: =IFERROR((J29-I29)/I29,0) -> 0.080820265 | ... M32: =IFERROR((M29-L29)/L29,0) -> 0.086501901 | N32: =M32 -> 0.086501901 | O32: =IFERROR((O29-M29)/M29,0) -> 0.088363955 | P32: =IFERROR((P29-O29)/O29,0) -> 0.090032154 | Q32: =IFERROR((Q29-P29)/P29,0) -> 0.090707965 | R32: =IFERROR((R29-Q29)/Q29,0) -> 0.091954023 | S32: =IFERROR((S29-R29)/R29,0) -> 0.092879257 | T32: =IFERROR((T29-S29)/S29,0) -> 0.094050992 | U32: =IFERROR((U29-T29)/T29,0) -> 0.094251683 | V32: =IFERROR((V29-U29)/U29,0) -> 0.095125414 | W32: =IFERROR((W29-V29)/V29,0) -> 0.09593777 | ... Z32: =IFERROR((Z29-Y29)/Y29,0) -> 0.097345133 | AA32: =Z32 -> 0.097345133 | AB32: =IFERROR((AB29-Z29)/Z29,0) -> 0.097968937 | AC32: =IFERROR((AC29-AB29)/AB29,0) -> 0.09820457 | AD32: =IFERROR((AD29-AC29)/AC29,0) -> 0.09858806 | AE32: =IFERROR((AE29-AD29)/AD29,0) -> 0.098759865 | AF32: =IFERROR((AF29-AE29)/AE29,0) -> 0.098912374 | AG32: =IFERROR((AG29-AF29)/AF29,0) -> 0.099159664 | AH32: =IFERROR((AH29-AG29)/AG29,0) -> 0.099388379 | AI32: =IFERROR((AI29-AH29)/AH29,0) -> 0.099366404 | AJ32: =IFERROR((AJ29-AI29)/AI29,0) -> 0.099522069 | ... AM32: =IFERROR((AM29-AL29)/AL29,0) -> 0.099703954 | AN32: =AM32 -> 0.099703954 | AO32: =IFERROR((AO29-AM29)/AM29,0) -> 0.099798096 | AP32: =IFERROR((AP29-AO29)/AO29,0) -> 0.099833902 | AQ32: =IFERROR((AQ29-AP29)/AP29,0) -> 0.099833082 | AR32: =IFERROR((AR29-AQ29)/AQ29,0) -> 0.099877141 | AS32: =IFERROR((AS29-AR29)/AR29,0) -> 0.099875156 | AT32: =IFERROR((AT29-AS29)/AS29,0) -> 0.099886493 | AU32: =IFERROR((AU29-AT29)/AT29,0) -> 0.099885938 | AV32: =IFERROR((AV29-AU29)/AU29,0) -> 0.099901235 | AW32: =IFERROR((AW29-AV29)/AV29,0) -> 0.099941633 | ... AZ32: =IFERROR((AZ29-AY29)/AY29,0) -> 0.099959517 | BA32: =AZ32 -> 0.099959517 | BB32: =IFERROR((BB29-AZ29)/AZ29,0) -> 0.099984665 | BC32: =IFERROR((BC29-BB29)/BB29,0) -> 0.099986059 | BD32: =IFERROR((BD29-BC29)/BC29,0) -> 0.099972117 | BE32: =IFERROR((BE29-BD29)/BD29,0) -> 0.099988478 | BF32: =IFERROR((BF29-BE29)/BE29,0) -> 0.09999162 | BG32: =IFERROR((BG29-BF29)/BF29,0) -> 0.10000571 | BH32: =IFERROR((BH29-BG29)/BG29,0) -> 0.10000346 | BI32: =IFERROR((BI29-BH29)/BH29,0) -> 0.099993704 | BJ32: =IFERROR((BJ29-BI29)/BI29,0) -> 0.10000429 | ... BM32: =IFERROR((BM29-BL29)/BL29,0) -> 0.099990325 | BN32: =BM32 -> 0.099990325
A34: COST OF GOODS SOLD (COGS)
A35: Payment Processing (% of GMV) | B35: =IFERROR(B16*ASSUMPTIONS!$B$39,0) -> 1890 | C35: =IFERROR(C16*ASSUMPTIONS!$B$39,0) -> 1994.4 | D35: =IFERROR(D16*ASSUMPTIONS!$B$39,0) -> 2113.2 | E35: =IFERROR(E16*ASSUMPTIONS!$B$39,0) -> 2250 | F35: =IFERROR(F16*ASSUMPTIONS!$B$39,0) -> 2404.8 | G35: =IFERROR(G16*ASSUMPTIONS!$B$39,0) -> 2577.6 | H35: =IFERROR(H16*ASSUMPTIONS!$B$39,0) -> 2768.4 | I35: =IFERROR(I16*ASSUMPTIONS!$B$39,0) -> 2984.4 | ... M35: =IFERROR(M16*ASSUMPTIONS!$B$39,0) -> 4114.8 | N35: =SUM(B35:M35) -> 33602.4 | O35: =IFERROR(O16*ASSUMPTIONS!$C$39,0) -> 4478.4 | P35: =IFERROR(P16*ASSUMPTIONS!$C$39,0) -> 4881.6 | Q35: =IFERROR(Q16*ASSUMPTIONS!$C$39,0) -> 5324.4 | R35: =IFERROR(R16*ASSUMPTIONS!$C$39,0) -> 5814 | S35: =IFERROR(S16*ASSUMPTIONS!$C$39,0) -> 6354 | T35: =IFERROR(T16*ASSUMPTIONS!$C$39,0) -> 6951.6 | U35: =IFERROR(U16*ASSUMPTIONS!$C$39,0) -> 7606.8 | V35: =IFERROR(V16*ASSUMPTIONS!$C$39,0) -> 8330.4 | ... Z35: =IFERROR(Z16*ASSUMPTIONS!$C$39,0) -> 12052.8 | AA35: =SUM(O35:Z35) -> 91918.8 | AB35: =IFERROR(AB16*ASSUMPTIONS!$D$39,0) -> 13233.6 | AC35: =IFERROR(AC16*ASSUMPTIONS!$D$39,0) -> 14533.2 | AD35: =IFERROR(AD16*ASSUMPTIONS!$D$39,0) -> 15966 | AE35: =IFERROR(AE16*ASSUMPTIONS!$D$39,0) -> 17542.8 | AF35: =IFERROR(AF16*ASSUMPTIONS!$D$39,0) -> 19278 | AG35: =IFERROR(AG16*ASSUMPTIONS!$D$39,0) -> 21189.6 | AH35: =IFERROR(AH16*ASSUMPTIONS!$D$39,0) -> 23295.6 | AI35: =IFERROR(AI16*ASSUMPTIONS!$D$39,0) -> 25610.4 | ... AM35: =IFERROR(AM16*ASSUMPTIONS!$D$39,0) -> 37443.6 | AN35: =SUM(AB35:AM35) -> 281264.4 | AO35: =IFERROR(AO16*ASSUMPTIONS!$E$39,0) -> 41180.4 | AP35: =IFERROR(AP16*ASSUMPTIONS!$E$39,0) -> 45291.6 | AQ35: =IFERROR(AQ16*ASSUMPTIONS!$E$39,0) -> 49813.2 | AR35: =IFERROR(AR16*ASSUMPTIONS!$E$39,0) -> 54788.4 | AS35: =IFERROR(AS16*ASSUMPTIONS!$E$39,0) -> 60260.4 | AT35: =IFERROR(AT16*ASSUMPTIONS!$E$39,0) -> 66279.6 | AU35: =IFERROR(AU16*ASSUMPTIONS!$E$39,0) -> 72900 | AV35: =IFERROR(AV16*ASSUMPTIONS!$E$39,0) -> 80182.8 | ... AZ35: =IFERROR(AZ16*ASSUMPTIONS!$E$39,0) -> 117378 | BA35: =SUM(AO35:AZ35) -> 879994.8 | BB35: =IFERROR(BB16*ASSUMPTIONS!$F$39,0) -> 129114 | BC35: =IFERROR(BC16*ASSUMPTIONS!$F$39,0) -> 142023.6 | BD35: =IFERROR(BD16*ASSUMPTIONS!$F$39,0) -> 156222 | BE35: =IFERROR(BE16*ASSUMPTIONS!$F$39,0) -> 171842.4 | BF35: =IFERROR(BF16*ASSUMPTIONS!$F$39,0) -> 189025.2 | BG35: =IFERROR(BG16*ASSUMPTIONS!$F$39,0) -> 207928.8 | BH35: =IFERROR(BH16*ASSUMPTIONS!$F$39,0) -> 228722.4 | BI35: =IFERROR(BI16*ASSUMPTIONS!$F$39,0) -> 251593.2 | ... BM35: =IFERROR(BM16*ASSUMPTIONS!$F$39,0) -> 368352 | BN35: =SUM(BB35:BM35) -> 2760872.4
