Workbook

Sheet COVER
B2: Raise Ready
B3: Seed Financial Model — Growth
B5: Includes: Cohort revenue, channel CAC, 3 scenarios, P&L, cash flow. 24-month horizon.

Sheet ASSUMPTIONS
A1: ASSUMPTIONS — Seed Model Inputs
A2: Yellow cells = inputs. Three scenario columns: Conservative / Base / Aggressive. Active scenario selected below.
A4: SECTION 1 — COMPANY INFORMATION
A5: Company Name | B5: SeedCo Inc | C5: Your legal name
A6: Reporting Currency | B6: $
A7: Model Start | B7: Jan 2025
A9: SCENARIO SELECTOR
A10: Active Scenario (1=Conservative, 2=Base, 3=Aggressive) | B10: 2 | C10: Change this to switch all model outputs
A12: SECTION 2 — REVENUE DRIVERS (BY SCENARIO)
B13: Conservative | C13: Base | D13: Aggressive
A14: Starting Customers | B14: 8 | C14: 15 | D14: 25
A15: New Customers / Month | B15: 10 | C15: 20 | D15: 35
A16: Monthly Customer Growth Rate | B16: 0.05 | C16: 0.1 | D16: 0.15
A17: Monthly Churn Rate | B17: 0.06 | C17: 0.045 | D17: 0.03
A18: ARPU ($) | B18: 79 | C18: 99 | D18: 119
A20: Active Scenario Values (auto-calculated)
A21: → Starting Customers | B21: =CHOOSE($B$10,B14,C14,D14) -> 15
A22: → New Customers / Month | B22: =CHOOSE($B$10,B15,C15,D15) -> 20
A23: → Monthly Customer Growth Rate | B23: =CHOOSE($B$10,B16,C16,D16) -> 0.1
A24: → Monthly Churn Rate | B24: =CHOOSE($B$10,B17,C17,D17) -> 0.045
A25: → ARPU ($) | B25: =CHOOSE($B$10,B18,C18,D18) -> 99
A27: SECTION 3 — CAC BY CHANNEL | B27: % of New Customers | C27: CAC ($)
A28: Organic / SEO | B28: 0.3 | C28: 25
A29: Paid Search | B29: 0.25 | C29: 180
A30: Social / Content | B30: 0.2 | C30: 90
A31: Referral | B31: 0.15 | C31: 40
A32: Direct Sales | B32: 0.1 | C32: 350
A33: Blended CAC ($) | B33: =SUMPRODUCT(B28:B32,C28:C32) -> 111.5
A35: SECTION 4 — COGS & OPEX
A36: Hosting Cost / Customer ($) | B36: 5
A37: Payment Processing (% Rev) | B37: 0.029
A38: Support Cost / Customer ($) | B38: 3
A40: SECTION 5 — HEADCOUNT PLAN
B41: Role | C41: Start Mo | D41: Salary ($)
A42: CEO | B42: CEO | C42: 1 | D42: 80000
A43: CTO | B43: CTO | C43: 1 | D43: 80000
A44: Eng #1 | B44: Eng #1 | C44: 1 | D44: 100000
A45: Eng #2 | B45: Eng #2 | C45: 3 | D45: 100000
A46: Eng #3 | B46: Eng #3 | C46: 6 | D46: 100000
A47: Designer | B47: Designer | C47: 3 | D47: 80000
...

Sheet REVENUE
A1: REVENUE MODEL — Scenario-Driven
A2: All inputs from ASSUMPTIONS. Active scenario auto-selected. Do not edit white cells.
B4: YEAR 1 | N4: YEAR 2
B5: Jan | C5: Feb | D5: Mar | E5: Apr | F5: May | G5: Jun | H5: Jul | I5: Aug | J5: Sep | K5: Oct | L5: Nov | M5: Dec | N5: Jan | O5: Feb | P5: Mar | Q5: Apr | R5: May | S5: Jun | T5: Jul | U5: Aug | V5: Sep | W5: Oct | X5: Nov | Y5: Dec | Z5: Y1 Total | AA5: Y2 Total
A6: CUSTOMER METRICS
A7: New Customers Added | B7: =IFERROR(ASSUMPTIONS!$B$22,0) -> 20 | C7: =IFERROR(ROUND(B7*(1+ASSUMPTIONS!$B$23),0),0) -> 22 | D7: =IFERROR(ROUND(C7*(1+ASSUMPTIONS!$B$23),0),0) -> 24 | E7: =IFERROR(ROUND(D7*(1+ASSUMPTIONS!$B$23),0),0) -> 26 | F7: =IFERROR(ROUND(E7*(1+ASSUMPTIONS!$B$23),0),0) -> 29 | G7: =IFERROR(ROUND(F7*(1+ASSUMPTIONS!$B$23),0),0) -> 32 | H7: =IFERROR(ROUND(G7*(1+ASSUMPTIONS!$B$23),0),0) -> 35 | I7: =IFERROR(ROUND(H7*(1+ASSUMPTIONS!$B$23),0),0) -> 39 | J7: =IFERROR(ROUND(I7*(1+ASSUMPTIONS!$B$23),0),0) -> 43 | ... Y7: =IFERROR(ROUND(X7*(1+ASSUMPTIONS!$B$23),0),0) -> 178
A8: Customers Churned | B8: =IFERROR(ROUND(ASSUMPTIONS!$B$21*ASSUMPTIONS!$B$24,0),0) -> 1 | C8: =IFERROR(ROUND(B9*ASSUMPTIONS!$B$24,0),0) -> 2 | D8: =IFERROR(ROUND(C9*ASSUMPTIONS!$B$24,0),0) -> 2 | E8: =IFERROR(ROUND(D9*ASSUMPTIONS!$B$24,0),0) -> 3 | F8: =IFERROR(ROUND(E9*ASSUMPTIONS!$B$24,0),0) -> 4 | G8: =IFERROR(ROUND(F9*ASSUMPTIONS!$B$24,0),0) -> 6 | H8: =IFERROR(ROUND(G9*ASSUMPTIONS!$B$24,0),0) -> 7 | I8: =IFERROR(ROUND(H9*ASSUMPTIONS!$B$24,0),0) -> 8 | J8: =IFERROR(ROUND(I9*ASSUMPTIONS!$B$24,0),0) -> 9 | ... Y8: =IFERROR(ROUND(X9*ASSUMPTIONS!$B$24,0),0) -> 54
A9: Active Customers — EOM | B9: =IFERROR(ASSUMPTIONS!$B$21+B7-B8,0) -> 34 | C9: =IFERROR(B9+C7-C8,0) -> 54 | D9: =IFERROR(C9+D7-D8,0) -> 76 | E9: =IFERROR(D9+E7-E8,0) -> 99 | F9: =IFERROR(E9+F7-F8,0) -> 124 | G9: =IFERROR(F9+G7-G8,0) -> 150 | H9: =IFERROR(G9+H7-H8,0) -> 178 | I9: =IFERROR(H9+I7-I8,0) -> 209 | J9: =IFERROR(I9+J7-J8,0) -> 243 | ... Y9: =IFERROR(X9+Y7-Y8,0) -> 1313
A11: REVENUE
A12: TOTAL REVENUE ($) | B12: =IFERROR(B9*ASSUMPTIONS!$B$25,0) -> 3366 | C12: =IFERROR(C9*ASSUMPTIONS!$B$25,0) -> 5346 | D12: =IFERROR(D9*ASSUMPTIONS!$B$25,0) -> 7524 | E12: =IFERROR(E9*ASSUMPTIONS!$B$25,0) -> 9801 | F12: =IFERROR(F9*ASSUMPTIONS!$B$25,0) -> 12276 | G12: =IFERROR(G9*ASSUMPTIONS!$B$25,0) -> 14850 | H12: =IFERROR(H9*ASSUMPTIONS!$B$25,0) -> 17622 | I12: =IFERROR(I9*ASSUMPTIONS!$B$25,0) -> 20691 | ... Y12: =IFERROR(Y9*ASSUMPTIONS!$B$25,0) -> 129987 | Z12: =SUM(B12:M12) -> 210375 | AA12: =SUM(N12:Y12) -> 943371
A13: Customer Acquisition Cost ($) | B13: =IFERROR(B7*ASSUMPTIONS!$B$33,0) -> 2230 | C13: =IFERROR(C7*ASSUMPTIONS!$B$33,0) -> 2453 | D13: =IFERROR(D7*ASSUMPTIONS!$B$33,0) -> 2676 | E13: =IFERROR(E7*ASSUMPTIONS!$B$33,0) -> 2899 | F13: =IFERROR(F7*ASSUMPTIONS!$B$33,0) -> 3233.5 | G13: =IFERROR(G7*ASSUMPTIONS!$B$33,0) -> 3568 | H13: =IFERROR(H7*ASSUMPTIONS!$B$33,0) -> 3902.5 | I13: =IFERROR(I7*ASSUMPTIONS!$B$33,0) -> 4348.5 | ... Y13: =IFERROR(Y7*ASSUMPTIONS!$B$33,0) -> 19847

Sheet HEADCOUNT
A1: HEADCOUNT — Staff Costs
A2: Auto-calculated from Assumptions. Edit roles there.
B4: YEAR 1 | N4: YEAR 2
B5: Jan | C5: Feb | D5: Mar | E5: Apr | F5: May | G5: Jun | H5: Jul | I5: Aug | J5: Sep | K5: Oct | L5: Nov | M5: Dec | N5: Jan | O5: Feb | P5: Mar | Q5: Apr | R5: May | S5: Jun | T5: Jul | U5: Aug | V5: Sep | W5: Oct | X5: Nov | Y5: Dec | Z5: Y1 Total | AA5: Y2 Total
A7: =IFERROR(ASSUMPTIONS!B42,"") -> CEO | B7: =IFERROR(IF(AND(1>=ASSUMPTIONS!$C$42,ASSUMPTIONS!$C$42>0),ASSUMPTIONS!$D$42/12*(ASSUMPTIONS!$B$53),0),0) -> 8666.6667 | C7: =IFERROR(IF(AND(2>=ASSUMPTIONS!$C$42,ASSUMPTIONS!$C$42>0),ASSUMPTIONS!$D$42/12*(ASSUMPTIONS!$B$53),0),0) -> 8666.6667 | D7: =IFERROR(IF(AND(3>=ASSUMPTIONS!$C$42,ASSUMPTIONS!$C$42>0),ASSUMPTIONS!$D$42/12*(ASSUMPTIONS!$B$53),0),0) -> 8666.6667 | E7: =IFERROR(IF(AND(4>=ASSUMPTIONS!$C$42,ASSUMPTIONS!$C$42>0),ASSUMPTIONS!$D$42/12*(ASSUMPTIONS!$B$53),0),0) -> 8666.6667 | F7: =IFERROR(IF(AND(5>=ASSUMPTIONS!$C$42,ASSUMPTIONS!$C$42>0),ASSUMPTIONS!$D$42/12*(ASSUMPTIONS!$B$53),0),0) -> 8666.6667 | G7: =IFERROR(IF(AND(6>=ASSUMPTIONS!$C$42,ASSUMPTIONS!$C$42>0),ASSUMPTIONS!$D$42/12*(ASSUMPTIONS!$B$53),0),0) -> 8666.6667 | H7: =IFERROR(IF(AND(7>=ASSUMPTIONS!$C$42,ASSUMPTIONS!$C$42>0),ASSUMPTIONS!$D$42/12*(ASSUMPTIONS!$B$53),0),0) -> 8666.6667 | I7: =IFERROR(IF(AND(8>=ASSUMPTIONS!$C$42,ASSUMPTIONS!$C$42>0),ASSUMPTIONS!$D$42/12*(ASSUMPTIONS!$B$53),0),0) -> 8666.6667 | J7: =IFERROR(IF(AND(9>=ASSUMPTIONS!$C$42,ASSUMPTIONS!$C$42>0),ASSUMPTIONS!$D$42/12*(ASSUMPTIONS!$B$53),0),0) -> 8666.6667 | K7: =IFERROR(IF(AND(10>=ASSUMPTIONS!$C$42,ASSUMPTIONS!$C$42>0),ASSUMPTIONS!$D$42/12*(ASSUMPTIONS!$B$53),0),0) -> 8666.6667 | L7: =IFERROR(IF(AND(11>=ASSUMPTIONS!$C$42,ASSUMPTIONS!$C$42>0),ASSUMPTIONS!$D$42/12*(ASSUMPTIONS!$B$53),0),0) -> 8666.6667 | M7: =IFERROR(IF(AND(12>=ASSUMPTIONS!$C$42,ASSUMPTIONS!$C$42>0),ASSUMPTIONS!$D$42/12*(ASSUMPTIONS!$B$53),0),0) -> 8666.6667 | N7: =IFERROR(IF(AND(13>=ASSUMPTIONS!$C$42,ASSUMPTIONS!$C$42>0),ASSUMPTIONS!$D$42/12*(ASSUMPTIONS!$B$53),0),0) -> 8666.6667 | O7: =IFERROR(IF(AND(14>=ASSUMPTIONS!$C$42,ASSUMPTIONS!$C$42>0),ASSUMPTIONS!$D$42/12*(ASSUMPTIONS!$B$53),0),0) -> 8666.6667 | P7: =IFERROR(IF(AND(15>=ASSUMPTIONS!$C$42,ASSUMPTIONS!$C$42>0),ASSUMPTIONS!$D$42/12*(ASSUMPTIONS!$B$53),0),0) -> 8666.6667 | Q7: =IFERROR(IF(AND(16>=ASSUMPTIONS!$C$42,ASSUMPTIONS!$C$42>0),ASSUMPTIONS!$D$42/12*(ASSUMPTIONS!$B$53),0),0) -> 8666.6667 | R7: =IFERROR(IF(AND(17>=ASSUMPTIONS!$C$42,ASSUMPTIONS!$C$42>0),ASSUMPTIONS!$D$42/12*(ASSUMPTIONS!$B$53),0),0) -> 8666.6667 | S7: =IFERROR(IF(AND(18>=ASSUMPTIONS!$C$42,ASSUMPTIONS!$C$42>0),ASSUMPTIONS!$D$42/12*(ASSUMPTIONS!$B$53),0),0) -> 8666.6667 | T7: =IFERROR(IF(AND(19>=ASSUMPTIONS!$C$42,ASSUMPTIONS!$C$42>0),ASSUMPTIONS!$D$42/12*(ASSUMPTIONS!$B$53),0),0) -> 8666.6667 | U7: =IFERROR(IF(AND(20>=ASSUMPTIONS!$C$42,ASSUMPTIONS!$C$42>0),ASSUMPTIONS!$D$42/12*(ASSUMPTIONS!$B$53),0),0) -> 8666.6667 | V7: =IFERROR(IF(AND(21>=ASSUMPTIONS!$C$42,ASSUMPTIONS!$C$42>0),ASSUMPTIONS!$D$42/12*(ASSUMPTIONS!$B$53),0),0) -> 8666.6667 | W7: =IFERROR(IF(AND(22>=ASSUMPTIONS!$C$42,ASSUMPTIONS!$C$42>0),ASSUMPTIONS!$D$42/12*(ASSUMPTIONS!$B$53),0),0) -> 8666.6667 | X7: =IFERROR(IF(AND(23>=ASSUMPTIONS!$C$42,ASSUMPTIONS!$C$42>0),ASSUMPTIONS!$D$42/12*(ASSUMPTIONS!$B$53),0),0) -> 8666.6667 | Y7: =IFERROR(IF(AND(24>=ASSUMPTIONS!$C$42,ASSUMPTIONS!$C$42>0),ASSUMPTIONS!$D$42/12*(ASSUMPTIONS!$B$53),0),0) -> 8666.6667
A8: =IFERROR(ASSUMPTIONS!B43,"") -> CTO | B8: =IFERROR(IF(AND(1>=ASSUMPTIONS!$C$43,ASSUMPTIONS!$C$43>0),ASSUMPTIONS!$D$43/12*(ASSUMPTIONS!$B$53),0),0) -> 8666.6667 | C8: =IFERROR(IF(AND(2>=ASSUMPTIONS!$C$43,ASSUMPTIONS!$C$43>0),ASSUMPTIONS!$D$43/12*(ASSUMPTIONS!$B$53),0),0) -> 8666.6667 | D8: =IFERROR(IF(AND(3>=ASSUMPTIONS!$C$43,ASSUMPTIONS!$C$43>0),ASSUMPTIONS!$D$43/12*(ASSUMPTIONS!$B$53),0),0) -> 8666.6667 | E8: =IFERROR(IF(AND(4>=ASSUMPTIONS!$C$43,ASSUMPTIONS!$C$43>0),ASSUMPTIONS!$D$43/12*(ASSUMPTIONS!$B$53),0),0) -> 8666.6667 | F8: =IFERROR(IF(AND(5>=ASSUMPTIONS!$C$43,ASSUMPTIONS!$C$43>0),ASSUMPTIONS!$D$43/12*(ASSUMPTIONS!$B$53),0),0) -> 8666.6667 | G8: =IFERROR(IF(AND(6>=ASSUMPTIONS!$C$43,ASSUMPTIONS!$C$43>0),ASSUMPTIONS!$D$43/12*(ASSUMPTIONS!$B$53),0),0) -> 8666.6667 | H8: =IFERROR(IF(AND(7>=ASSUMPTIONS!$C$43,ASSUMPTIONS!$C$43>0),ASSUMPTIONS!$D$43/12*(ASSUMPTIONS!$B$53),0),0) -> 8666.6667 | I8: =IFERROR(IF(AND(8>=ASSUMPTIONS!$C$43,ASSUMPTIONS!$C$43>0),ASSUMPTIONS!$D$43/12*(ASSUMPTIONS!$B$53),0),0) -> 8666.6667 | J8: =IFERROR(IF(AND(9>=ASSUMPTIONS!$C$43,ASSUMPTIONS!$C$43>0),ASSUMPTIONS!$D$43/12*(ASSUMPTIONS!$B$53),0),0) -> 8666.6667 | K8: =IFERROR(IF(AND(10>=ASSUMPTIONS!$C$43,ASSUMPTIONS!$C$43>0),ASSUMPTIONS!$D$43/12*(ASSUMPTIONS!$B$53),0),0) -> 8666.6667 | L8: =IFERROR(IF(AND(11>=ASSUMPTIONS!$C$43,ASSUMPTIONS!$C$43>0),ASSUMPTIONS!$D$43/12*(ASSUMPTIONS!$B$53),0),0) -> 8666.6667 | M8: =IFERROR(IF(AND(12>=ASSUMPTIONS!$C$43,ASSUMPTIONS!$C$43>0),ASSUMPTIONS!$D$43/12*(ASSUMPTIONS!$B$53),0),0) -> 8666.6667 | N8: =IFERROR(IF(AND(13>=ASSUMPTIONS!$C$43,ASSUMPTIONS!$C$43>0),ASSUMPTIONS!$D$43/12*(ASSUMPTIONS!$B$53),0),0) -> 8666.6667 | O8: =IFERROR(IF(AND(14>=ASSUMPTIONS!$C$43,ASSUMPTIONS!$C$43>0),ASSUMPTIONS!$D$43/12*(ASSUMPTIONS!$B$53),0),0) -> 8666.6667 | P8: =IFERROR(IF(AND(15>=ASSUMPTIONS!$C$43,ASSUMPTIONS!$C$43>0),ASSUMPTIONS!$D$43/12*(ASSUMPTIONS!$B$53),0),0) -> 8666.6667 | Q8: =IFERROR(IF(AND(16>=ASSUMPTIONS!$C$43,ASSUMPTIONS!$C$43>0),ASSUMPTIONS!$D$43/12*(ASSUMPTIONS!$B$53),0),0) -> 8666.6667 | R8: =IFERROR(IF(AND(17>=ASSUMPTIONS!$C$43,ASSUMPTIONS!$C$43>0),ASSUMPTIONS!$D$43/12*(ASSUMPTIONS!$B$53),0),0) -> 8666.6667 | S8: =IFERROR(IF(AND(18>=ASSUMPTIONS!$C$43,ASSUMPTIONS!$C$43>0),ASSUMPTIONS!$D$43/12*(ASSUMPTIONS!$B$53),0),0) -> 8666.6667 | T8: =IFERROR(IF(AND(19>=ASSUMPTIONS!$C$43,ASSUMPTIONS!$C$43>0),ASSUMPTIONS!$D$43/12*(ASSUMPTIONS!$B$53),0),0) -> 8666.6667 | U8: =IFERROR(IF(AND(20>=ASSUMPTIONS!$C$43,ASSUMPTIONS!$C$43>0),ASSUMPTIONS!$D$43/12*(ASSUMPTIONS!$B$53),0),0) -> 8666.6667 | V8: =IFERROR(IF(AND(21>=ASSUMPTIONS!$C$43,ASSUMPTIONS!$C$43>0),ASSUMPTIONS!$D$43/12*(ASSUMPTIONS!$B$53),0),0) -> 8666.6667 | W8: =IFERROR(IF(AND(22>=ASSUMPTIONS!$C$43,ASSUMPTIONS!$C$43>0),ASSUMPTIONS!$D$43/12*(ASSUMPTIONS!$B$53),0),0) -> 8666.6667 | X8: =IFERROR(IF(AND(23>=ASSUMPTIONS!$C$43,ASSUMPTIONS!$C$43>0),ASSUMPTIONS!$D$43/12*(ASSUMPTIONS!$B$53),0),0) -> 8666.6667 | Y8: =IFERROR(IF(AND(24>=ASSUMPTIONS!$C$43,ASSUMPTIONS!$C$43>0),ASSUMPTIONS!$D$43/12*(ASSUMPTIONS!$B$53),0),0) -> 8666.6667
A9: =IFERROR(ASSUMPTIONS!B44,"") -> Eng #1 | B9: =IFERROR(IF(AND(1>=ASSUMPTIONS!$C$44,ASSUMPTIONS!$C$44>0),ASSUMPTIONS!$D$44/12*(ASSUMPTIONS!$B$53),0),0) -> 10833.333 | C9: =IFERROR(IF(AND(2>=ASSUMPTIONS!$C$44,ASSUMPTIONS!$C$44>0),ASSUMPTIONS!$D$44/12*(ASSUMPTIONS!$B$53),0),0) -> 10833.333 | D9: =IFERROR(IF(AND(3>=ASSUMPTIONS!$C$44,ASSUMPTIONS!$C$44>0),ASSUMPTIONS!$D$44/12*(ASSUMPTIONS!$B$53),0),0) -> 10833.333 | E9: =IFERROR(IF(AND(4>=ASSUMPTIONS!$C$44,ASSUMPTIONS!$C$44>0),ASSUMPTIONS!$D$44/12*(ASSUMPTIONS!$B$53),0),0) -> 10833.333 | F9: =IFERROR(IF(AND(5>=ASSUMPTIONS!$C$44,ASSUMPTIONS!$C$44>0),ASSUMPTIONS!$D$44/12*(ASSUMPTIONS!$B$53),0),0) -> 10833.333 | G9: =IFERROR(IF(AND(6>=ASSUMPTIONS!$C$44,ASSUMPTIONS!$C$44>0),ASSUMPTIONS!$D$44/12*(ASSUMPTIONS!$B$53),0),0) -> 10833.333 | H9: =IFERROR(IF(AND(7>=ASSUMPTIONS!$C$44,ASSUMPTIONS!$C$44>0),ASSUMPTIONS!$D$44/12*(ASSUMPTIONS!$B$53),0),0) -> 10833.333 | I9: =IFERROR(IF(AND(8>=ASSUMPTIONS!$C$44,ASSUMPTIONS!$C$44>0),ASSUMPTIONS!$D$44/12*(ASSUMPTIONS!$B$53),0),0) -> 10833.333 | J9: =IFERROR(IF(AND(9>=ASSUMPTIONS!$C$44,ASSUMPTIONS!$C$44>0),ASSUMPTIONS!$D$44/12*(ASSUMPTIONS!$B$53),0),0) -> 10833.333 | K9: =IFERROR(IF(AND(10>=ASSUMPTIONS!$C$44,ASSUMPTIONS!$C$44>0),ASSUMPTIONS!$D$44/12*(ASSUMPTIONS!$B$53),0),0) -> 10833.333 | L9: =IFERROR(IF(AND(11>=ASSUMPTIONS!$C$44,ASSUMPTIONS!$C$44>0),ASSUMPTIONS!$D$44/12*(ASSUMPTIONS!$B$53),0),0) -> 10833.333 | M9: =IFERROR(IF(AND(12>=ASSUMPTIONS!$C$44,ASSUMPTIONS!$C$44>0),ASSUMPTIONS!$D$44/12*(ASSUMPTIONS!$B$53),0),0) -> 10833.333 | N9: =IFERROR(IF(AND(13>=ASSUMPTIONS!$C$44,ASSUMPTIONS!$C$44>0),ASSUMPTIONS!$D$44/12*(ASSUMPTIONS!$B$53),0),0) -> 10833.333 | O9: =IFERROR(IF(AND(14>=ASSUMPTIONS!$C$44,ASSUMPTIONS!$C$44>0),ASSUMPTIONS!$D$44/12*(ASSUMPTIONS!$B$53),0),0) -> 10833.333 | P9: =IFERROR(IF(AND(15>=ASSUMPTIONS!$C$44,ASSUMPTIONS!$C$44>0),ASSUMPTIONS!$D$44/12*(ASSUMPTIONS!$B$53),0),0) -> 10833.333 | Q9: =IFERROR(IF(AND(16>=ASSUMPTIONS!$C$44,ASSUMPTIONS!$C$44>0),ASSUMPTIONS!$D$44/12*(ASSUMPTIONS!$B$53),0),0) -> 10833.333 | R9: =IFERROR(IF(AND(17>=ASSUMPTIONS!$C$44,ASSUMPTIONS!$C$44>0),ASSUMPTIONS!$D$44/12*(ASSUMPTIONS!$B$53),0),0) -> 10833.333 | S9: =IFERROR(IF(AND(18>=ASSUMPTIONS!$C$44,ASSUMPTIONS!$C$44>0),ASSUMPTIONS!$D$44/12*(ASSUMPTIONS!$B$53),0),0) -> 10833.333 | T9: =IFERROR(IF(AND(19>=ASSUMPTIONS!$C$44,ASSUMPTIONS!$C$44>0),ASSUMPTIONS!$D$44/12*(ASSUMPTIONS!$B$53),0),0) -> 10833.333 | U9: =IFERROR(IF(AND(20>=ASSUMPTIONS!$C$44,ASSUMPTIONS!$C$44>0),ASSUMPTIONS!$D$44/12*(ASSUMPTIONS!$B$53),0),0) -> 10833.333 | V9: =IFERROR(IF(AND(21>=ASSUMPTIONS!$C$44,ASSUMPTIONS!$C$44>0),ASSUMPTIONS!$D$44/12*(ASSUMPTIONS!$B$53),0),0) -> 10833.333 | W9: =IFERROR(IF(AND(22>=ASSUMPTIONS!$C$44,ASSUMPTIONS!$C$44>0),ASSUMPTIONS!$D$44/12*(ASSUMPTIONS!$B$53),0),0) -> 10833.333 | X9: =IFERROR(IF(AND(23>=ASSUMPTIONS!$C$44,ASSUMPTIONS!$C$44>0),ASSUMPTIONS!$D$44/12*(ASSUMPTIONS!$B$53),0),0) -> 10833.333 | Y9: =IFERROR(IF(AND(24>=ASSUMPTIONS!$C$44,ASSUMPTIONS!$C$44>0),ASSUMPTIONS!$D$44/12*(ASSUMPTIONS!$B$53),0),0) -> 10833.333
A10: =IFERROR(ASSUMPTIONS!B45,"") -> Eng #2 | B10: =IFERROR(IF(AND(1>=ASSUMPTIONS!$C$45,ASSUMPTIONS!$C$45>0),ASSUMPTIONS!$D$45/12*(ASSUMPTIONS!$B$53),0),0) -> 0 | C10: =IFERROR(IF(AND(2>=ASSUMPTIONS!$C$45,ASSUMPTIONS!$C$45>0),ASSUMPTIONS!$D$45/12*(ASSUMPTIONS!$B$53),0),0) -> 0 | D10: =IFERROR(IF(AND(3>=ASSUMPTIONS!$C$45,ASSUMPTIONS!$C$45>0),ASSUMPTIONS!$D$45/12*(ASSUMPTIONS!$B$53),0),0) -> 10833.333 | E10: =IFERROR(IF(AND(4>=ASSUMPTIONS!$C$45,ASSUMPTIONS!$C$45>0),ASSUMPTIONS!$D$45/12*(ASSUMPTIONS!$B$53),0),0) -> 10833.333 | F10: =IFERROR(IF(AND(5>=ASSUMPTIONS!$C$45,ASSUMPTIONS!$C$45>0),ASSUMPTIONS!$D$45/12*(ASSUMPTIONS!$B$53),0),0) -> 10833.333 | G10: =IFERROR(IF(AND(6>=ASSUMPTIONS!$C$45,ASSUMPTIONS!$C$45>0),ASSUMPTIONS!$D$45/12*(ASSUMPTIONS!$B$53),0),0) -> 10833.333 | H10: =IFERROR(IF(AND(7>=ASSUMPTIONS!$C$45,ASSUMPTIONS!$C$45>0),ASSUMPTIONS!$D$45/12*(ASSUMPTIONS!$B$53),0),0) -> 10833.333 | I10: =IFERROR(IF(AND(8>=ASSUMPTIONS!$C$45,ASSUMPTIONS!$C$45>0),ASSUMPTIONS!$D$45/12*(ASSUMPTIONS!$B$53),0),0) -> 10833.333 | J10: =IFERROR(IF(AND(9>=ASSUMPTIONS!$C$45,ASSUMPTIONS!$C$45>0),ASSUMPTIONS!$D$45/12*(ASSUMPTIONS!$B$53),0),0) -> 10833.333 | K10: =IFERROR(IF(AND(10>=ASSUMPTIONS!$C$45,ASSUMPTIONS!$C$45>0),ASSUMPTIONS!$D$45/12*(ASSUMPTIONS!$B$53),0),0) -> 10833.333 | L10: =IFERROR(IF(AND(11>=ASSUMPTIONS!$C$45,ASSUMPTIONS!$C$45>0),ASSUMPTIONS!$D$45/12*(ASSUMPTIONS!$B$53),0),0) -> 10833.333 | M10: =IFERROR(IF(AND(12>=ASSUMPTIONS!$C$45,ASSUMPTIONS!$C$45>0),ASSUMPTIONS!$D$45/12*(ASSUMPTIONS!$B$53),0),0) -> 10833.333 | N10: =IFERROR(IF(AND(13>=ASSUMPTIONS!$C$45,ASSUMPTIONS!$C$45>0),ASSUMPTIONS!$D$45/12*(ASSUMPTIONS!$B$53),0),0) -> 10833.333 | O10: =IFERROR(IF(AND(14>=ASSUMPTIONS!$C$45,ASSUMPTIONS!$C$45>0),ASSUMPTIONS!$D$45/12*(ASSUMPTIONS!$B$53),0),0) -> 10833.333 | P10: =IFERROR(IF(AND(15>=ASSUMPTIONS!$C$45,ASSUMPTIONS!$C$45>0),ASSUMPTIONS!$D$45/12*(ASSUMPTIONS!$B$53),0),0) -> 10833.333 | Q10: =IFERROR(IF(AND(16>=ASSUMPTIONS!$C$45,ASSUMPTIONS!$C$45>0),ASSUMPTIONS!$D$45/12*(ASSUMPTIONS!$B$53),0),0) -> 10833.333 | R10: =IFERROR(IF(AND(17>=ASSUMPTIONS!$C$45,ASSUMPTIONS!$C$45>0),ASSUMPTIONS!$D$45/12*(ASSUMPTIONS!$B$53),0),0) -> 10833.333 | S10: =IFERROR(IF(AND(18>=ASSUMPTIONS!$C$45,ASSUMPTIONS!$C$45>0),ASSUMPTIONS!$D$45/12*(ASSUMPTIONS!$B$53),0),0) -> 10833.333 | T10: =IFERROR(IF(AND(19>=ASSUMPTIONS!$C$45,ASSUMPTIONS!$C$45>0),ASSUMPTIONS!$D$45/12*(ASSUMPTIONS!$B$53),0),0) -> 10833.333 | U10: =IFERROR(IF(AND(20>=ASSUMPTIONS!$C$45,ASSUMPTIONS!$C$45>0),ASSUMPTIONS!$D$45/12*(ASSUMPTIONS!$B$53),0),0) -> 10833.333 | V10: =IFERROR(IF(AND(21>=ASSUMPTIONS!$C$45,ASSUMPTIONS!$C$45>0),ASSUMPTIONS!$D$45/12*(ASSUMPTIONS!$B$53),0),0) -> 10833.333 | W10: =IFERROR(IF(AND(22>=ASSUMPTIONS!$C$45,ASSUMPTIONS!$C$45>0),ASSUMPTIONS!$D$45/12*(ASSUMPTIONS!$B$53),0),0) -> 10833.333 | X10: =IFERROR(IF(AND(23>=ASSUMPTIONS!$C$45,ASSUMPTIONS!$C$45>0),ASSUMPTIONS!$D$45/12*(ASSUMPTIONS!$B$53),0),0) -> 10833.333 | Y10: =IFERROR(IF(AND(24>=ASSUMPTIONS!$C$45,ASSUMPTIONS!$C$45>0),ASSUMPTIONS!$D$45/12*(ASSUMPTIONS!$B$53),0),0) -> 10833.333
A11: =IFERROR(ASSUMPTIONS!B46,"") -> Eng #3 | B11: =IFERROR(IF(AND(1>=ASSUMPTIONS!$C$46,ASSUMPTIONS!$C$46>0),ASSUMPTIONS!$D$46/12*(ASSUMPTIONS!$B$53),0),0) -> 0 | C11: =IFERROR(IF(AND(2>=ASSUMPTIONS!$C$46,ASSUMPTIONS!$C$46>0),ASSUMPTIONS!$D$46/12*(ASSUMPTIONS!$B$53),0),0) -> 0 | D11: =IFERROR(IF(AND(3>=ASSUMPTIONS!$C$46,ASSUMPTIONS!$C$46>0),ASSUMPTIONS!$D$46/12*(ASSUMPTIONS!$B$53),0),0) -> 0 | E11: =IFERROR(IF(AND(4>=ASSUMPTIONS!$C$46,ASSUMPTIONS!$C$46>0),ASSUMPTIONS!$D$46/12*(ASSUMPTIONS!$B$53),0),0) -> 0 | F11: =IFERROR(IF(AND(5>=ASSUMPTIONS!$C$46,ASSUMPTIONS!$C$46>0),ASSUMPTIONS!$D$46/12*(ASSUMPTIONS!$B$53),0),0) -> 0 | G11: =IFERROR(IF(AND(6>=ASSUMPTIONS!$C$46,ASSUMPTIONS!$C$46>0),ASSUMPTIONS!$D$46/12*(ASSUMPTIONS!$B$53),0),0) -> 10833.333 | H11: =IFERROR(IF(AND(7>=ASSUMPTIONS!$C$46,ASSUMPTIONS!$C$46>0),ASSUMPTIONS!$D$46/12*(ASSUMPTIONS!$B$53),0),0) -> 10833.333 | I11: =IFERROR(IF(AND(8>=ASSUMPTIONS!$C$46,ASSUMPTIONS!$C$46>0),ASSUMPTIONS!$D$46/12*(ASSUMPTIONS!$B$53),0),0) -> 10833.333 | J11: =IFERROR(IF(AND(9>=ASSUMPTIONS!$C$46,ASSUMPTIONS!$C$46>0),ASSUMPTIONS!$D$46/12*(ASSUMPTIONS!$B$53),0),0) -> 10833.333 | K11: =IFERROR(IF(AND(10>=ASSUMPTIONS!$C$46,ASSUMPTIONS!$C$46>0),ASSUMPTIONS!$D$46/12*(ASSUMPTIONS!$B$53),0),0) -> 10833.333 | L11: =IFERROR(IF(AND(11>=ASSUMPTIONS!$C$46,ASSUMPTIONS!$C$46>0),ASSUMPTIONS!$D$46/12*(ASSUMPTIONS!$B$53),0),0) -> 10833.333 | M11: =IFERROR(IF(AND(12>=ASSUMPTIONS!$C$46,ASSUMPTIONS!$C$46>0),ASSUMPTIONS!$D$46/12*(ASSUMPTIONS!$B$53),0),0) -> 10833.333 | N11: =IFERROR(IF(AND(13>=ASSUMPTIONS!$C$46,ASSUMPTIONS!$C$46>0),ASSUMPTIONS!$D$46/12*(ASSUMPTIONS!$B$53),0),0) -> 10833.333 | O11: =IFERROR(IF(AND(14>=ASSUMPTIONS!$C$46,ASSUMPTIONS!$C$46>0),ASSUMPTIONS!$D$46/12*(ASSUMPTIONS!$B$53),0),0) -> 10833.333 | P11: =IFERROR(IF(AND(15>=ASSUMPTIONS!$C$46,ASSUMPTIONS!$C$46>0),ASSUMPTIONS!$D$46/12*(ASSUMPTIONS!$B$53),0),0) -> 10833.333 | Q11: =IFERROR(IF(AND(16>=ASSUMPTIONS!$C$46,ASSUMPTIONS!$C$46>0),ASSUMPTIONS!$D$46/12*(ASSUMPTIONS!$B$53),0),0) -> 10833.333 | R11: =IFERROR(IF(AND(17>=ASSUMPTIONS!$C$46,ASSUMPTIONS!$C$46>0),ASSUMPTIONS!$D$46/12*(ASSUMPTIONS!$B$53),0),0) -> 10833.333 | S11: =IFERROR(IF(AND(18>=ASSUMPTIONS!$C$46,ASSUMPTIONS!$C$46>0),ASSUMPTIONS!$D$46/12*(ASSUMPTIONS!$B$53),0),0) -> 10833.333 | T11: =IFERROR(IF(AND(19>=ASSUMPTIONS!$C$46,ASSUMPTIONS!$C$46>0),ASSUMPTIONS!$D$46/12*(ASSUMPTIONS!$B$53),0),0) -> 10833.333 | U11: =IFERROR(IF(AND(20>=ASSUMPTIONS!$C$46,ASSUMPTIONS!$C$46>0),ASSUMPTIONS!$D$46/12*(ASSUMPTIONS!$B$53),0),0) -> 10833.333 | V11: =IFERROR(IF(AND(21>=ASSUMPTIONS!$C$46,ASSUMPTIONS!$C$46>0),ASSUMPTIONS!$D$46/12*(ASSUMPTIONS!$B$53),0),0) -> 10833.333 | W11: =IFERROR(IF(AND(22>=ASSUMPTIONS!$C$46,ASSUMPTIONS!$C$46>0),ASSUMPTIONS!$D$46/12*(ASSUMPTIONS!$B$53),0),0) -> 10833.333 | X11: =IFERROR(IF(AND(23>=ASSUMPTIONS!$C$46,ASSUMPTIONS!$C$46>0),ASSUMPTIONS!$D$46/12*(ASSUMPTIONS!$B$53),0),0) -> 10833.333 | Y11: =IFERROR(IF(AND(24>=ASSUMPTIONS!$C$46,ASSUMPTIONS!$C$46>0),ASSUMPTIONS!$D$46/12*(ASSUMPTIONS!$B$53),0),0) -> 10833.333
A12: =IFERROR(ASSUMPTIONS!B47,"") -> Designer | B12: =IFERROR(IF(AND(1>=ASSUMPTIONS!$C$47,ASSUMPTIONS!$C$47>0),ASSUMPTIONS!$D$47/12*(ASSUMPTIONS!$B$53),0),0) -> 0 | C12: =IFERROR(IF(AND(2>=ASSUMPTIONS!$C$47,ASSUMPTIONS!$C$47>0),ASSUMPTIONS!$D$47/12*(ASSUMPTIONS!$B$53),0),0) -> 0 | D12: =IFERROR(IF(AND(3>=ASSUMPTIONS!$C$47,ASSUMPTIONS!$C$47>0),ASSUMPTIONS!$D$47/12*(ASSUMPTIONS!$B$53),0),0) -> 8666.6667 | E12: =IFERROR(IF(AND(4>=ASSUMPTIONS!$C$47,ASSUMPTIONS!$C$47>0),ASSUMPTIONS!$D$47/12*(ASSUMPTIONS!$B$53),0),0) -> 8666.6667 | F12: =IFERROR(IF(AND(5>=ASSUMPTIONS!$C$47,ASSUMPTIONS!$C$47>0),ASSUMPTIONS!$D$47/12*(ASSUMPTIONS!$B$53),0),0) -> 8666.6667 | G12: =IFERROR(IF(AND(6>=ASSUMPTIONS!$C$47,ASSUMPTIONS!$C$47>0),ASSUMPTIONS!$D$47/12*(ASSUMPTIONS!$B$53),0),0) -> 8666.6667 | H12: =IFERROR(IF(AND(7>=ASSUMPTIONS!$C$47,ASSUMPTIONS!$C$47>0),ASSUMPTIONS!$D$47/12*(ASSUMPTIONS!$B$53),0),0) -> 8666.6667 | I12: =IFERROR(IF(AND(8>=ASSUMPTIONS!$C$47,ASSUMPTIONS!$C$47>0),ASSUMPTIONS!$D$47/12*(ASSUMPTIONS!$B$53),0),0) -> 8666.6667 | J12: =IFERROR(IF(AND(9>=ASSUMPTIONS!$C$47,ASSUMPTIONS!$C$47>0),ASSUMPTIONS!$D$47/12*(ASSUMPTIONS!$B$53),0),0) -> 8666.6667 | K12: =IFERROR(IF(AND(10>=ASSUMPTIONS!$C$47,ASSUMPTIONS!$C$47>0),ASSUMPTIONS!$D$47/12*(ASSUMPTIONS!$B$53),0),0) -> 8666.6667 | L12: =IFERROR(IF(AND(11>=ASSUMPTIONS!$C$47,ASSUMPTIONS!$C$47>0),ASSUMPTIONS!$D$47/12*(ASSUMPTIONS!$B$53),0),0) -> 8666.6667 | M12: =IFERROR(IF(AND(12>=ASSUMPTIONS!$C$47,ASSUMPTIONS!$C$47>0),ASSUMPTIONS!$D$47/12*(ASSUMPTIONS!$B$53),0),0) -> 8666.6667 | N12: =IFERROR(IF(AND(13>=ASSUMPTIONS!$C$47,ASSUMPTIONS!$C$47>0),ASSUMPTIONS!$D$47/12*(ASSUMPTIONS!$B$53),0),0) -> 8666.6667 | O12: =IFERROR(IF(AND(14>=ASSUMPTIONS!$C$47,ASSUMPTIONS!$C$47>0),ASSUMPTIONS!$D$47/12*(ASSUMPTIONS!$B$53),0),0) -> 8666.6667 | P12: =IFERROR(IF(AND(15>=ASSUMPTIONS!$C$47,ASSUMPTIONS!$C$47>0),ASSUMPTIONS!$D$47/12*(ASSUMPTIONS!$B$53),0),0) -> 8666.6667 | Q12: =IFERROR(IF(AND(16>=ASSUMPTIONS!$C$47,ASSUMPTIONS!$C$47>0),ASSUMPTIONS!$D$47/12*(ASSUMPTIONS!$B$53),0),0) -> 8666.6667 | R12: =IFERROR(IF(AND(17>=ASSUMPTIONS!$C$47,ASSUMPTIONS!$C$47>0),ASSUMPTIONS!$D$47/12*(ASSUMPTIONS!$B$53),0),0) -> 8666.6667 | S12: =IFERROR(IF(AND(18>=ASSUMPTIONS!$C$47,ASSUMPTIONS!$C$47>0),ASSUMPTIONS!$D$47/12*(ASSUMPTIONS!$B$53),0),0) -> 8666.6667 | T12: =IFERROR(IF(AND(19>=ASSUMPTIONS!$C$47,ASSUMPTIONS!$C$47>0),ASSUMPTIONS!$D$47/12*(ASSUMPTIONS!$B$53),0),0) -> 8666.6667 | U12: =IFERROR(IF(AND(20>=ASSUMPTIONS!$C$47,ASSUMPTIONS!$C$47>0),ASSUMPTIONS!$D$47/12*(ASSUMPTIONS!$B$53),0),0) -> 8666.6667 | V12: =IFERROR(IF(AND(21>=ASSUMPTIONS!$C$47,ASSUMPTIONS!$C$47>0),ASSUMPTIONS!$D$47/12*(ASSUMPTIONS!$B$53),0),0) -> 8666.6667 | W12: =IFERROR(IF(AND(22>=ASSUMPTIONS!$C$47,ASSUMPTIONS!$C$47>0),ASSUMPTIONS!$D$47/12*(ASSUMPTIONS!$B$53),0),0) -> 8666.6667 | X12: =IFERROR(IF(AND(23>=ASSUMPTIONS!$C$47,ASSUMPTIONS!$C$47>0),ASSUMPTIONS!$D$47/12*(ASSUMPTIONS!$B$53),0),0) -> 8666.6667 | Y12: =IFERROR(IF(AND(24>=ASSUMPTIONS!$C$47,ASSUMPTIONS!$C$47>0),ASSUMPTIONS!$D$47/12*(ASSUMPTIONS!$B$53),0),0) -> 8666.6667
A13: =IFERROR(ASSUMPTIONS!B48,"") -> Sales Lead | B13: =IFERROR(IF(AND(1>=ASSUMPTIONS!$C$48,ASSUMPTIONS!$C$48>0),ASSUMPTIONS!$D$48/12*(ASSUMPTIONS!$B$53),0),0) -> 0 | C13: =IFERROR(IF(AND(2>=ASSUMPTIONS!$C$48,ASSUMPTIONS!$C$48>0),ASSUMPTIONS!$D$48/12*(ASSUMPTIONS!$B$53),0),0) -> 0 | D13: =IFERROR(IF(AND(3>=ASSUMPTIONS!$C$48,ASSUMPTIONS!$C$48>0),ASSUMPTIONS!$D$48/12*(ASSUMPTIONS!$B$53),0),0) -> 0 | E13: =IFERROR(IF(AND(4>=ASSUMPTIONS!$C$48,ASSUMPTIONS!$C$48>0),ASSUMPTIONS!$D$48/12*(ASSUMPTIONS!$B$53),0),0) -> 9208.3333 | F13: =IFERROR(IF(AND(5>=ASSUMPTIONS!$C$48,ASSUMPTIONS!$C$48>0),ASSUMPTIONS!$D$48/12*(ASSUMPTIONS!$B$53),0),0) -> 9208.3333 | G13: =IFERROR(IF(AND(6>=ASSUMPTIONS!$C$48,ASSUMPTIONS!$C$48>0),ASSUMPTIONS!$D$48/12*(ASSUMPTIONS!$B$53),0),0) -> 9208.3333 | H13: =IFERROR(IF(AND(7>=ASSUMPTIONS!$C$48,ASSUMPTIONS!$C$48>0),ASSUMPTIONS!$D$48/12*(ASSUMPTIONS!$B$53),0),0) -> 9208.3333 | I13: =IFERROR(IF(AND(8>=ASSUMPTIONS!$C$48,ASSUMPTIONS!$C$48>0),ASSUMPTIONS!$D$48/12*(ASSUMPTIONS!$B$53),0),0) -> 9208.3333 | J13: =IFERROR(IF(AND(9>=ASSUMPTIONS!$C$48,ASSUMPTIONS!$C$48>0),ASSUMPTIONS!$D$48/12*(ASSUMPTIONS!$B$53),0),0) -> 9208.3333 | K13: =IFERROR(IF(AND(10>=ASSUMPTIONS!$C$48,ASSUMPTIONS!$C$48>0),ASSUMPTIONS!$D$48/12*(ASSUMPTIONS!$B$53),0),0) -> 9208.3333 | L13: =IFERROR(IF(AND(11>=ASSUMPTIONS!$C$48,ASSUMPTIONS!$C$48>0),ASSUMPTIONS!$D$48/12*(ASSUMPTIONS!$B$53),0),0) -> 9208.3333 | M13: =IFERROR(IF(AND(12>=ASSUMPTIONS!$C$48,ASSUMPTIONS!$C$48>0),ASSUMPTIONS!$D$48/12*(ASSUMPTIONS!$B$53),0),0) -> 9208.3333 | N13: =IFERROR(IF(AND(13>=ASSUMPTIONS!$C$48,ASSUMPTIONS!$C$48>0),ASSUMPTIONS!$D$48/12*(ASSUMPTIONS!$B$53),0),0) -> 9208.3333 | O13: =IFERROR(IF(AND(14>=ASSUMPTIONS!$C$48,ASSUMPTIONS!$C$48>0),ASSUMPTIONS!$D$48/12*(ASSUMPTIONS!$B$53),0),0) -> 9208.3333 | P13: =IFERROR(IF(AND(15>=ASSUMPTIONS!$C$48,ASSUMPTIONS!$C$48>0),ASSUMPTIONS!$D$48/12*(ASSUMPTIONS!$B$53),0),0) -> 9208.3333 | Q13: =IFERROR(IF(AND(16>=ASSUMPTIONS!$C$48,ASSUMPTIONS!$C$48>0),ASSUMPTIONS!$D$48/12*(ASSUMPTIONS!$B$53),0),0) -> 9208.3333 | R13: =IFERROR(IF(AND(17>=ASSUMPTIONS!$C$48,ASSUMPTIONS!$C$48>0),ASSUMPTIONS!$D$48/12*(ASSUMPTIONS!$B$53),0),0) -> 9208.3333 | S13: =IFERROR(IF(AND(18>=ASSUMPTIONS!$C$48,ASSUMPTIONS!$C$48>0),ASSUMPTIONS!$D$48/12*(ASSUMPTIONS!$B$53),0),0) -> 9208.3333 | T13: =IFERROR(IF(AND(19>=ASSUMPTIONS!$C$48,ASSUMPTIONS!$C$48>0),ASSUMPTIONS!$D$48/12*(ASSUMPTIONS!$B$53),0),0) -> 9208.3333 | U13: =IFERROR(IF(AND(20>=ASSUMPTIONS!$C$48,ASSUMPTIONS!$C$48>0),ASSUMPTIONS!$D$48/12*(ASSUMPTIONS!$B$53),0),0) -> 9208.3333 | V13: =IFERROR(IF(AND(21>=ASSUMPTIONS!$C$48,ASSUMPTIONS!$C$48>0),ASSUMPTIONS!$D$48/12*(ASSUMPTIONS!$B$53),0),0) -> 9208.3333 | W13: =IFERROR(IF(AND(22>=ASSUMPTIONS!$C$48,ASSUMPTIONS!$C$48>0),ASSUMPTIONS!$D$48/12*(ASSUMPTIONS!$B$53),0),0) -> 9208.3333 | X13: =IFERROR(IF(AND(23>=ASSUMPTIONS!$C$48,ASSUMPTIONS!$C$48>0),ASSUMPTIONS!$D$48/12*(ASSUMPTIONS!$B$53),0),0) -> 9208.3333 | Y13: =IFERROR(IF(AND(24>=ASSUMPTIONS!$C$48,ASSUMPTIONS!$C$48>0),ASSUMPTIONS!$D$48/12*(ASSUMPTIONS!$B$53),0),0) -> 9208.3333
A14: =IFERROR(ASSUMPTIONS!B49,"") -> Marketing | B14: =IFERROR(IF(AND(1>=ASSUMPTIONS!$C$49,ASSUMPTIONS!$C$49>0),ASSUMPTIONS!$D$49/12*(ASSUMPTIONS!$B$53),0),0) -> 0 | C14: =IFERROR(IF(AND(2>=ASSUMPTIONS!$C$49,ASSUMPTIONS!$C$49>0),ASSUMPTIONS!$D$49/12*(ASSUMPTIONS!$B$53),0),0) -> 0 | D14: =IFERROR(IF(AND(3>=ASSUMPTIONS!$C$49,ASSUMPTIONS!$C$49>0),ASSUMPTIONS!$D$49/12*(ASSUMPTIONS!$B$53),0),0) -> 0 | E14: =IFERROR(IF(AND(4>=ASSUMPTIONS!$C$49,ASSUMPTIONS!$C$49>0),ASSUMPTIONS!$D$49/12*(ASSUMPTIONS!$B$53),0),0) -> 0 | F14: =IFERROR(IF(AND(5>=ASSUMPTIONS!$C$49,ASSUMPTIONS!$C$49>0),ASSUMPTIONS!$D$49/12*(ASSUMPTIONS!$B$53),0),0) -> 0 | G14: =IFERROR(IF(AND(6>=ASSUMPTIONS!$C$49,ASSUMPTIONS!$C$49>0),ASSUMPTIONS!$D$49/12*(ASSUMPTIONS!$B$53),0),0) -> 8125 | H14: =IFERROR(IF(AND(7>=ASSUMPTIONS!$C$49,ASSUMPTIONS!$C$49>0),ASSUMPTIONS!$D$49/12*(ASSUMPTIONS!$B$53),0),0) -> 8125 | I14: =IFERROR(IF(AND(8>=ASSUMPTIONS!$C$49,ASSUMPTIONS!$C$49>0),ASSUMPTIONS!$D$49/12*(ASSUMPTIONS!$B$53),0),0) -> 8125 | J14: =IFERROR(IF(AND(9>=ASSUMPTIONS!$C$49,ASSUMPTIONS!$C$49>0),ASSUMPTIONS!$D$49/12*(ASSUMPTIONS!$B$53),0),0) -> 8125 | K14: =IFERROR(IF(AND(10>=ASSUMPTIONS!$C$49,ASSUMPTIONS!$C$49>0),ASSUMPTIONS!$D$49/12*(ASSUMPTIONS!$B$53),0),0) -> 8125 | L14: =IFERROR(IF(AND(11>=ASSUMPTIONS!$C$49,ASSUMPTIONS!$C$49>0),ASSUMPTIONS!$D$49/12*(ASSUMPTIONS!$B$53),0),0) -> 8125 | M14: =IFERROR(IF(AND(12>=ASSUMPTIONS!$C$49,ASSUMPTIONS!$C$49>0),ASSUMPTIONS!$D$49/12*(ASSUMPTIONS!$B$53),0),0) -> 8125 | N14: =IFERROR(IF(AND(13>=ASSUMPTIONS!$C$49,ASSUMPTIONS!$C$49>0),ASSUMPTIONS!$D$49/12*(ASSUMPTIONS!$B$53),0),0) -> 8125 | O14: =IFERROR(IF(AND(14>=ASSUMPTIONS!$C$49,ASSUMPTIONS!$C$49>0),ASSUMPTIONS!$D$49/12*(ASSUMPTIONS!$B$53),0),0) -> 8125 | P14: =IFERROR(IF(AND(15>=ASSUMPTIONS!$C$49,ASSUMPTIONS!$C$49>0),ASSUMPTIONS!$D$49/12*(ASSUMPTIONS!$B$53),0),0) -> 8125 | Q14: =IFERROR(IF(AND(16>=ASSUMPTIONS!$C$49,ASSUMPTIONS!$C$49>0),ASSUMPTIONS!$D$49/12*(ASSUMPTIONS!$B$53),0),0) -> 8125 | R14: =IFERROR(IF(AND(17>=ASSUMPTIONS!$C$49,ASSUMPTIONS!$C$49>0),ASSUMPTIONS!$D$49/12*(ASSUMPTIONS!$B$53),0),0) -> 8125 | S14: =IFERROR(IF(AND(18>=ASSUMPTIONS!$C$49,ASSUMPTIONS!$C$49>0),ASSUMPTIONS!$D$49/12*(ASSUMPTIONS!$B$53),0),0) -> 8125 | T14: =IFERROR(IF(AND(19>=ASSUMPTIONS!$C$49,ASSUMPTIONS!$C$49>0),ASSUMPTIONS!$D$49/12*(ASSUMPTIONS!$B$53),0),0) -> 8125 | U14: =IFERROR(IF(AND(20>=ASSUMPTIONS!$C$49,ASSUMPTIONS!$C$49>0),ASSUMPTIONS!$D$49/12*(ASSUMPTIONS!$B$53),0),0) -> 8125 | V14: =IFERROR(IF(AND(21>=ASSUMPTIONS!$C$49,ASSUMPTIONS!$C$49>0),ASSUMPTIONS!$D$49/12*(ASSUMPTIONS!$B$53),0),0) -> 8125 | W14: =IFERROR(IF(AND(22>=ASSUMPTIONS!$C$49,ASSUMPTIONS!$C$49>0),ASSUMPTIONS!$D$49/12*(ASSUMPTIONS!$B$53),0),0) -> 8125 | X14: =IFERROR(IF(AND(23>=ASSUMPTIONS!$C$49,ASSUMPTIONS!$C$49>0),ASSUMPTIONS!$D$49/12*(ASSUMPTIONS!$B$53),0),0) -> 8125 | Y14: =IFERROR(IF(AND(24>=ASSUMPTIONS!$C$49,ASSUMPTIONS!$C$49>0),ASSUMPTIONS!$D$49/12*(ASSUMPTIONS!$B$53),0),0) -> 8125
A15: =IFERROR(ASSUMPTIONS!B50,"") -> CS #1 | B15: =IFERROR(IF(AND(1>=ASSUMPTIONS!$C$50,ASSUMPTIONS!$C$50>0),ASSUMPTIONS!$D$50/12*(ASSUMPTIONS!$B$53),0),0) -> 0 | C15: =IFERROR(IF(AND(2>=ASSUMPTIONS!$C$50,ASSUMPTIONS!$C$50>0),ASSUMPTIONS!$D$50/12*(ASSUMPTIONS!$B$53),0),0) -> 0 | D15: =IFERROR(IF(AND(3>=ASSUMPTIONS!$C$50,ASSUMPTIONS!$C$50>0),ASSUMPTIONS!$D$50/12*(ASSUMPTIONS!$B$53),0),0) -> 0 | E15: =IFERROR(IF(AND(4>=ASSUMPTIONS!$C$50,ASSUMPTIONS!$C$50>0),ASSUMPTIONS!$D$50/12*(ASSUMPTIONS!$B$53),0),0) -> 0 | F15: =IFERROR(IF(AND(5>=ASSUMPTIONS!$C$50,ASSUMPTIONS!$C$50>0),ASSUMPTIONS!$D$50/12*(ASSUMPTIONS!$B$53),0),0) -> 0 | G15: =IFERROR(IF(AND(6>=ASSUMPTIONS!$C$50,ASSUMPTIONS!$C$50>0),ASSUMPTIONS!$D$50/12*(ASSUMPTIONS!$B$53),0),0) -> 7041.6667 | H15: =IFERROR(IF(AND(7>=ASSUMPTIONS!$C$50,ASSUMPTIONS!$C$50>0),ASSUMPTIONS!$D$50/12*(ASSUMPTIONS!$B$53),0),0) -> 7041.6667 | I15: =IFERROR(IF(AND(8>=ASSUMPTIONS!$C$50,ASSUMPTIONS!$C$50>0),ASSUMPTIONS!$D$50/12*(ASSUMPTIONS!$B$53),0),0) -> 7041.6667 | J15: =IFERROR(IF(AND(9>=ASSUMPTIONS!$C$50,ASSUMPTIONS!$C$50>0),ASSUMPTIONS!$D$50/12*(ASSUMPTIONS!$B$53),0),0) -> 7041.6667 | K15: =IFERROR(IF(AND(10>=ASSUMPTIONS!$C$50,ASSUMPTIONS!$C$50>0),ASSUMPTIONS!$D$50/12*(ASSUMPTIONS!$B$53),0),0) -> 7041.6667 | L15: =IFERROR(IF(AND(11>=ASSUMPTIONS!$C$50,ASSUMPTIONS!$C$50>0),ASSUMPTIONS!$D$50/12*(ASSUMPTIONS!$B$53),0),0) -> 7041.6667 | M15: =IFERROR(IF(AND(12>=ASSUMPTIONS!$C$50,ASSUMPTIONS!$C$50>0),ASSUMPTIONS!$D$50/12*(ASSUMPTIONS!$B$53),0),0) -> 7041.6667 | N15: =IFERROR(IF(AND(13>=ASSUMPTIONS!$C$50,ASSUMPTIONS!$C$50>0),ASSUMPTIONS!$D$50/12*(ASSUMPTIONS!$B$53),0),0) -> 7041.6667 | O15: =IFERROR(IF(AND(14>=ASSUMPTIONS!$C$50,ASSUMPTIONS!$C$50>0),ASSUMPTIONS!$D$50/12*(ASSUMPTIONS!$B$53),0),0) -> 7041.6667 | P15: =IFERROR(IF(AND(15>=ASSUMPTIONS!$C$50,ASSUMPTIONS!$C$50>0),ASSUMPTIONS!$D$50/12*(ASSUMPTIONS!$B$53),0),0) -> 7041.6667 | Q15: =IFERROR(IF(AND(16>=ASSUMPTIONS!$C$50,ASSUMPTIONS!$C$50>0),ASSUMPTIONS!$D$50/12*(ASSUMPTIONS!$B$53),0),0) -> 7041.6667 | R15: =IFERROR(IF(AND(17>=ASSUMPTIONS!$C$50,ASSUMPTIONS!$C$50>0),ASSUMPTIONS!$D$50/12*(ASSUMPTIONS!$B$53),0),0) -> 7041.6667 | S15: =IFERROR(IF(AND(18>=ASSUMPTIONS!$C$50,ASSUMPTIONS!$C$50>0),ASSUMPTIONS!$D$50/12*(ASSUMPTIONS!$B$53),0),0) -> 7041.6667 | T15: =IFERROR(IF(AND(19>=ASSUMPTIONS!$C$50,ASSUMPTIONS!$C$50>0),ASSUMPTIONS!$D$50/12*(ASSUMPTIONS!$B$53),0),0) -> 7041.6667 | U15: =IFERROR(IF(AND(20>=ASSUMPTIONS!$C$50,ASSUMPTIONS!$C$50>0),ASSUMPTIONS!$D$50/12*(ASSUMPTIONS!$B$53),0),0) -> 7041.6667 | V15: =IFERROR(IF(AND(21>=ASSUMPTIONS!$C$50,ASSUMPTIONS!$C$50>0),ASSUMPTIONS!$D$50/12*(ASSUMPTIONS!$B$53),0),0) -> 7041.6667 | W15: =IFERROR(IF(AND(22>=ASSUMPTIONS!$C$50,ASSUMPTIONS!$C$50>0),ASSUMPTIONS!$D$50/12*(ASSUMPTIONS!$B$53),0),0) -> 7041.6667 | X15: =IFERROR(IF(AND(23>=ASSUMPTIONS!$C$50,ASSUMPTIONS!$C$50>0),ASSUMPTIONS!$D$50/12*(ASSUMPTIONS!$B$53),0),0) -> 7041.6667 | Y15: =IFERROR(IF(AND(24>=ASSUMPTIONS!$C$50,ASSUMPTIONS!$C$50>0),ASSUMPTIONS!$D$50/12*(ASSUMPTIONS!$B$53),0),0) -> 7041.6667
A16: =IFERROR(ASSUMPTIONS!B51,"") -> 0 | B16: =IFERROR(IF(AND(1>=ASSUMPTIONS!$C$51,ASSUMPTIONS!$C$51>0),ASSUMPTIONS!$D$51/12*(ASSUMPTIONS!$B$53),0),0) -> 0 | C16: =IFERROR(IF(AND(2>=ASSUMPTIONS!$C$51,ASSUMPTIONS!$C$51>0),ASSUMPTIONS!$D$51/12*(ASSUMPTIONS!$B$53),0),0) -> 0 | D16: =IFERROR(IF(AND(3>=ASSUMPTIONS!$C$51,ASSUMPTIONS!$C$51>0),ASSUMPTIONS!$D$51/12*(ASSUMPTIONS!$B$53),0),0) -> 0 | E16: =IFERROR(IF(AND(4>=ASSUMPTIONS!$C$51,ASSUMPTIONS!$C$51>0),ASSUMPTIONS!$D$51/12*(ASSUMPTIONS!$B$53),0),0) -> 0 | F16: =IFERROR(IF(AND(5>=ASSUMPTIONS!$C$51,ASSUMPTIONS!$C$51>0),ASSUMPTIONS!$D$51/12*(ASSUMPTIONS!$B$53),0),0) -> 0 | G16: =IFERROR(IF(AND(6>=ASSUMPTIONS!$C$51,ASSUMPTIONS!$C$51>0),ASSUMPTIONS!$D$51/12*(ASSUMPTIONS!$B$53),0),0) -> 0 | H16: =IFERROR(IF(AND(7>=ASSUMPTIONS!$C$51,ASSUMPTIONS!$C$51>0),ASSUMPTIONS!$D$51/12*(ASSUMPTIONS!$B$53),0),0) -> 0 | I16: =IFERROR(IF(AND(8>=ASSUMPTIONS!$C$51,ASSUMPTIONS!$C$51>0),ASSUMPTIONS!$D$51/12*(ASSUMPTIONS!$B$53),0),0) -> 0 | J16: =IFERROR(IF(AND(9>=ASSUMPTIONS!$C$51,ASSUMPTIONS!$C$51>0),ASSUMPTIONS!$D$51/12*(ASSUMPTIONS!$B$53),0),0) -> 0 | K16: =IFERROR(IF(AND(10>=ASSUMPTIONS!$C$51,ASSUMPTIONS!$C$51>0),ASSUMPTIONS!$D$51/12*(ASSUMPTIONS!$B$53),0),0) -> 0 | L16: =IFERROR(IF(AND(11>=ASSUMPTIONS!$C$51,ASSUMPTIONS!$C$51>0),ASSUMPTIONS!$D$51/12*(ASSUMPTIONS!$B$53),0),0) -> 0 | M16: =IFERROR(IF(AND(12>=ASSUMPTIONS!$C$51,ASSUMPTIONS!$C$51>0),ASSUMPTIONS!$D$51/12*(ASSUMPTIONS!$B$53),0),0) -> 0 | N16: =IFERROR(IF(AND(13>=ASSUMPTIONS!$C$51,ASSUMPTIONS!$C$51>0),ASSUMPTIONS!$D$51/12*(ASSUMPTIONS!$B$53),0),0) -> 0 | O16: =IFERROR(IF(AND(14>=ASSUMPTIONS!$C$51,ASSUMPTIONS!$C$51>0),ASSUMPTIONS!$D$51/12*(ASSUMPTIONS!$B$53),0),0) -> 0 | P16: =IFERROR(IF(AND(15>=ASSUMPTIONS!$C$51,ASSUMPTIONS!$C$51>0),ASSUMPTIONS!$D$51/12*(ASSUMPTIONS!$B$53),0),0) -> 0 | Q16: =IFERROR(IF(AND(16>=ASSUMPTIONS!$C$51,ASSUMPTIONS!$C$51>0),ASSUMPTIONS!$D$51/12*(ASSUMPTIONS!$B$53),0),0) -> 0 | R16: =IFERROR(IF(AND(17>=ASSUMPTIONS!$C$51,ASSUMPTIONS!$C$51>0),ASSUMPTIONS!$D$51/12*(ASSUMPTIONS!$B$53),0),0) -> 0 | S16: =IFERROR(IF(AND(18>=ASSUMPTIONS!$C$51,ASSUMPTIONS!$C$51>0),ASSUMPTIONS!$D$51/12*(ASSUMPTIONS!$B$53),0),0) -> 0 | T16: =IFERROR(IF(AND(19>=ASSUMPTIONS!$C$51,ASSUMPTIONS!$C$51>0),ASSUMPTIONS!$D$51/12*(ASSUMPTIONS!$B$53),0),0) -> 0 | U16: =IFERROR(IF(AND(20>=ASSUMPTIONS!$C$51,ASSUMPTIONS!$C$51>0),ASSUMPTIONS!$D$51/12*(ASSUMPTIONS!$B$53),0),0) -> 0 | V16: =IFERROR(IF(AND(21>=ASSUMPTIONS!$C$51,ASSUMPTIONS!$C$51>0),ASSUMPTIONS!$D$51/12*(ASSUMPTIONS!$B$53),0),0) -> 0 | W16: =IFERROR(IF(AND(22>=ASSUMPTIONS!$C$51,ASSUMPTIONS!$C$51>0),ASSUMPTIONS!$D$51/12*(ASSUMPTIONS!$B$53),0),0) -> 0 | X16: =IFERROR(IF(AND(23>=ASSUMPTIONS!$C$51,ASSUMPTIONS!$C$51>0),ASSUMPTIONS!$D$51/12*(ASSUMPTIONS!$B$53),0),0) -> 0 | Y16: =IFERROR(IF(AND(24>=ASSUMPTIONS!$C$51,ASSUMPTIONS!$C$51>0),ASSUMPTIONS!$D$51/12*(ASSUMPTIONS!$B$53),0),0) -> 0
A18: TOTAL HEADCOUNT ($) | B18: =SUM(B7:B16) -> 28166.667 | C18: =SUM(C7:C16) -> 28166.667 | D18: =SUM(D7:D16) -> 47666.667 | E18: =SUM(E7:E16) -> 56875 | F18: =SUM(F7:F16) -> 56875 | G18: =SUM(G7:G16) -> 82875 | H18: =SUM(H7:H16) -> 82875 | I18: =SUM(I7:I16) -> 82875 | ... Y18: =SUM(Y7:Y16) -> 82875

Sheet P&L
A1: PROFIT & LOSS STATEMENT
A2: Auto-populated from REVENUE and HEADCOUNT. Green = cross-sheet links.
B4: YEAR 1 | N4: YEAR 2
B5: Jan | C5: Feb | D5: Mar | E5: Apr | F5: May | G5: Jun | H5: Jul | I5: Aug | J5: Sep | K5: Oct | L5: Nov | M5: Dec | N5: Jan | O5: Feb | P5: Mar | Q5: Apr | R5: May | S5: Jun | T5: Jul | U5: Aug | V5: Sep | W5: Oct | X5: Nov | Y5: Dec | Z5: Y1 Total | AA5: Y2 Total
A6: REVENUE
A8: Total Revenue ($) | B8: =IFERROR(REVENUE!B12,0) -> 3366 | C8: =IFERROR(REVENUE!C12,0) -> 5346 | D8: =IFERROR(REVENUE!D12,0) -> 7524 | E8: =IFERROR(REVENUE!E12,0) -> 9801 | F8: =IFERROR(REVENUE!F12,0) -> 12276 | G8: =IFERROR(REVENUE!G12,0) -> 14850 | H8: =IFERROR(REVENUE!H12,0) -> 17622 | I8: =IFERROR(REVENUE!I12,0) -> 20691 | ... Y8: =IFERROR(REVENUE!Y12,0) -> 129987
A10: COGS
A11: Hosting + Support + Processing ($) | B11: =IFERROR(REVENUE!B9*(ASSUMPTIONS!$B$36+ASSUMPTIONS!$B$38)+B8*ASSUMPTIONS!$B$37,0) -> 369.614 | C11: =IFERROR(REVENUE!C9*(ASSUMPTIONS!$B$36+ASSUMPTIONS!$B$38)+C8*ASSUMPTIONS!$B$37,0) -> 587.034 | D11: =IFERROR(REVENUE!D9*(ASSUMPTIONS!$B$36+ASSUMPTIONS!$B$38)+D8*ASSUMPTIONS!$B$37,0) -> 826.196 | E11: =IFERROR(REVENUE!E9*(ASSUMPTIONS!$B$36+ASSUMPTIONS!$B$38)+E8*ASSUMPTIONS!$B$37,0) -> 1076.229 | F11: =IFERROR(REVENUE!F9*(ASSUMPTIONS!$B$36+ASSUMPTIONS!$B$38)+F8*ASSUMPTIONS!$B$37,0) -> 1348.004 | G11: =IFERROR(REVENUE!G9*(ASSUMPTIONS!$B$36+ASSUMPTIONS!$B$38)+G8*ASSUMPTIONS!$B$37,0) -> 1630.65 | H11: =IFERROR(REVENUE!H9*(ASSUMPTIONS!$B$36+ASSUMPTIONS!$B$38)+H8*ASSUMPTIONS!$B$37,0) -> 1935.038 | I11: =IFERROR(REVENUE!I9*(ASSUMPTIONS!$B$36+ASSUMPTIONS!$B$38)+I8*ASSUMPTIONS!$B$37,0) -> 2272.039 | ... Y11: =IFERROR(REVENUE!Y9*(ASSUMPTIONS!$B$36+ASSUMPTIONS!$B$38)+Y8*ASSUMPTIONS!$B$37,0) -> 14273.623
A12: GROSS PROFIT ($) | B12: =B8-B11 -> 2996.386 | C12: =C8-C11 -> 4758.966 | D12: =D8-D11 -> 6697.804 | E12: =E8-E11 -> 8724.771 | F12: =F8-F11 -> 10927.996 | G12: =G8-G11 -> 13219.35 | H12: =H8-H11 -> 15686.962 | I12: =I8-I11 -> 18418.961 | ... Y12: =Y8-Y11 -> 115713.38
A13: Gross Margin % | B13: =IFERROR(B12/B8,0) -> 0.89019192 | C13: =IFERROR(C12/C8,0) -> 0.89019192 | D13: =IFERROR(D12/D8,0) -> 0.89019192 | E13: =IFERROR(E12/E8,0) -> 0.89019192 | F13: =IFERROR(F12/F8,0) -> 0.89019192 | G13: =IFERROR(G12/G8,0) -> 0.89019192 | H13: =IFERROR(H12/H8,0) -> 0.89019192 | I13: =IFERROR(I12/I8,0) -> 0.89019192 | ... Y13: =IFERROR(Y12/Y8,0) -> 0.89019192
A15: OPEX
A16: Headcount ($) | B16: =IFERROR(HEADCOUNT!B18,0) -> 28166.667 | C16: =IFERROR(HEADCOUNT!C18,0) -> 28166.667 | D16: =IFERROR(HEADCOUNT!D18,0) -> 47666.667 | E16: =IFERROR(HEADCOUNT!E18,0) -> 56875 | F16: =IFERROR(HEADCOUNT!F18,0) -> 56875 | G16: =IFERROR(HEADCOUNT!G18,0) -> 82875 | H16: =IFERROR(HEADCOUNT!H18,0) -> 82875 | I16: =IFERROR(HEADCOUNT!I18,0) -> 82875 | ... Y16: =IFERROR(HEADCOUNT!Y18,0) -> 82875
A17: Marketing ($) | B17: =IFERROR(ASSUMPTIONS!$B$56,0) -> 5000 | C17: =IFERROR(ROUND(B17*(1+ASSUMPTIONS!$B$57),0),0) -> 5400 | D17: =IFERROR(ROUND(C17*(1+ASSUMPTIONS!$B$57),0),0) -> 5832 | E17: =IFERROR(ROUND(D17*(1+ASSUMPTIONS!$B$57),0),0) -> 6299 | F17: =IFERROR(ROUND(E17*(1+ASSUMPTIONS!$B$57),0),0) -> 6803 | G17: =IFERROR(ROUND(F17*(1+ASSUMPTIONS!$B$57),0),0) -> 7347 | H17: =IFERROR(ROUND(G17*(1+ASSUMPTIONS!$B$57),0),0) -> 7935 | I17: =IFERROR(ROUND(H17*(1+ASSUMPTIONS!$B$57),0),0) -> 8570 | J17: =IFERROR(ROUND(I17*(1+ASSUMPTIONS!$B$57),0),0) -> 9256 | ... Y17: =IFERROR(ROUND(X17*(1+ASSUMPTIONS!$B$57),0),0) -> 29363
A18: Other OpEx ($) | B18: =IFERROR(ASSUMPTIONS!$B$58+ASSUMPTIONS!$B$59+ASSUMPTIONS!$B$60+ASSUMPTIONS!$B$61,0) -> 2500 | C18: =IFERROR(ASSUMPTIONS!$B$58+ASSUMPTIONS!$B$59+ASSUMPTIONS!$B$60+ASSUMPTIONS!$B$61,0) -> 2500 | D18: =IFERROR(ASSUMPTIONS!$B$58+ASSUMPTIONS!$B$59+ASSUMPTIONS!$B$60+ASSUMPTIONS!$B$61,0) -> 2500 | E18: =IFERROR(ASSUMPTIONS!$B$58+ASSUMPTIONS!$B$59+ASSUMPTIONS!$B$60+ASSUMPTIONS!$B$61,0) -> 2500 | F18: =IFERROR(ASSUMPTIONS!$B$58+ASSUMPTIONS!$B$59+ASSUMPTIONS!$B$60+ASSUMPTIONS!$B$61,0) -> 2500 | G18: =IFERROR(ASSUMPTIONS!$B$58+ASSUMPTIONS!$B$59+ASSUMPTIONS!$B$60+ASSUMPTIONS!$B$61,0) -> 2500 | H18: =IFERROR(ASSUMPTIONS!$B$58+ASSUMPTIONS!$B$59+ASSUMPTIONS!$B$60+ASSUMPTIONS!$B$61,0) -> 2500 | I18: =IFERROR(ASSUMPTIONS!$B$58+ASSUMPTIONS!$B$59+ASSUMPTIONS!$B$60+ASSUMPTIONS!$B$61,0) -> 2500 | ... Y18: =IFERROR(ASSUMPTIONS!$B$58+ASSUMPTIONS!$B$59+ASSUMPTIONS!$B$60+ASSUMPTIONS!$B$61,0) -> 2500
A19: TOTAL OPEX ($) | B19: =B16+B17+B18 -> 35666.667 | C19: =C16+C17+C18 -> 36066.667 | D19: =D16+D17+D18 -> 55998.667 | E19: =E16+E17+E18 -> 65674 | F19: =F16+F17+F18 -> 66178 | G19: =G16+G17+G18 -> 92722 | H19: =H16+H17+H18 -> 93310 | I19: =I16+I17+I18 -> 93945 | ... Y19: =Y16+Y17+Y18 -> 114738
A21: EBITDA ($) | B21: =B12-B19 -> -32670.281 | C21: =C12-C19 -> -31307.701 | D21: =D12-D19 -> -49300.863 | E21: =E12-E19 -> -56949.229 | F21: =F12-F19 -> -55250.004 | G21: =G12-G19 -> -79502.65 | H21: =H12-H19 -> -77623.038 | I21: =I12-I19 -> -75526.039 | ... Y21: =Y12-Y19 -> 975.377
A22: EBITDA Margin % | B22: =IFERROR(B21/B8,0) -> -9.7059657 | C22: =IFERROR(C21/C8,0) -> -5.8562852 | D22: =IFERROR(D21/D8,0) -> -6.5524804 | E22: =IFERROR(E21/E8,0) -> -5.8105529 | F22: =IFERROR(F21/F8,0) -> -4.500652 | G22: =IFERROR(G21/G8,0) -> -5.3537138 | H22: =IFERROR(H21/H8,0) -> -4.4048938 | I22: =IFERROR(I21/I8,0) -> -3.650188 | ... Y22: =IFERROR(Y21/Y8,0) -> 0.0075036504

Sheet CASH FLOW
A1: CASH FLOW STATEMENT
A2: Auto-calculated. Shows runway.
B4: YEAR 1 | N4: YEAR 2
B5: Jan | C5: Feb | D5: Mar | E5: Apr | F5: May | G5: Jun | H5: Jul | I5: Aug | J5: Sep | K5: Oct | L5: Nov | M5: Dec | N5: Jan | O5: Feb | P5: Mar | Q5: Apr | R5: May | S5: Jun | T5: Jul | U5: Aug | V5: Sep | W5: Oct | X5: Nov | Y5: Dec | Z5: Y1 Total | AA5: Y2 Total
A6: OPENING CASH
A7: Opening Cash ($) | B7: =ASSUMPTIONS!$B$64 -> 100000 | C7: =IFERROR(B17,0) -> 67329.719 | D7: =IFERROR(C17,0) -> 36022.019 | E7: =IFERROR(D17,0) -> -13278.844 | F7: =IFERROR(E17,0) -> 1429771.9 | G7: =IFERROR(F17,0) -> 1374521.9 | H7: =IFERROR(G17,0) -> 1295019.3 | I7: =IFERROR(H17,0) -> 1217396.2 | J7: =IFERROR(I17,0) -> 1141870.2 | ... Y7: =IFERROR(X17,0) -> 439832.99
A9: OPERATIONS
A10: EBITDA | B10: =IFERROR('P&L'!B21,0) -> -32670.281 | C10: =IFERROR('P&L'!C21,0) -> -31307.701 | D10: =IFERROR('P&L'!D21,0) -> -49300.863 | E10: =IFERROR('P&L'!E21,0) -> -56949.229 | F10: =IFERROR('P&L'!F21,0) -> -55250.004 | G10: =IFERROR('P&L'!G21,0) -> -79502.65 | H10: =IFERROR('P&L'!H21,0) -> -77623.038 | I10: =IFERROR('P&L'!I21,0) -> -75526.039 | ... Y10: =IFERROR('P&L'!Y21,0) -> 975.377
A11: CASH FROM OPS ($) | B11: =B10 -> -32670.281 | C11: =C10 -> -31307.701 | D11: =D10 -> -49300.863 | E11: =E10 -> -56949.229 | F11: =F10 -> -55250.004 | G11: =G10 -> -79502.65 | H11: =H10 -> -77623.038 | I11: =I10 -> -75526.039 | ... Y11: =Y10 -> 975.377
A13: FINANCING
A14: Seed Raise ($) | B14: =IF(1=ASSUMPTIONS!$B$66,ASSUMPTIONS!$B$65,0) -> 0 | C14: =IF(2=ASSUMPTIONS!$B$66,ASSUMPTIONS!$B$65,0) -> 0 | D14: =IF(3=ASSUMPTIONS!$B$66,ASSUMPTIONS!$B$65,0) -> 0 | E14: =IF(4=ASSUMPTIONS!$B$66,ASSUMPTIONS!$B$65,0) -> 1500000 | F14: =IF(5=ASSUMPTIONS!$B$66,ASSUMPTIONS!$B$65,0) -> 0 | G14: =IF(6=ASSUMPTIONS!$B$66,ASSUMPTIONS!$B$65,0) -> 0 | H14: =IF(7=ASSUMPTIONS!$B$66,ASSUMPTIONS!$B$65,0) -> 0 | I14: =IF(8=ASSUMPTIONS!$B$66,ASSUMPTIONS!$B$65,0) -> 0 | J14: =IF(9=ASSUMPTIONS!$B$66,ASSUMPTIONS!$B$65,0) -> 0 | K14: =IF(10=ASSUMPTIONS!$B$66,ASSUMPTIONS!$B$65,0) -> 0 | L14: =IF(11=ASSUMPTIONS!$B$66,ASSUMPTIONS!$B$65,0) -> 0 | M14: =IF(12=ASSUMPTIONS!$B$66,ASSUMPTIONS!$B$65,0) -> 0 | N14: =IF(13=ASSUMPTIONS!$B$66,ASSUMPTIONS!$B$65,0) -> 0 | O14: =IF(14=ASSUMPTIONS!$B$66,ASSUMPTIONS!$B$65,0) -> 0 | P14: =IF(15=ASSUMPTIONS!$B$66,ASSUMPTIONS!$B$65,0) -> 0 | Q14: =IF(16=ASSUMPTIONS!$B$66,ASSUMPTIONS!$B$65,0) -> 0 | R14: =IF(17=ASSUMPTIONS!$B$66,ASSUMPTIONS!$B$65,0) -> 0 | S14: =IF(18=ASSUMPTIONS!$B$66,ASSUMPTIONS!$B$65,0) -> 0 | T14: =IF(19=ASSUMPTIONS!$B$66,ASSUMPTIONS!$B$65,0) -> 0 | U14: =IF(20=ASSUMPTIONS!$B$66,ASSUMPTIONS!$B$65,0) -> 0 | V14: =IF(21=ASSUMPTIONS!$B$66,ASSUMPTIONS!$B$65,0) -> 0 | W14: =IF(22=ASSUMPTIONS!$B$66,ASSUMPTIONS!$B$65,0) -> 0 | X14: =IF(23=ASSUMPTIONS!$B$66,ASSUMPTIONS!$B$65,0) -> 0 | Y14: =IF(24=ASSUMPTIONS!$B$66,ASSUMPTIONS!$B$65,0) -> 0
A16: NET CASH MOVEMENT ($) | B16: =B11+B14 -> -32670.281 | C16: =C11+C14 -> -31307.701 | D16: =D11+D14 -> -49300.863 | E16: =E11+E14 -> 1443050.8 | F16: =F11+F14 -> -55250.004 | G16: =G11+G14 -> -79502.65 | H16: =H11+H14 -> -77623.038 | I16: =I11+I14 -> -75526.039 | ... Y16: =Y11+Y14 -> 975.377
A17: CLOSING CASH ($) | B17: =B7+B16 -> 67329.719 | C17: =C7+C16 -> 36022.019 | D17: =D7+D16 -> -13278.844 | E17: =E7+E16 -> 1429771.9 | F17: =F7+F16 -> 1374521.9 | G17: =G7+G16 -> 1295019.3 | H17: =H7+H16 -> 1217396.2 | I17: =I7+I16 -> 1141870.2 | ... Y17: =Y7+Y16 -> 440808.37
A19: Monthly Burn ($) | B19: =B11 -> -32670.281 | C19: =C11 -> -31307.701 | D19: =D11 -> -49300.863 | E19: =E11 -> -56949.229 | F19: =F11 -> -55250.004 | G19: =G11 -> -79502.65 | H19: =H11 -> -77623.038 | I19: =I11 -> -75526.039 | ... Y19: =Y11 -> 975.377
A20: Runway (Months) | B20: =IFERROR(IF(B19<0,B17/ABS(B19),"∞"),0) -> 2.0608859 | C20: =IFERROR(IF(C19<0,C17/ABS(C19),"∞"),0) -> 1.1505801 | D20: =IFERROR(IF(D19<0,D17/ABS(D19),"∞"),0) -> -0.26934304 | E20: =IFERROR(IF(E19<0,E17/ABS(E19),"∞"),0) -> 25.10608 | F20: =IFERROR(IF(F19<0,F17/ABS(F19),"∞"),0) -> 24.878223 | G20: =IFERROR(IF(G19<0,G17/ABS(G19),"∞"),0) -> 16.289008 | H20: =IFERROR(IF(H19<0,H17/ABS(H19),"∞"),0) -> 15.68344 | I20: =IFERROR(IF(I19<0,I17/ABS(I19),"∞"),0) -> 15.118894 | ... Y20: =IFERROR(IF(Y19<0,Y17/ABS(Y19),"∞"),0) -> ∞
