Workbook

Sheet COVER
B2: Raise Ready
B3: Series A Financial Model — Popular
B5: Includes: Marketplace + SaaS revenue, departmental headcount, unit economics, sensitivity analysis, balance sheet, KPI dashboard. 36-month horizon.
B7: ASSUMPTIONS | C7: All model inputs, 3 scenarios, CAC channels
B8: REVENUE | C8: Marketplace + SaaS dual-revenue model
B9: HEADCOUNT | C9: Departmental: Engineering, Product, Sales, Marketing, CS, G&A
B10: P&L | C10: Full profit & loss
B11: CASH FLOW | C11: Cash flow + runway
B12: BALANCE SHEET | C12: Assets, liabilities, equity, balance check
B13: UNIT ECONOMICS | C13: CAC, LTV, LTV:CAC, payback by segment
B14: SENSITIVITY | C14: What-if analysis on key drivers
B15: KPI DASHBOARD | C15: Year-end summary metrics

Sheet ASSUMPTIONS
A1: ASSUMPTIONS — Series A Model
A2: Yellow = inputs (blue text). Scenarios: Conservative / Base / Aggressive.
A4: SECTION 1 — COMPANY
A5: Company Name | B5: SeriesA Co
A6: Currency | B6: $
A7: Model Start | B7: Jan 2025
A9: SCENARIO SELECTOR
A10: Active Scenario (1/2/3) | B10: 2
A12: SECTION 2 — MARKETPLACE REVENUE
B13: Conservative | C13: Base | D13: Aggressive
A14: Starting Buyers | B14: 20 | C14: 40 | D14: 60
A15: New Buyers/Mo | B15: 8 | C15: 15 | D15: 25
A16: Buyer Growth MoM | B16: 0.04 | C16: 0.08 | D16: 0.12
A17: Buyer Churn | B17: 0.06 | C17: 0.045 | D17: 0.03
A18: Starting Sellers | B18: 10 | C18: 20 | D18: 30
A19: New Sellers/Mo | B19: 3 | C19: 6 | D19: 10
A20: Seller Growth MoM | B20: 0.03 | C20: 0.06 | D20: 0.1
A21: Seller Churn | B21: 0.04 | C21: 0.03 | D21: 0.02
A22: Avg Transactions/Buyer/Mo | B22: 2 | C22: 3 | D22: 4
A23: Avg Transaction Value ($) | B23: 150 | C23: 200 | D23: 250
A24: Take Rate % | B24: 0.12 | C24: 0.15 | D24: 0.18
A25: Seller Subscription ($/Mo) | B25: 0 | C25: 49 | D25: 99
A26: Active Marketplace Values
A27: → Starting Buyers | B27: =CHOOSE($B$10,B14,C14,D14) -> 40
A28: → New Buyers/Mo | B28: =CHOOSE($B$10,B15,C15,D15) -> 15
A29: → Buyer Growth MoM | B29: =CHOOSE($B$10,B16,C16,D16) -> 0.08
A30: → Buyer Churn | B30: =CHOOSE($B$10,B17,C17,D17) -> 0.045
A31: → Starting Sellers | B31: =CHOOSE($B$10,B18,C18,D18) -> 20
A32: → New Sellers/Mo | B32: =CHOOSE($B$10,B19,C19,D19) -> 6
A33: → Seller Growth MoM | B33: =CHOOSE($B$10,B20,C20,D20) -> 0.06
A34: → Seller Churn | B34: =CHOOSE($B$10,B21,C21,D21) -> 0.03
A35: → Avg Transactions/Buyer/Mo | B35: =CHOOSE($B$10,B22,C22,D22) -> 3
A36: → Avg Transaction Value ($) | B36: =CHOOSE($B$10,B23,C23,D23) -> 200
A37: → Take Rate % | B37: =CHOOSE($B$10,B24,C24,D24) -> 0.15
A38: → Seller Subscription ($/Mo) | B38: =CHOOSE($B$10,B25,C25,D25) -> 49
A40: SECTION 3 — SAAS SUBSCRIPTION REVENUE
B41: Conservative | C41: Base | D41: Aggressive
A42: Starting SaaS Subscribers | B42: 5 | C42: 15 | D42: 30
A43: New SaaS Subs/Mo | B43: 3 | C43: 8 | D43: 15
A44: SaaS Sub Growth MoM | B44: 0.04 | C44: 0.08 | D44: 0.12
...

Sheet REVENUE
A1: REVENUE — Marketplace + SaaS
A2: Dual revenue model. All from ASSUMPTIONS.
B4: YEAR 1 | N4: YEAR 2 | Z4: YEAR 3
B5: Jan | C5: Feb | D5: Mar | E5: Apr | F5: May | G5: Jun | H5: Jul | I5: Aug | J5: Sep | K5: Oct | L5: Nov | M5: Dec | N5: Jan | O5: Feb | P5: Mar | Q5: Apr | R5: May | S5: Jun | T5: Jul | U5: Aug | V5: Sep | W5: Oct | X5: Nov | Y5: Dec | Z5: Jan | AA5: Feb | AB5: Mar | AC5: Apr | AD5: May | AE5: Jun | AF5: Jul | AG5: Aug | AH5: Sep | AI5: Oct | AJ5: Nov | AK5: Dec | AL5: Y1 Total | AM5: Y2 Total | AN5: Y3 Total
A6: MARKETPLACE — BUYERS & SELLERS
A7: New Buyers | B7: =IFERROR(ASSUMPTIONS!$B$28,0) -> 15 | C7: =IFERROR(ROUND(B7*(1+ASSUMPTIONS!$B$29),0),0) -> 16 | D7: =IFERROR(ROUND(C7*(1+ASSUMPTIONS!$B$29),0),0) -> 17 | E7: =IFERROR(ROUND(D7*(1+ASSUMPTIONS!$B$29),0),0) -> 18 | F7: =IFERROR(ROUND(E7*(1+ASSUMPTIONS!$B$29),0),0) -> 19 | G7: =IFERROR(ROUND(F7*(1+ASSUMPTIONS!$B$29),0),0) -> 21 | H7: =IFERROR(ROUND(G7*(1+ASSUMPTIONS!$B$29),0),0) -> 23 | I7: =IFERROR(ROUND(H7*(1+ASSUMPTIONS!$B$29),0),0) -> 25 | J7: =IFERROR(ROUND(I7*(1+ASSUMPTIONS!$B$29),0),0) -> 27 | ... AK7: =IFERROR(ROUND(AJ7*(1+ASSUMPTIONS!$B$29),0),0) -> 211
A8: Buyers Churned | B8: =IFERROR(ROUND(ASSUMPTIONS!$B$27*ASSUMPTIONS!$B$30,0),0) -> 2 | C8: =IFERROR(ROUND(B9*ASSUMPTIONS!$B$30,0),0) -> 2 | D8: =IFERROR(ROUND(C9*ASSUMPTIONS!$B$30,0),0) -> 3 | E8: =IFERROR(ROUND(D9*ASSUMPTIONS!$B$30,0),0) -> 4 | F8: =IFERROR(ROUND(E9*ASSUMPTIONS!$B$30,0),0) -> 4 | G8: =IFERROR(ROUND(F9*ASSUMPTIONS!$B$30,0),0) -> 5 | H8: =IFERROR(ROUND(G9*ASSUMPTIONS!$B$30,0),0) -> 6 | I8: =IFERROR(ROUND(H9*ASSUMPTIONS!$B$30,0),0) -> 6 | J8: =IFERROR(ROUND(I9*ASSUMPTIONS!$B$30,0),0) -> 7 | ... AK8: =IFERROR(ROUND(AJ9*ASSUMPTIONS!$B$30,0),0) -> 75
A9: Active Buyers EOM | B9: =IFERROR(ASSUMPTIONS!$B$27+B7-B8,0) -> 53 | C9: =IFERROR(B9+C7-C8,0) -> 67 | D9: =IFERROR(C9+D7-D8,0) -> 81 | E9: =IFERROR(D9+E7-E8,0) -> 95 | F9: =IFERROR(E9+F7-F8,0) -> 110 | G9: =IFERROR(F9+G7-G8,0) -> 126 | H9: =IFERROR(G9+H7-H8,0) -> 143 | I9: =IFERROR(H9+I7-I8,0) -> 162 | J9: =IFERROR(I9+J7-J8,0) -> 182 | ... AK9: =IFERROR(AJ9+AK7-AK8,0) -> 1812
A11: New Sellers | B11: =IFERROR(ASSUMPTIONS!$B$32,0) -> 6 | C11: =IFERROR(ROUND(B11*(1+ASSUMPTIONS!$B$33),0),0) -> 6 | D11: =IFERROR(ROUND(C11*(1+ASSUMPTIONS!$B$33),0),0) -> 6 | E11: =IFERROR(ROUND(D11*(1+ASSUMPTIONS!$B$33),0),0) -> 6 | F11: =IFERROR(ROUND(E11*(1+ASSUMPTIONS!$B$33),0),0) -> 6 | G11: =IFERROR(ROUND(F11*(1+ASSUMPTIONS!$B$33),0),0) -> 6 | H11: =IFERROR(ROUND(G11*(1+ASSUMPTIONS!$B$33),0),0) -> 6 | I11: =IFERROR(ROUND(H11*(1+ASSUMPTIONS!$B$33),0),0) -> 6 | J11: =IFERROR(ROUND(I11*(1+ASSUMPTIONS!$B$33),0),0) -> 6 | ... AK11: =IFERROR(ROUND(AJ11*(1+ASSUMPTIONS!$B$33),0),0) -> 6
A12: Sellers Churned | B12: =IFERROR(ROUND(ASSUMPTIONS!$B$31*ASSUMPTIONS!$B$34,0),0) -> 1 | C12: =IFERROR(ROUND(B13*ASSUMPTIONS!$B$34,0),0) -> 1 | D12: =IFERROR(ROUND(C13*ASSUMPTIONS!$B$34,0),0) -> 1 | E12: =IFERROR(ROUND(D13*ASSUMPTIONS!$B$34,0),0) -> 1 | F12: =IFERROR(ROUND(E13*ASSUMPTIONS!$B$34,0),0) -> 1 | G12: =IFERROR(ROUND(F13*ASSUMPTIONS!$B$34,0),0) -> 1 | H12: =IFERROR(ROUND(G13*ASSUMPTIONS!$B$34,0),0) -> 2 | I12: =IFERROR(ROUND(H13*ASSUMPTIONS!$B$34,0),0) -> 2 | J12: =IFERROR(ROUND(I13*ASSUMPTIONS!$B$34,0),0) -> 2 | ... AK12: =IFERROR(ROUND(AJ13*ASSUMPTIONS!$B$34,0),0) -> 4
A13: Active Sellers EOM | B13: =IFERROR(ASSUMPTIONS!$B$31+B11-B12,0) -> 25 | C13: =IFERROR(B13+C11-C12,0) -> 30 | D13: =IFERROR(C13+D11-D12,0) -> 35 | E13: =IFERROR(D13+E11-E12,0) -> 40 | F13: =IFERROR(E13+F11-F12,0) -> 45 | G13: =IFERROR(F13+G11-G12,0) -> 50 | H13: =IFERROR(G13+H11-H12,0) -> 54 | I13: =IFERROR(H13+I11-I12,0) -> 58 | J13: =IFERROR(I13+J11-J12,0) -> 62 | ... AK13: =IFERROR(AJ13+AK11-AK12,0) -> 139
A15: MARKETPLACE REVENUE
A16: GMV ($) | B16: =IFERROR(B9*ASSUMPTIONS!$B$35*ASSUMPTIONS!$B$36,0) -> 31800 | C16: =IFERROR(C9*ASSUMPTIONS!$B$35*ASSUMPTIONS!$B$36,0) -> 40200 | D16: =IFERROR(D9*ASSUMPTIONS!$B$35*ASSUMPTIONS!$B$36,0) -> 48600 | E16: =IFERROR(E9*ASSUMPTIONS!$B$35*ASSUMPTIONS!$B$36,0) -> 57000 | F16: =IFERROR(F9*ASSUMPTIONS!$B$35*ASSUMPTIONS!$B$36,0) -> 66000 | G16: =IFERROR(G9*ASSUMPTIONS!$B$35*ASSUMPTIONS!$B$36,0) -> 75600 | H16: =IFERROR(H9*ASSUMPTIONS!$B$35*ASSUMPTIONS!$B$36,0) -> 85800 | I16: =IFERROR(I9*ASSUMPTIONS!$B$35*ASSUMPTIONS!$B$36,0) -> 97200 | ... AK16: =IFERROR(AK9*ASSUMPTIONS!$B$35*ASSUMPTIONS!$B$36,0) -> 1087200
A17: Transaction Revenue (GMV × Take Rate) | B17: =IFERROR(B16*ASSUMPTIONS!$B$37,0) -> 4770 | C17: =IFERROR(C16*ASSUMPTIONS!$B$37,0) -> 6030 | D17: =IFERROR(D16*ASSUMPTIONS!$B$37,0) -> 7290 | E17: =IFERROR(E16*ASSUMPTIONS!$B$37,0) -> 8550 | F17: =IFERROR(F16*ASSUMPTIONS!$B$37,0) -> 9900 | G17: =IFERROR(G16*ASSUMPTIONS!$B$37,0) -> 11340 | H17: =IFERROR(H16*ASSUMPTIONS!$B$37,0) -> 12870 | I17: =IFERROR(I16*ASSUMPTIONS!$B$37,0) -> 14580 | ... AK17: =IFERROR(AK16*ASSUMPTIONS!$B$37,0) -> 163080
A18: Seller Subscription Revenue ($) | B18: =IFERROR(B13*ASSUMPTIONS!$B$38,0) -> 1225 | C18: =IFERROR(C13*ASSUMPTIONS!$B$38,0) -> 1470 | D18: =IFERROR(D13*ASSUMPTIONS!$B$38,0) -> 1715 | E18: =IFERROR(E13*ASSUMPTIONS!$B$38,0) -> 1960 | F18: =IFERROR(F13*ASSUMPTIONS!$B$38,0) -> 2205 | G18: =IFERROR(G13*ASSUMPTIONS!$B$38,0) -> 2450 | H18: =IFERROR(H13*ASSUMPTIONS!$B$38,0) -> 2646 | I18: =IFERROR(I13*ASSUMPTIONS!$B$38,0) -> 2842 | ... AK18: =IFERROR(AK13*ASSUMPTIONS!$B$38,0) -> 6811
A19: TOTAL MARKETPLACE REVENUE ($) | B19: =B17+B18 -> 5995 | C19: =C17+C18 -> 7500 | D19: =D17+D18 -> 9005 | E19: =E17+E18 -> 10510 | F19: =F17+F18 -> 12105 | G19: =G17+G18 -> 13790 | H19: =H17+H18 -> 15516 | I19: =I17+I18 -> 17422 | ... AK19: =AK17+AK18 -> 169891 | AL19: =SUM(B19:M19) -> 182391 | AM19: =SUM(N19:Y19) -> 555105 | AN19: =SUM(Z19:AK19) -> 1394165
A21: SAAS SUBSCRIPTION REVENUE
A22: New SaaS Subs | B22: =IFERROR(ASSUMPTIONS!$B$49,0) -> 8 | C22: =IFERROR(ROUND(B22*(1+ASSUMPTIONS!$B$50),0),0) -> 9 | D22: =IFERROR(ROUND(C22*(1+ASSUMPTIONS!$B$50),0),0) -> 10 | E22: =IFERROR(ROUND(D22*(1+ASSUMPTIONS!$B$50),0),0) -> 11 | F22: =IFERROR(ROUND(E22*(1+ASSUMPTIONS!$B$50),0),0) -> 12 | G22: =IFERROR(ROUND(F22*(1+ASSUMPTIONS!$B$50),0),0) -> 13 | H22: =IFERROR(ROUND(G22*(1+ASSUMPTIONS!$B$50),0),0) -> 14 | I22: =IFERROR(ROUND(H22*(1+ASSUMPTIONS!$B$50),0),0) -> 15 | J22: =IFERROR(ROUND(I22*(1+ASSUMPTIONS!$B$50),0),0) -> 16 | ... AK22: =IFERROR(ROUND(AJ22*(1+ASSUMPTIONS!$B$50),0),0) -> 123
A23: SaaS Churned | B23: =IFERROR(ROUND(ASSUMPTIONS!$B$48*ASSUMPTIONS!$B$51,0),0) -> 1 | C23: =IFERROR(ROUND(B24*ASSUMPTIONS!$B$51,0),0) -> 1 | D23: =IFERROR(ROUND(C24*ASSUMPTIONS!$B$51,0),0) -> 1 | E23: =IFERROR(ROUND(D24*ASSUMPTIONS!$B$51,0),0) -> 1 | F23: =IFERROR(ROUND(E24*ASSUMPTIONS!$B$51,0),0) -> 2 | G23: =IFERROR(ROUND(F24*ASSUMPTIONS!$B$51,0),0) -> 2 | H23: =IFERROR(ROUND(G24*ASSUMPTIONS!$B$51,0),0) -> 2 | I23: =IFERROR(ROUND(H24*ASSUMPTIONS!$B$51,0),0) -> 3 | J23: =IFERROR(ROUND(I24*ASSUMPTIONS!$B$51,0),0) -> 3 | ... AK23: =IFERROR(ROUND(AJ24*ASSUMPTIONS!$B$51,0),0) -> 37
A24: Active SaaS Subs EOM | B24: =IFERROR(ASSUMPTIONS!$B$48+B22-B23,0) -> 22 | C24: =IFERROR(B24+C22-C23,0) -> 30 | D24: =IFERROR(C24+D22-D23,0) -> 39 | E24: =IFERROR(D24+E22-E23,0) -> 49 | F24: =IFERROR(E24+F22-F23,0) -> 59 | G24: =IFERROR(F24+G22-G23,0) -> 70 | H24: =IFERROR(G24+H22-H23,0) -> 82 | I24: =IFERROR(H24+I22-I23,0) -> 94 | J24: =IFERROR(I24+J22-J23,0) -> 107 | ... AK24: =IFERROR(AJ24+AK22-AK23,0) -> 1146
A25: TOTAL SAAS REVENUE ($) | B25: =IFERROR(B24*ASSUMPTIONS!$B$52,0) -> 2838 | C25: =IFERROR(C24*ASSUMPTIONS!$B$52,0) -> 3870 | D25: =IFERROR(D24*ASSUMPTIONS!$B$52,0) -> 5031 | E25: =IFERROR(E24*ASSUMPTIONS!$B$52,0) -> 6321 | F25: =IFERROR(F24*ASSUMPTIONS!$B$52,0) -> 7611 | G25: =IFERROR(G24*ASSUMPTIONS!$B$52,0) -> 9030 | H25: =IFERROR(H24*ASSUMPTIONS!$B$52,0) -> 10578 | I25: =IFERROR(I24*ASSUMPTIONS!$B$52,0) -> 12126 | ... AK25: =IFERROR(AK24*ASSUMPTIONS!$B$52,0) -> 147834 | AL25: =SUM(B25:M25) -> 123066 | AM25: =SUM(N25:Y25) -> 442341 | AN25: =SUM(Z25:AK25) -> 1191702
A27: TOTAL REVENUE SUMMARY
A28: TOTAL REVENUE ($) | B28: =B19+B25 -> 8833 | C28: =C19+C25 -> 11370 | D28: =D19+D25 -> 14036 | E28: =E19+E25 -> 16831 | F28: =F19+F25 -> 19716 | G28: =G19+G25 -> 22820 | H28: =H19+H25 -> 26094 | I28: =I19+I25 -> 29548 | ... AK28: =AK19+AK25 -> 317725 | AL28: =SUM(B28:M28) -> 305457 | AM28: =SUM(N28:Y28) -> 997446 | AN28: =SUM(Z28:AK28) -> 2585867
A29: MoM Revenue Growth % | C29: =IFERROR((C28-B28)/B28,0) -> 0.28721839 | D29: =IFERROR((D28-C28)/C28,0) -> 0.23447669 | E29: =IFERROR((E28-D28)/D28,0) -> 0.19913081 | F29: =IFERROR((F28-E28)/E28,0) -> 0.1714099 | G29: =IFERROR((G28-F28)/F28,0) -> 0.15743559 | H29: =IFERROR((H28-G28)/G28,0) -> 0.14347064 | I29: =IFERROR((I28-H28)/H28,0) -> 0.13236759 | J29: =IFERROR((J28-I28)/I28,0) -> 0.12430621 | ... AK29: =IFERROR((AK28-AJ28)/AJ28,0) -> 0.07962133

Sheet HEADCOUNT
A1: HEADCOUNT — Departmental
A2: Auto-calculated from Assumptions Section 6.
B4: YEAR 1 | N4: YEAR 2 | Z4: YEAR 3
B5: Jan | C5: Feb | D5: Mar | E5: Apr | F5: May | G5: Jun | H5: Jul | I5: Aug | J5: Sep | K5: Oct | L5: Nov | M5: Dec | N5: Jan | O5: Feb | P5: Mar | Q5: Apr | R5: May | S5: Jun | T5: Jul | U5: Aug | V5: Sep | W5: Oct | X5: Nov | Y5: Dec | Z5: Jan | AA5: Feb | AB5: Mar | AC5: Apr | AD5: May | AE5: Jun | AF5: Jul | AG5: Aug | AH5: Sep | AI5: Oct | AJ5: Nov | AK5: Dec | AL5: Y1 Total | AM5: Y2 Total | AN5: Y3 Total
A7: ENGINEERING
A8: CTO | B8: =IFERROR(IF(1>=1,ROUND(140000/12*ASSUMPTIONS!$B$92,0),0),0) -> 15167 | C8: =IFERROR(IF(2>=1,ROUND(140000/12*ASSUMPTIONS!$B$92,0),0),0) -> 15167 | D8: =IFERROR(IF(3>=1,ROUND(140000/12*ASSUMPTIONS!$B$92,0),0),0) -> 15167 | E8: =IFERROR(IF(4>=1,ROUND(140000/12*ASSUMPTIONS!$B$92,0),0),0) -> 15167 | F8: =IFERROR(IF(5>=1,ROUND(140000/12*ASSUMPTIONS!$B$92,0),0),0) -> 15167 | G8: =IFERROR(IF(6>=1,ROUND(140000/12*ASSUMPTIONS!$B$92,0),0),0) -> 15167 | H8: =IFERROR(IF(7>=1,ROUND(140000/12*ASSUMPTIONS!$B$92,0),0),0) -> 15167 | I8: =IFERROR(IF(8>=1,ROUND(140000/12*ASSUMPTIONS!$B$92,0),0),0) -> 15167 | J8: =IFERROR(IF(9>=1,ROUND(140000/12*ASSUMPTIONS!$B$92,0),0),0) -> 15167 | K8: =IFERROR(IF(10>=1,ROUND(140000/12*ASSUMPTIONS!$B$92,0),0),0) -> 15167 | L8: =IFERROR(IF(11>=1,ROUND(140000/12*ASSUMPTIONS!$B$92,0),0),0) -> 15167 | M8: =IFERROR(IF(12>=1,ROUND(140000/12*ASSUMPTIONS!$B$92,0),0),0) -> 15167 | N8: =IFERROR(IF(13>=1,ROUND(140000/12*ASSUMPTIONS!$B$92,0),0),0) -> 15167 | O8: =IFERROR(IF(14>=1,ROUND(140000/12*ASSUMPTIONS!$B$92,0),0),0) -> 15167 | P8: =IFERROR(IF(15>=1,ROUND(140000/12*ASSUMPTIONS!$B$92,0),0),0) -> 15167 | Q8: =IFERROR(IF(16>=1,ROUND(140000/12*ASSUMPTIONS!$B$92,0),0),0) -> 15167 | R8: =IFERROR(IF(17>=1,ROUND(140000/12*ASSUMPTIONS!$B$92,0),0),0) -> 15167 | S8: =IFERROR(IF(18>=1,ROUND(140000/12*ASSUMPTIONS!$B$92,0),0),0) -> 15167 | T8: =IFERROR(IF(19>=1,ROUND(140000/12*ASSUMPTIONS!$B$92,0),0),0) -> 15167 | U8: =IFERROR(IF(20>=1,ROUND(140000/12*ASSUMPTIONS!$B$92,0),0),0) -> 15167 | V8: =IFERROR(IF(21>=1,ROUND(140000/12*ASSUMPTIONS!$B$92,0),0),0) -> 15167 | W8: =IFERROR(IF(22>=1,ROUND(140000/12*ASSUMPTIONS!$B$92,0),0),0) -> 15167 | X8: =IFERROR(IF(23>=1,ROUND(140000/12*ASSUMPTIONS!$B$92,0),0),0) -> 15167 | Y8: =IFERROR(IF(24>=1,ROUND(140000/12*ASSUMPTIONS!$B$92,0),0),0) -> 15167 | Z8: =IFERROR(IF(25>=1,ROUND(140000/12*ASSUMPTIONS!$B$92,0),0),0) -> 15167 | AA8: =IFERROR(IF(26>=1,ROUND(140000/12*ASSUMPTIONS!$B$92,0),0),0) -> 15167 | AB8: =IFERROR(IF(27>=1,ROUND(140000/12*ASSUMPTIONS!$B$92,0),0),0) -> 15167 | AC8: =IFERROR(IF(28>=1,ROUND(140000/12*ASSUMPTIONS!$B$92,0),0),0) -> 15167 | AD8: =IFERROR(IF(29>=1,ROUND(140000/12*ASSUMPTIONS!$B$92,0),0),0) -> 15167 | AE8: =IFERROR(IF(30>=1,ROUND(140000/12*ASSUMPTIONS!$B$92,0),0),0) -> 15167 | AF8: =IFERROR(IF(31>=1,ROUND(140000/12*ASSUMPTIONS!$B$92,0),0),0) -> 15167 | AG8: =IFERROR(IF(32>=1,ROUND(140000/12*ASSUMPTIONS!$B$92,0),0),0) -> 15167 | AH8: =IFERROR(IF(33>=1,ROUND(140000/12*ASSUMPTIONS!$B$92,0),0),0) -> 15167 | AI8: =IFERROR(IF(34>=1,ROUND(140000/12*ASSUMPTIONS!$B$92,0),0),0) -> 15167 | AJ8: =IFERROR(IF(35>=1,ROUND(140000/12*ASSUMPTIONS!$B$92,0),0),0) -> 15167 | AK8: =IFERROR(IF(36>=1,ROUND(140000/12*ASSUMPTIONS!$B$92,0),0),0) -> 15167
A9: Sr Eng | B9: =IFERROR(IF(1>=1,ROUND(130000/12*ASSUMPTIONS!$B$92,0),0),0) -> 14083 | C9: =IFERROR(IF(2>=1,ROUND(130000/12*ASSUMPTIONS!$B$92,0),0),0) -> 14083 | D9: =IFERROR(IF(3>=1,ROUND(130000/12*ASSUMPTIONS!$B$92,0),0),0) -> 14083 | E9: =IFERROR(IF(4>=1,ROUND(130000/12*ASSUMPTIONS!$B$92,0),0),0) -> 14083 | F9: =IFERROR(IF(5>=1,ROUND(130000/12*ASSUMPTIONS!$B$92,0),0),0) -> 14083 | G9: =IFERROR(IF(6>=1,ROUND(130000/12*ASSUMPTIONS!$B$92,0),0),0) -> 14083 | H9: =IFERROR(IF(7>=1,ROUND(130000/12*ASSUMPTIONS!$B$92,0),0),0) -> 14083 | I9: =IFERROR(IF(8>=1,ROUND(130000/12*ASSUMPTIONS!$B$92,0),0),0) -> 14083 | J9: =IFERROR(IF(9>=1,ROUND(130000/12*ASSUMPTIONS!$B$92,0),0),0) -> 14083 | K9: =IFERROR(IF(10>=1,ROUND(130000/12*ASSUMPTIONS!$B$92,0),0),0) -> 14083 | L9: =IFERROR(IF(11>=1,ROUND(130000/12*ASSUMPTIONS!$B$92,0),0),0) -> 14083 | M9: =IFERROR(IF(12>=1,ROUND(130000/12*ASSUMPTIONS!$B$92,0),0),0) -> 14083 | N9: =IFERROR(IF(13>=1,ROUND(130000/12*ASSUMPTIONS!$B$92,0),0),0) -> 14083 | O9: =IFERROR(IF(14>=1,ROUND(130000/12*ASSUMPTIONS!$B$92,0),0),0) -> 14083 | P9: =IFERROR(IF(15>=1,ROUND(130000/12*ASSUMPTIONS!$B$92,0),0),0) -> 14083 | Q9: =IFERROR(IF(16>=1,ROUND(130000/12*ASSUMPTIONS!$B$92,0),0),0) -> 14083 | R9: =IFERROR(IF(17>=1,ROUND(130000/12*ASSUMPTIONS!$B$92,0),0),0) -> 14083 | S9: =IFERROR(IF(18>=1,ROUND(130000/12*ASSUMPTIONS!$B$92,0),0),0) -> 14083 | T9: =IFERROR(IF(19>=1,ROUND(130000/12*ASSUMPTIONS!$B$92,0),0),0) -> 14083 | U9: =IFERROR(IF(20>=1,ROUND(130000/12*ASSUMPTIONS!$B$92,0),0),0) -> 14083 | V9: =IFERROR(IF(21>=1,ROUND(130000/12*ASSUMPTIONS!$B$92,0),0),0) -> 14083 | W9: =IFERROR(IF(22>=1,ROUND(130000/12*ASSUMPTIONS!$B$92,0),0),0) -> 14083 | X9: =IFERROR(IF(23>=1,ROUND(130000/12*ASSUMPTIONS!$B$92,0),0),0) -> 14083 | Y9: =IFERROR(IF(24>=1,ROUND(130000/12*ASSUMPTIONS!$B$92,0),0),0) -> 14083 | Z9: =IFERROR(IF(25>=1,ROUND(130000/12*ASSUMPTIONS!$B$92,0),0),0) -> 14083 | AA9: =IFERROR(IF(26>=1,ROUND(130000/12*ASSUMPTIONS!$B$92,0),0),0) -> 14083 | AB9: =IFERROR(IF(27>=1,ROUND(130000/12*ASSUMPTIONS!$B$92,0),0),0) -> 14083 | AC9: =IFERROR(IF(28>=1,ROUND(130000/12*ASSUMPTIONS!$B$92,0),0),0) -> 14083 | AD9: =IFERROR(IF(29>=1,ROUND(130000/12*ASSUMPTIONS!$B$92,0),0),0) -> 14083 | AE9: =IFERROR(IF(30>=1,ROUND(130000/12*ASSUMPTIONS!$B$92,0),0),0) -> 14083 | AF9: =IFERROR(IF(31>=1,ROUND(130000/12*ASSUMPTIONS!$B$92,0),0),0) -> 14083 | AG9: =IFERROR(IF(32>=1,ROUND(130000/12*ASSUMPTIONS!$B$92,0),0),0) -> 14083 | AH9: =IFERROR(IF(33>=1,ROUND(130000/12*ASSUMPTIONS!$B$92,0),0),0) -> 14083 | AI9: =IFERROR(IF(34>=1,ROUND(130000/12*ASSUMPTIONS!$B$92,0),0),0) -> 14083 | AJ9: =IFERROR(IF(35>=1,ROUND(130000/12*ASSUMPTIONS!$B$92,0),0),0) -> 14083 | AK9: =IFERROR(IF(36>=1,ROUND(130000/12*ASSUMPTIONS!$B$92,0),0),0) -> 14083
A10: Eng #2 | B10: =IFERROR(IF(1>=3,ROUND(120000/12*ASSUMPTIONS!$B$92,0),0),0) -> 0 | C10: =IFERROR(IF(2>=3,ROUND(120000/12*ASSUMPTIONS!$B$92,0),0),0) -> 0 | D10: =IFERROR(IF(3>=3,ROUND(120000/12*ASSUMPTIONS!$B$92,0),0),0) -> 13000 | E10: =IFERROR(IF(4>=3,ROUND(120000/12*ASSUMPTIONS!$B$92,0),0),0) -> 13000 | F10: =IFERROR(IF(5>=3,ROUND(120000/12*ASSUMPTIONS!$B$92,0),0),0) -> 13000 | G10: =IFERROR(IF(6>=3,ROUND(120000/12*ASSUMPTIONS!$B$92,0),0),0) -> 13000 | H10: =IFERROR(IF(7>=3,ROUND(120000/12*ASSUMPTIONS!$B$92,0),0),0) -> 13000 | I10: =IFERROR(IF(8>=3,ROUND(120000/12*ASSUMPTIONS!$B$92,0),0),0) -> 13000 | J10: =IFERROR(IF(9>=3,ROUND(120000/12*ASSUMPTIONS!$B$92,0),0),0) -> 13000 | K10: =IFERROR(IF(10>=3,ROUND(120000/12*ASSUMPTIONS!$B$92,0),0),0) -> 13000 | L10: =IFERROR(IF(11>=3,ROUND(120000/12*ASSUMPTIONS!$B$92,0),0),0) -> 13000 | M10: =IFERROR(IF(12>=3,ROUND(120000/12*ASSUMPTIONS!$B$92,0),0),0) -> 13000 | N10: =IFERROR(IF(13>=3,ROUND(120000/12*ASSUMPTIONS!$B$92,0),0),0) -> 13000 | O10: =IFERROR(IF(14>=3,ROUND(120000/12*ASSUMPTIONS!$B$92,0),0),0) -> 13000 | P10: =IFERROR(IF(15>=3,ROUND(120000/12*ASSUMPTIONS!$B$92,0),0),0) -> 13000 | Q10: =IFERROR(IF(16>=3,ROUND(120000/12*ASSUMPTIONS!$B$92,0),0),0) -> 13000 | R10: =IFERROR(IF(17>=3,ROUND(120000/12*ASSUMPTIONS!$B$92,0),0),0) -> 13000 | S10: =IFERROR(IF(18>=3,ROUND(120000/12*ASSUMPTIONS!$B$92,0),0),0) -> 13000 | T10: =IFERROR(IF(19>=3,ROUND(120000/12*ASSUMPTIONS!$B$92,0),0),0) -> 13000 | U10: =IFERROR(IF(20>=3,ROUND(120000/12*ASSUMPTIONS!$B$92,0),0),0) -> 13000 | V10: =IFERROR(IF(21>=3,ROUND(120000/12*ASSUMPTIONS!$B$92,0),0),0) -> 13000 | W10: =IFERROR(IF(22>=3,ROUND(120000/12*ASSUMPTIONS!$B$92,0),0),0) -> 13000 | X10: =IFERROR(IF(23>=3,ROUND(120000/12*ASSUMPTIONS!$B$92,0),0),0) -> 13000 | Y10: =IFERROR(IF(24>=3,ROUND(120000/12*ASSUMPTIONS!$B$92,0),0),0) -> 13000 | Z10: =IFERROR(IF(25>=3,ROUND(120000/12*ASSUMPTIONS!$B$92,0),0),0) -> 13000 | AA10: =IFERROR(IF(26>=3,ROUND(120000/12*ASSUMPTIONS!$B$92,0),0),0) -> 13000 | AB10: =IFERROR(IF(27>=3,ROUND(120000/12*ASSUMPTIONS!$B$92,0),0),0) -> 13000 | AC10: =IFERROR(IF(28>=3,ROUND(120000/12*ASSUMPTIONS!$B$92,0),0),0) -> 13000 | AD10: =IFERROR(IF(29>=3,ROUND(120000/12*ASSUMPTIONS!$B$92,0),0),0) -> 13000 | AE10: =IFERROR(IF(30>=3,ROUND(120000/12*ASSUMPTIONS!$B$92,0),0),0) -> 13000 | AF10: =IFERROR(IF(31>=3,ROUND(120000/12*ASSUMPTIONS!$B$92,0),0),0) -> 13000 | AG10: =IFERROR(IF(32>=3,ROUND(120000/12*ASSUMPTIONS!$B$92,0),0),0) -> 13000 | AH10: =IFERROR(IF(33>=3,ROUND(120000/12*ASSUMPTIONS!$B$92,0),0),0) -> 13000 | AI10: =IFERROR(IF(34>=3,ROUND(120000/12*ASSUMPTIONS!$B$92,0),0),0) -> 13000 | AJ10: =IFERROR(IF(35>=3,ROUND(120000/12*ASSUMPTIONS!$B$92,0),0),0) -> 13000 | AK10: =IFERROR(IF(36>=3,ROUND(120000/12*ASSUMPTIONS!$B$92,0),0),0) -> 13000
A11: Eng #3 | B11: =IFERROR(IF(1>=6,ROUND(120000/12*ASSUMPTIONS!$B$92,0),0),0) -> 0 | C11: =IFERROR(IF(2>=6,ROUND(120000/12*ASSUMPTIONS!$B$92,0),0),0) -> 0 | D11: =IFERROR(IF(3>=6,ROUND(120000/12*ASSUMPTIONS!$B$92,0),0),0) -> 0 | E11: =IFERROR(IF(4>=6,ROUND(120000/12*ASSUMPTIONS!$B$92,0),0),0) -> 0 | F11: =IFERROR(IF(5>=6,ROUND(120000/12*ASSUMPTIONS!$B$92,0),0),0) -> 0 | G11: =IFERROR(IF(6>=6,ROUND(120000/12*ASSUMPTIONS!$B$92,0),0),0) -> 13000 | H11: =IFERROR(IF(7>=6,ROUND(120000/12*ASSUMPTIONS!$B$92,0),0),0) -> 13000 | I11: =IFERROR(IF(8>=6,ROUND(120000/12*ASSUMPTIONS!$B$92,0),0),0) -> 13000 | J11: =IFERROR(IF(9>=6,ROUND(120000/12*ASSUMPTIONS!$B$92,0),0),0) -> 13000 | K11: =IFERROR(IF(10>=6,ROUND(120000/12*ASSUMPTIONS!$B$92,0),0),0) -> 13000 | L11: =IFERROR(IF(11>=6,ROUND(120000/12*ASSUMPTIONS!$B$92,0),0),0) -> 13000 | M11: =IFERROR(IF(12>=6,ROUND(120000/12*ASSUMPTIONS!$B$92,0),0),0) -> 13000 | N11: =IFERROR(IF(13>=6,ROUND(120000/12*ASSUMPTIONS!$B$92,0),0),0) -> 13000 | O11: =IFERROR(IF(14>=6,ROUND(120000/12*ASSUMPTIONS!$B$92,0),0),0) -> 13000 | P11: =IFERROR(IF(15>=6,ROUND(120000/12*ASSUMPTIONS!$B$92,0),0),0) -> 13000 | Q11: =IFERROR(IF(16>=6,ROUND(120000/12*ASSUMPTIONS!$B$92,0),0),0) -> 13000 | R11: =IFERROR(IF(17>=6,ROUND(120000/12*ASSUMPTIONS!$B$92,0),0),0) -> 13000 | S11: =IFERROR(IF(18>=6,ROUND(120000/12*ASSUMPTIONS!$B$92,0),0),0) -> 13000 | T11: =IFERROR(IF(19>=6,ROUND(120000/12*ASSUMPTIONS!$B$92,0),0),0) -> 13000 | U11: =IFERROR(IF(20>=6,ROUND(120000/12*ASSUMPTIONS!$B$92,0),0),0) -> 13000 | V11: =IFERROR(IF(21>=6,ROUND(120000/12*ASSUMPTIONS!$B$92,0),0),0) -> 13000 | W11: =IFERROR(IF(22>=6,ROUND(120000/12*ASSUMPTIONS!$B$92,0),0),0) -> 13000 | X11: =IFERROR(IF(23>=6,ROUND(120000/12*ASSUMPTIONS!$B$92,0),0),0) -> 13000 | Y11: =IFERROR(IF(24>=6,ROUND(120000/12*ASSUMPTIONS!$B$92,0),0),0) -> 13000 | Z11: =IFERROR(IF(25>=6,ROUND(120000/12*ASSUMPTIONS!$B$92,0),0),0) -> 13000 | AA11: =IFERROR(IF(26>=6,ROUND(120000/12*ASSUMPTIONS!$B$92,0),0),0) -> 13000 | AB11: =IFERROR(IF(27>=6,ROUND(120000/12*ASSUMPTIONS!$B$92,0),0),0) -> 13000 | AC11: =IFERROR(IF(28>=6,ROUND(120000/12*ASSUMPTIONS!$B$92,0),0),0) -> 13000 | AD11: =IFERROR(IF(29>=6,ROUND(120000/12*ASSUMPTIONS!$B$92,0),0),0) -> 13000 | AE11: =IFERROR(IF(30>=6,ROUND(120000/12*ASSUMPTIONS!$B$92,0),0),0) -> 13000 | AF11: =IFERROR(IF(31>=6,ROUND(120000/12*ASSUMPTIONS!$B$92,0),0),0) -> 13000 | AG11: =IFERROR(IF(32>=6,ROUND(120000/12*ASSUMPTIONS!$B$92,0),0),0) -> 13000 | AH11: =IFERROR(IF(33>=6,ROUND(120000/12*ASSUMPTIONS!$B$92,0),0),0) -> 13000 | AI11: =IFERROR(IF(34>=6,ROUND(120000/12*ASSUMPTIONS!$B$92,0),0),0) -> 13000 | AJ11: =IFERROR(IF(35>=6,ROUND(120000/12*ASSUMPTIONS!$B$92,0),0),0) -> 13000 | AK11: =IFERROR(IF(36>=6,ROUND(120000/12*ASSUMPTIONS!$B$92,0),0),0) -> 13000
A12: Eng #4 | B12: =IFERROR(IF(1>=9,ROUND(120000/12*ASSUMPTIONS!$B$92,0),0),0) -> 0 | C12: =IFERROR(IF(2>=9,ROUND(120000/12*ASSUMPTIONS!$B$92,0),0),0) -> 0 | D12: =IFERROR(IF(3>=9,ROUND(120000/12*ASSUMPTIONS!$B$92,0),0),0) -> 0 | E12: =IFERROR(IF(4>=9,ROUND(120000/12*ASSUMPTIONS!$B$92,0),0),0) -> 0 | F12: =IFERROR(IF(5>=9,ROUND(120000/12*ASSUMPTIONS!$B$92,0),0),0) -> 0 | G12: =IFERROR(IF(6>=9,ROUND(120000/12*ASSUMPTIONS!$B$92,0),0),0) -> 0 | H12: =IFERROR(IF(7>=9,ROUND(120000/12*ASSUMPTIONS!$B$92,0),0),0) -> 0 | I12: =IFERROR(IF(8>=9,ROUND(120000/12*ASSUMPTIONS!$B$92,0),0),0) -> 0 | J12: =IFERROR(IF(9>=9,ROUND(120000/12*ASSUMPTIONS!$B$92,0),0),0) -> 13000 | K12: =IFERROR(IF(10>=9,ROUND(120000/12*ASSUMPTIONS!$B$92,0),0),0) -> 13000 | L12: =IFERROR(IF(11>=9,ROUND(120000/12*ASSUMPTIONS!$B$92,0),0),0) -> 13000 | M12: =IFERROR(IF(12>=9,ROUND(120000/12*ASSUMPTIONS!$B$92,0),0),0) -> 13000 | N12: =IFERROR(IF(13>=9,ROUND(120000/12*ASSUMPTIONS!$B$92,0),0),0) -> 13000 | O12: =IFERROR(IF(14>=9,ROUND(120000/12*ASSUMPTIONS!$B$92,0),0),0) -> 13000 | P12: =IFERROR(IF(15>=9,ROUND(120000/12*ASSUMPTIONS!$B$92,0),0),0) -> 13000 | Q12: =IFERROR(IF(16>=9,ROUND(120000/12*ASSUMPTIONS!$B$92,0),0),0) -> 13000 | R12: =IFERROR(IF(17>=9,ROUND(120000/12*ASSUMPTIONS!$B$92,0),0),0) -> 13000 | S12: =IFERROR(IF(18>=9,ROUND(120000/12*ASSUMPTIONS!$B$92,0),0),0) -> 13000 | T12: =IFERROR(IF(19>=9,ROUND(120000/12*ASSUMPTIONS!$B$92,0),0),0) -> 13000 | U12: =IFERROR(IF(20>=9,ROUND(120000/12*ASSUMPTIONS!$B$92,0),0),0) -> 13000 | V12: =IFERROR(IF(21>=9,ROUND(120000/12*ASSUMPTIONS!$B$92,0),0),0) -> 13000 | W12: =IFERROR(IF(22>=9,ROUND(120000/12*ASSUMPTIONS!$B$92,0),0),0) -> 13000 | X12: =IFERROR(IF(23>=9,ROUND(120000/12*ASSUMPTIONS!$B$92,0),0),0) -> 13000 | Y12: =IFERROR(IF(24>=9,ROUND(120000/12*ASSUMPTIONS!$B$92,0),0),0) -> 13000 | Z12: =IFERROR(IF(25>=9,ROUND(120000/12*ASSUMPTIONS!$B$92,0),0),0) -> 13000 | AA12: =IFERROR(IF(26>=9,ROUND(120000/12*ASSUMPTIONS!$B$92,0),0),0) -> 13000 | AB12: =IFERROR(IF(27>=9,ROUND(120000/12*ASSUMPTIONS!$B$92,0),0),0) -> 13000 | AC12: =IFERROR(IF(28>=9,ROUND(120000/12*ASSUMPTIONS!$B$92,0),0),0) -> 13000 | AD12: =IFERROR(IF(29>=9,ROUND(120000/12*ASSUMPTIONS!$B$92,0),0),0) -> 13000 | AE12: =IFERROR(IF(30>=9,ROUND(120000/12*ASSUMPTIONS!$B$92,0),0),0) -> 13000 | AF12: =IFERROR(IF(31>=9,ROUND(120000/12*ASSUMPTIONS!$B$92,0),0),0) -> 13000 | AG12: =IFERROR(IF(32>=9,ROUND(120000/12*ASSUMPTIONS!$B$92,0),0),0) -> 13000 | AH12: =IFERROR(IF(33>=9,ROUND(120000/12*ASSUMPTIONS!$B$92,0),0),0) -> 13000 | AI12: =IFERROR(IF(34>=9,ROUND(120000/12*ASSUMPTIONS!$B$92,0),0),0) -> 13000 | AJ12: =IFERROR(IF(35>=9,ROUND(120000/12*ASSUMPTIONS!$B$92,0),0),0) -> 13000 | AK12: =IFERROR(IF(36>=9,ROUND(120000/12*ASSUMPTIONS!$B$92,0),0),0) -> 13000
A13: Eng #5 | B13: =IFERROR(IF(1>=12,ROUND(120000/12*ASSUMPTIONS!$B$92,0),0),0) -> 0 | C13: =IFERROR(IF(2>=12,ROUND(120000/12*ASSUMPTIONS!$B$92,0),0),0) -> 0 | D13: =IFERROR(IF(3>=12,ROUND(120000/12*ASSUMPTIONS!$B$92,0),0),0) -> 0 | E13: =IFERROR(IF(4>=12,ROUND(120000/12*ASSUMPTIONS!$B$92,0),0),0) -> 0 | F13: =IFERROR(IF(5>=12,ROUND(120000/12*ASSUMPTIONS!$B$92,0),0),0) -> 0 | G13: =IFERROR(IF(6>=12,ROUND(120000/12*ASSUMPTIONS!$B$92,0),0),0) -> 0 | H13: =IFERROR(IF(7>=12,ROUND(120000/12*ASSUMPTIONS!$B$92,0),0),0) -> 0 | I13: =IFERROR(IF(8>=12,ROUND(120000/12*ASSUMPTIONS!$B$92,0),0),0) -> 0 | J13: =IFERROR(IF(9>=12,ROUND(120000/12*ASSUMPTIONS!$B$92,0),0),0) -> 0 | K13: =IFERROR(IF(10>=12,ROUND(120000/12*ASSUMPTIONS!$B$92,0),0),0) -> 0 | L13: =IFERROR(IF(11>=12,ROUND(120000/12*ASSUMPTIONS!$B$92,0),0),0) -> 0 | M13: =IFERROR(IF(12>=12,ROUND(120000/12*ASSUMPTIONS!$B$92,0),0),0) -> 13000 | N13: =IFERROR(IF(13>=12,ROUND(120000/12*ASSUMPTIONS!$B$92,0),0),0) -> 13000 | O13: =IFERROR(IF(14>=12,ROUND(120000/12*ASSUMPTIONS!$B$92,0),0),0) -> 13000 | P13: =IFERROR(IF(15>=12,ROUND(120000/12*ASSUMPTIONS!$B$92,0),0),0) -> 13000 | Q13: =IFERROR(IF(16>=12,ROUND(120000/12*ASSUMPTIONS!$B$92,0),0),0) -> 13000 | R13: =IFERROR(IF(17>=12,ROUND(120000/12*ASSUMPTIONS!$B$92,0),0),0) -> 13000 | S13: =IFERROR(IF(18>=12,ROUND(120000/12*ASSUMPTIONS!$B$92,0),0),0) -> 13000 | T13: =IFERROR(IF(19>=12,ROUND(120000/12*ASSUMPTIONS!$B$92,0),0),0) -> 13000 | U13: =IFERROR(IF(20>=12,ROUND(120000/12*ASSUMPTIONS!$B$92,0),0),0) -> 13000 | V13: =IFERROR(IF(21>=12,ROUND(120000/12*ASSUMPTIONS!$B$92,0),0),0) -> 13000 | W13: =IFERROR(IF(22>=12,ROUND(120000/12*ASSUMPTIONS!$B$92,0),0),0) -> 13000 | X13: =IFERROR(IF(23>=12,ROUND(120000/12*ASSUMPTIONS!$B$92,0),0),0) -> 13000 | Y13: =IFERROR(IF(24>=12,ROUND(120000/12*ASSUMPTIONS!$B$92,0),0),0) -> 13000 | Z13: =IFERROR(IF(25>=12,ROUND(120000/12*ASSUMPTIONS!$B$92,0),0),0) -> 13000 | AA13: =IFERROR(IF(26>=12,ROUND(120000/12*ASSUMPTIONS!$B$92,0),0),0) -> 13000 | AB13: =IFERROR(IF(27>=12,ROUND(120000/12*ASSUMPTIONS!$B$92,0),0),0) -> 13000 | AC13: =IFERROR(IF(28>=12,ROUND(120000/12*ASSUMPTIONS!$B$92,0),0),0) -> 13000 | AD13: =IFERROR(IF(29>=12,ROUND(120000/12*ASSUMPTIONS!$B$92,0),0),0) -> 13000 | AE13: =IFERROR(IF(30>=12,ROUND(120000/12*ASSUMPTIONS!$B$92,0),0),0) -> 13000 | AF13: =IFERROR(IF(31>=12,ROUND(120000/12*ASSUMPTIONS!$B$92,0),0),0) -> 13000 | AG13: =IFERROR(IF(32>=12,ROUND(120000/12*ASSUMPTIONS!$B$92,0),0),0) -> 13000 | AH13: =IFERROR(IF(33>=12,ROUND(120000/12*ASSUMPTIONS!$B$92,0),0),0) -> 13000 | AI13: =IFERROR(IF(34>=12,ROUND(120000/12*ASSUMPTIONS!$B$92,0),0),0) -> 13000 | AJ13: =IFERROR(IF(35>=12,ROUND(120000/12*ASSUMPTIONS!$B$92,0),0),0) -> 13000 | AK13: =IFERROR(IF(36>=12,ROUND(120000/12*ASSUMPTIONS!$B$92,0),0),0) -> 13000
A14: Total ENGINEERING ($) | B14: =SUM(B8:B13) -> 29250 | C14: =SUM(C8:C13) -> 29250 | D14: =SUM(D8:D13) -> 42250 | E14: =SUM(E8:E13) -> 42250 | F14: =SUM(F8:F13) -> 42250 | G14: =SUM(G8:G13) -> 55250 | H14: =SUM(H8:H13) -> 55250 | I14: =SUM(I8:I13) -> 55250 | ... AK14: =SUM(AK8:AK13) -> 81250
A15: PRODUCT
A16: VP Product | B16: =IFERROR(IF(1>=3,ROUND(130000/12*ASSUMPTIONS!$B$92,0),0),0) -> 0 | C16: =IFERROR(IF(2>=3,ROUND(130000/12*ASSUMPTIONS!$B$92,0),0),0) -> 0 | D16: =IFERROR(IF(3>=3,ROUND(130000/12*ASSUMPTIONS!$B$92,0),0),0) -> 14083 | E16: =IFERROR(IF(4>=3,ROUND(130000/12*ASSUMPTIONS!$B$92,0),0),0) -> 14083 | F16: =IFERROR(IF(5>=3,ROUND(130000/12*ASSUMPTIONS!$B$92,0),0),0) -> 14083 | G16: =IFERROR(IF(6>=3,ROUND(130000/12*ASSUMPTIONS!$B$92,0),0),0) -> 14083 | H16: =IFERROR(IF(7>=3,ROUND(130000/12*ASSUMPTIONS!$B$92,0),0),0) -> 14083 | I16: =IFERROR(IF(8>=3,ROUND(130000/12*ASSUMPTIONS!$B$92,0),0),0) -> 14083 | J16: =IFERROR(IF(9>=3,ROUND(130000/12*ASSUMPTIONS!$B$92,0),0),0) -> 14083 | K16: =IFERROR(IF(10>=3,ROUND(130000/12*ASSUMPTIONS!$B$92,0),0),0) -> 14083 | L16: =IFERROR(IF(11>=3,ROUND(130000/12*ASSUMPTIONS!$B$92,0),0),0) -> 14083 | M16: =IFERROR(IF(12>=3,ROUND(130000/12*ASSUMPTIONS!$B$92,0),0),0) -> 14083 | N16: =IFERROR(IF(13>=3,ROUND(130000/12*ASSUMPTIONS!$B$92,0),0),0) -> 14083 | O16: =IFERROR(IF(14>=3,ROUND(130000/12*ASSUMPTIONS!$B$92,0),0),0) -> 14083 | P16: =IFERROR(IF(15>=3,ROUND(130000/12*ASSUMPTIONS!$B$92,0),0),0) -> 14083 | Q16: =IFERROR(IF(16>=3,ROUND(130000/12*ASSUMPTIONS!$B$92,0),0),0) -> 14083 | R16: =IFERROR(IF(17>=3,ROUND(130000/12*ASSUMPTIONS!$B$92,0),0),0) -> 14083 | S16: =IFERROR(IF(18>=3,ROUND(130000/12*ASSUMPTIONS!$B$92,0),0),0) -> 14083 | T16: =IFERROR(IF(19>=3,ROUND(130000/12*ASSUMPTIONS!$B$92,0),0),0) -> 14083 | U16: =IFERROR(IF(20>=3,ROUND(130000/12*ASSUMPTIONS!$B$92,0),0),0) -> 14083 | V16: =IFERROR(IF(21>=3,ROUND(130000/12*ASSUMPTIONS!$B$92,0),0),0) -> 14083 | W16: =IFERROR(IF(22>=3,ROUND(130000/12*ASSUMPTIONS!$B$92,0),0),0) -> 14083 | X16: =IFERROR(IF(23>=3,ROUND(130000/12*ASSUMPTIONS!$B$92,0),0),0) -> 14083 | Y16: =IFERROR(IF(24>=3,ROUND(130000/12*ASSUMPTIONS!$B$92,0),0),0) -> 14083 | Z16: =IFERROR(IF(25>=3,ROUND(130000/12*ASSUMPTIONS!$B$92,0),0),0) -> 14083 | AA16: =IFERROR(IF(26>=3,ROUND(130000/12*ASSUMPTIONS!$B$92,0),0),0) -> 14083 | AB16: =IFERROR(IF(27>=3,ROUND(130000/12*ASSUMPTIONS!$B$92,0),0),0) -> 14083 | AC16: =IFERROR(IF(28>=3,ROUND(130000/12*ASSUMPTIONS!$B$92,0),0),0) -> 14083 | AD16: =IFERROR(IF(29>=3,ROUND(130000/12*ASSUMPTIONS!$B$92,0),0),0) -> 14083 | AE16: =IFERROR(IF(30>=3,ROUND(130000/12*ASSUMPTIONS!$B$92,0),0),0) -> 14083 | AF16: =IFERROR(IF(31>=3,ROUND(130000/12*ASSUMPTIONS!$B$92,0),0),0) -> 14083 | AG16: =IFERROR(IF(32>=3,ROUND(130000/12*ASSUMPTIONS!$B$92,0),0),0) -> 14083 | AH16: =IFERROR(IF(33>=3,ROUND(130000/12*ASSUMPTIONS!$B$92,0),0),0) -> 14083 | AI16: =IFERROR(IF(34>=3,ROUND(130000/12*ASSUMPTIONS!$B$92,0),0),0) -> 14083 | AJ16: =IFERROR(IF(35>=3,ROUND(130000/12*ASSUMPTIONS!$B$92,0),0),0) -> 14083 | AK16: =IFERROR(IF(36>=3,ROUND(130000/12*ASSUMPTIONS!$B$92,0),0),0) -> 14083
A17: PM | B17: =IFERROR(IF(1>=6,ROUND(110000/12*ASSUMPTIONS!$B$92,0),0),0) -> 0 | C17: =IFERROR(IF(2>=6,ROUND(110000/12*ASSUMPTIONS!$B$92,0),0),0) -> 0 | D17: =IFERROR(IF(3>=6,ROUND(110000/12*ASSUMPTIONS!$B$92,0),0),0) -> 0 | E17: =IFERROR(IF(4>=6,ROUND(110000/12*ASSUMPTIONS!$B$92,0),0),0) -> 0 | F17: =IFERROR(IF(5>=6,ROUND(110000/12*ASSUMPTIONS!$B$92,0),0),0) -> 0 | G17: =IFERROR(IF(6>=6,ROUND(110000/12*ASSUMPTIONS!$B$92,0),0),0) -> 11917 | H17: =IFERROR(IF(7>=6,ROUND(110000/12*ASSUMPTIONS!$B$92,0),0),0) -> 11917 | I17: =IFERROR(IF(8>=6,ROUND(110000/12*ASSUMPTIONS!$B$92,0),0),0) -> 11917 | J17: =IFERROR(IF(9>=6,ROUND(110000/12*ASSUMPTIONS!$B$92,0),0),0) -> 11917 | K17: =IFERROR(IF(10>=6,ROUND(110000/12*ASSUMPTIONS!$B$92,0),0),0) -> 11917 | L17: =IFERROR(IF(11>=6,ROUND(110000/12*ASSUMPTIONS!$B$92,0),0),0) -> 11917 | M17: =IFERROR(IF(12>=6,ROUND(110000/12*ASSUMPTIONS!$B$92,0),0),0) -> 11917 | N17: =IFERROR(IF(13>=6,ROUND(110000/12*ASSUMPTIONS!$B$92,0),0),0) -> 11917 | O17: =IFERROR(IF(14>=6,ROUND(110000/12*ASSUMPTIONS!$B$92,0),0),0) -> 11917 | P17: =IFERROR(IF(15>=6,ROUND(110000/12*ASSUMPTIONS!$B$92,0),0),0) -> 11917 | Q17: =IFERROR(IF(16>=6,ROUND(110000/12*ASSUMPTIONS!$B$92,0),0),0) -> 11917 | R17: =IFERROR(IF(17>=6,ROUND(110000/12*ASSUMPTIONS!$B$92,0),0),0) -> 11917 | S17: =IFERROR(IF(18>=6,ROUND(110000/12*ASSUMPTIONS!$B$92,0),0),0) -> 11917 | T17: =IFERROR(IF(19>=6,ROUND(110000/12*ASSUMPTIONS!$B$92,0),0),0) -> 11917 | U17: =IFERROR(IF(20>=6,ROUND(110000/12*ASSUMPTIONS!$B$92,0),0),0) -> 11917 | V17: =IFERROR(IF(21>=6,ROUND(110000/12*ASSUMPTIONS!$B$92,0),0),0) -> 11917 | W17: =IFERROR(IF(22>=6,ROUND(110000/12*ASSUMPTIONS!$B$92,0),0),0) -> 11917 | X17: =IFERROR(IF(23>=6,ROUND(110000/12*ASSUMPTIONS!$B$92,0),0),0) -> 11917 | Y17: =IFERROR(IF(24>=6,ROUND(110000/12*ASSUMPTIONS!$B$92,0),0),0) -> 11917 | Z17: =IFERROR(IF(25>=6,ROUND(110000/12*ASSUMPTIONS!$B$92,0),0),0) -> 11917 | AA17: =IFERROR(IF(26>=6,ROUND(110000/12*ASSUMPTIONS!$B$92,0),0),0) -> 11917 | AB17: =IFERROR(IF(27>=6,ROUND(110000/12*ASSUMPTIONS!$B$92,0),0),0) -> 11917 | AC17: =IFERROR(IF(28>=6,ROUND(110000/12*ASSUMPTIONS!$B$92,0),0),0) -> 11917 | AD17: =IFERROR(IF(29>=6,ROUND(110000/12*ASSUMPTIONS!$B$92,0),0),0) -> 11917 | AE17: =IFERROR(IF(30>=6,ROUND(110000/12*ASSUMPTIONS!$B$92,0),0),0) -> 11917 | AF17: =IFERROR(IF(31>=6,ROUND(110000/12*ASSUMPTIONS!$B$92,0),0),0) -> 11917 | AG17: =IFERROR(IF(32>=6,ROUND(110000/12*ASSUMPTIONS!$B$92,0),0),0) -> 11917 | AH17: =IFERROR(IF(33>=6,ROUND(110000/12*ASSUMPTIONS!$B$92,0),0),0) -> 11917 | AI17: =IFERROR(IF(34>=6,ROUND(110000/12*ASSUMPTIONS!$B$92,0),0),0) -> 11917 | AJ17: =IFERROR(IF(35>=6,ROUND(110000/12*ASSUMPTIONS!$B$92,0),0),0) -> 11917 | AK17: =IFERROR(IF(36>=6,ROUND(110000/12*ASSUMPTIONS!$B$92,0),0),0) -> 11917
A18: Designer | B18: =IFERROR(IF(1>=4,ROUND(95000/12*ASSUMPTIONS!$B$92,0),0),0) -> 0 | C18: =IFERROR(IF(2>=4,ROUND(95000/12*ASSUMPTIONS!$B$92,0),0),0) -> 0 | D18: =IFERROR(IF(3>=4,ROUND(95000/12*ASSUMPTIONS!$B$92,0),0),0) -> 0 | E18: =IFERROR(IF(4>=4,ROUND(95000/12*ASSUMPTIONS!$B$92,0),0),0) -> 10292 | F18: =IFERROR(IF(5>=4,ROUND(95000/12*ASSUMPTIONS!$B$92,0),0),0) -> 10292 | G18: =IFERROR(IF(6>=4,ROUND(95000/12*ASSUMPTIONS!$B$92,0),0),0) -> 10292 | H18: =IFERROR(IF(7>=4,ROUND(95000/12*ASSUMPTIONS!$B$92,0),0),0) -> 10292 | I18: =IFERROR(IF(8>=4,ROUND(95000/12*ASSUMPTIONS!$B$92,0),0),0) -> 10292 | J18: =IFERROR(IF(9>=4,ROUND(95000/12*ASSUMPTIONS!$B$92,0),0),0) -> 10292 | K18: =IFERROR(IF(10>=4,ROUND(95000/12*ASSUMPTIONS!$B$92,0),0),0) -> 10292 | L18: =IFERROR(IF(11>=4,ROUND(95000/12*ASSUMPTIONS!$B$92,0),0),0) -> 10292 | M18: =IFERROR(IF(12>=4,ROUND(95000/12*ASSUMPTIONS!$B$92,0),0),0) -> 10292 | N18: =IFERROR(IF(13>=4,ROUND(95000/12*ASSUMPTIONS!$B$92,0),0),0) -> 10292 | O18: =IFERROR(IF(14>=4,ROUND(95000/12*ASSUMPTIONS!$B$92,0),0),0) -> 10292 | P18: =IFERROR(IF(15>=4,ROUND(95000/12*ASSUMPTIONS!$B$92,0),0),0) -> 10292 | Q18: =IFERROR(IF(16>=4,ROUND(95000/12*ASSUMPTIONS!$B$92,0),0),0) -> 10292 | R18: =IFERROR(IF(17>=4,ROUND(95000/12*ASSUMPTIONS!$B$92,0),0),0) -> 10292 | S18: =IFERROR(IF(18>=4,ROUND(95000/12*ASSUMPTIONS!$B$92,0),0),0) -> 10292 | T18: =IFERROR(IF(19>=4,ROUND(95000/12*ASSUMPTIONS!$B$92,0),0),0) -> 10292 | U18: =IFERROR(IF(20>=4,ROUND(95000/12*ASSUMPTIONS!$B$92,0),0),0) -> 10292 | V18: =IFERROR(IF(21>=4,ROUND(95000/12*ASSUMPTIONS!$B$92,0),0),0) -> 10292 | W18: =IFERROR(IF(22>=4,ROUND(95000/12*ASSUMPTIONS!$B$92,0),0),0) -> 10292 | X18: =IFERROR(IF(23>=4,ROUND(95000/12*ASSUMPTIONS!$B$92,0),0),0) -> 10292 | Y18: =IFERROR(IF(24>=4,ROUND(95000/12*ASSUMPTIONS!$B$92,0),0),0) -> 10292 | Z18: =IFERROR(IF(25>=4,ROUND(95000/12*ASSUMPTIONS!$B$92,0),0),0) -> 10292 | AA18: =IFERROR(IF(26>=4,ROUND(95000/12*ASSUMPTIONS!$B$92,0),0),0) -> 10292 | AB18: =IFERROR(IF(27>=4,ROUND(95000/12*ASSUMPTIONS!$B$92,0),0),0) -> 10292 | AC18: =IFERROR(IF(28>=4,ROUND(95000/12*ASSUMPTIONS!$B$92,0),0),0) -> 10292 | AD18: =IFERROR(IF(29>=4,ROUND(95000/12*ASSUMPTIONS!$B$92,0),0),0) -> 10292 | AE18: =IFERROR(IF(30>=4,ROUND(95000/12*ASSUMPTIONS!$B$92,0),0),0) -> 10292 | AF18: =IFERROR(IF(31>=4,ROUND(95000/12*ASSUMPTIONS!$B$92,0),0),0) -> 10292 | AG18: =IFERROR(IF(32>=4,ROUND(95000/12*ASSUMPTIONS!$B$92,0),0),0) -> 10292 | AH18: =IFERROR(IF(33>=4,ROUND(95000/12*ASSUMPTIONS!$B$92,0),0),0) -> 10292 | AI18: =IFERROR(IF(34>=4,ROUND(95000/12*ASSUMPTIONS!$B$92,0),0),0) -> 10292 | AJ18: =IFERROR(IF(35>=4,ROUND(95000/12*ASSUMPTIONS!$B$92,0),0),0) -> 10292 | AK18: =IFERROR(IF(36>=4,ROUND(95000/12*ASSUMPTIONS!$B$92,0),0),0) -> 10292
A19: Total PRODUCT ($) | B19: =SUM(B16:B18) -> 0 | C19: =SUM(C16:C18) -> 0 | D19: =SUM(D16:D18) -> 14083 | E19: =SUM(E16:E18) -> 24375 | F19: =SUM(F16:F18) -> 24375 | G19: =SUM(G16:G18) -> 36292 | H19: =SUM(H16:H18) -> 36292 | I19: =SUM(I16:I18) -> 36292 | ... AK19: =SUM(AK16:AK18) -> 36292
A20: SALES
A21: Sales Lead | B21: =IFERROR(IF(1>=1,ROUND(100000/12*ASSUMPTIONS!$B$92,0),0),0) -> 10833 | C21: =IFERROR(IF(2>=1,ROUND(100000/12*ASSUMPTIONS!$B$92,0),0),0) -> 10833 | D21: =IFERROR(IF(3>=1,ROUND(100000/12*ASSUMPTIONS!$B$92,0),0),0) -> 10833 | E21: =IFERROR(IF(4>=1,ROUND(100000/12*ASSUMPTIONS!$B$92,0),0),0) -> 10833 | F21: =IFERROR(IF(5>=1,ROUND(100000/12*ASSUMPTIONS!$B$92,0),0),0) -> 10833 | G21: =IFERROR(IF(6>=1,ROUND(100000/12*ASSUMPTIONS!$B$92,0),0),0) -> 10833 | H21: =IFERROR(IF(7>=1,ROUND(100000/12*ASSUMPTIONS!$B$92,0),0),0) -> 10833 | I21: =IFERROR(IF(8>=1,ROUND(100000/12*ASSUMPTIONS!$B$92,0),0),0) -> 10833 | J21: =IFERROR(IF(9>=1,ROUND(100000/12*ASSUMPTIONS!$B$92,0),0),0) -> 10833 | K21: =IFERROR(IF(10>=1,ROUND(100000/12*ASSUMPTIONS!$B$92,0),0),0) -> 10833 | L21: =IFERROR(IF(11>=1,ROUND(100000/12*ASSUMPTIONS!$B$92,0),0),0) -> 10833 | M21: =IFERROR(IF(12>=1,ROUND(100000/12*ASSUMPTIONS!$B$92,0),0),0) -> 10833 | N21: =IFERROR(IF(13>=1,ROUND(100000/12*ASSUMPTIONS!$B$92,0),0),0) -> 10833 | O21: =IFERROR(IF(14>=1,ROUND(100000/12*ASSUMPTIONS!$B$92,0),0),0) -> 10833 | P21: =IFERROR(IF(15>=1,ROUND(100000/12*ASSUMPTIONS!$B$92,0),0),0) -> 10833 | Q21: =IFERROR(IF(16>=1,ROUND(100000/12*ASSUMPTIONS!$B$92,0),0),0) -> 10833 | R21: =IFERROR(IF(17>=1,ROUND(100000/12*ASSUMPTIONS!$B$92,0),0),0) -> 10833 | S21: =IFERROR(IF(18>=1,ROUND(100000/12*ASSUMPTIONS!$B$92,0),0),0) -> 10833 | T21: =IFERROR(IF(19>=1,ROUND(100000/12*ASSUMPTIONS!$B$92,0),0),0) -> 10833 | U21: =IFERROR(IF(20>=1,ROUND(100000/12*ASSUMPTIONS!$B$92,0),0),0) -> 10833 | V21: =IFERROR(IF(21>=1,ROUND(100000/12*ASSUMPTIONS!$B$92,0),0),0) -> 10833 | W21: =IFERROR(IF(22>=1,ROUND(100000/12*ASSUMPTIONS!$B$92,0),0),0) -> 10833 | X21: =IFERROR(IF(23>=1,ROUND(100000/12*ASSUMPTIONS!$B$92,0),0),0) -> 10833 | Y21: =IFERROR(IF(24>=1,ROUND(100000/12*ASSUMPTIONS!$B$92,0),0),0) -> 10833 | Z21: =IFERROR(IF(25>=1,ROUND(100000/12*ASSUMPTIONS!$B$92,0),0),0) -> 10833 | AA21: =IFERROR(IF(26>=1,ROUND(100000/12*ASSUMPTIONS!$B$92,0),0),0) -> 10833 | AB21: =IFERROR(IF(27>=1,ROUND(100000/12*ASSUMPTIONS!$B$92,0),0),0) -> 10833 | AC21: =IFERROR(IF(28>=1,ROUND(100000/12*ASSUMPTIONS!$B$92,0),0),0) -> 10833 | AD21: =IFERROR(IF(29>=1,ROUND(100000/12*ASSUMPTIONS!$B$92,0),0),0) -> 10833 | AE21: =IFERROR(IF(30>=1,ROUND(100000/12*ASSUMPTIONS!$B$92,0),0),0) -> 10833 | AF21: =IFERROR(IF(31>=1,ROUND(100000/12*ASSUMPTIONS!$B$92,0),0),0) -> 10833 | AG21: =IFERROR(IF(32>=1,ROUND(100000/12*ASSUMPTIONS!$B$92,0),0),0) -> 10833 | AH21: =IFERROR(IF(33>=1,ROUND(100000/12*ASSUMPTIONS!$B$92,0),0),0) -> 10833 | AI21: =IFERROR(IF(34>=1,ROUND(100000/12*ASSUMPTIONS!$B$92,0),0),0) -> 10833 | AJ21: =IFERROR(IF(35>=1,ROUND(100000/12*ASSUMPTIONS!$B$92,0),0),0) -> 10833 | AK21: =IFERROR(IF(36>=1,ROUND(100000/12*ASSUMPTIONS!$B$92,0),0),0) -> 10833
A22: AE #1 | B22: =IFERROR(IF(1>=4,ROUND(85000/12*ASSUMPTIONS!$B$92,0),0),0) -> 0 | C22: =IFERROR(IF(2>=4,ROUND(85000/12*ASSUMPTIONS!$B$92,0),0),0) -> 0 | D22: =IFERROR(IF(3>=4,ROUND(85000/12*ASSUMPTIONS!$B$92,0),0),0) -> 0 | E22: =IFERROR(IF(4>=4,ROUND(85000/12*ASSUMPTIONS!$B$92,0),0),0) -> 9208 | F22: =IFERROR(IF(5>=4,ROUND(85000/12*ASSUMPTIONS!$B$92,0),0),0) -> 9208 | G22: =IFERROR(IF(6>=4,ROUND(85000/12*ASSUMPTIONS!$B$92,0),0),0) -> 9208 | H22: =IFERROR(IF(7>=4,ROUND(85000/12*ASSUMPTIONS!$B$92,0),0),0) -> 9208 | I22: =IFERROR(IF(8>=4,ROUND(85000/12*ASSUMPTIONS!$B$92,0),0),0) -> 9208 | J22: =IFERROR(IF(9>=4,ROUND(85000/12*ASSUMPTIONS!$B$92,0),0),0) -> 9208 | K22: =IFERROR(IF(10>=4,ROUND(85000/12*ASSUMPTIONS!$B$92,0),0),0) -> 9208 | L22: =IFERROR(IF(11>=4,ROUND(85000/12*ASSUMPTIONS!$B$92,0),0),0) -> 9208 | M22: =IFERROR(IF(12>=4,ROUND(85000/12*ASSUMPTIONS!$B$92,0),0),0) -> 9208 | N22: =IFERROR(IF(13>=4,ROUND(85000/12*ASSUMPTIONS!$B$92,0),0),0) -> 9208 | O22: =IFERROR(IF(14>=4,ROUND(85000/12*ASSUMPTIONS!$B$92,0),0),0) -> 9208 | P22: =IFERROR(IF(15>=4,ROUND(85000/12*ASSUMPTIONS!$B$92,0),0),0) -> 9208 | Q22: =IFERROR(IF(16>=4,ROUND(85000/12*ASSUMPTIONS!$B$92,0),0),0) -> 9208 | R22: =IFERROR(IF(17>=4,ROUND(85000/12*ASSUMPTIONS!$B$92,0),0),0) -> 9208 | S22: =IFERROR(IF(18>=4,ROUND(85000/12*ASSUMPTIONS!$B$92,0),0),0) -> 9208 | T22: =IFERROR(IF(19>=4,ROUND(85000/12*ASSUMPTIONS!$B$92,0),0),0) -> 9208 | U22: =IFERROR(IF(20>=4,ROUND(85000/12*ASSUMPTIONS!$B$92,0),0),0) -> 9208 | V22: =IFERROR(IF(21>=4,ROUND(85000/12*ASSUMPTIONS!$B$92,0),0),0) -> 9208 | W22: =IFERROR(IF(22>=4,ROUND(85000/12*ASSUMPTIONS!$B$92,0),0),0) -> 9208 | X22: =IFERROR(IF(23>=4,ROUND(85000/12*ASSUMPTIONS!$B$92,0),0),0) -> 9208 | Y22: =IFERROR(IF(24>=4,ROUND(85000/12*ASSUMPTIONS!$B$92,0),0),0) -> 9208 | Z22: =IFERROR(IF(25>=4,ROUND(85000/12*ASSUMPTIONS!$B$92,0),0),0) -> 9208 | AA22: =IFERROR(IF(26>=4,ROUND(85000/12*ASSUMPTIONS!$B$92,0),0),0) -> 9208 | AB22: =IFERROR(IF(27>=4,ROUND(85000/12*ASSUMPTIONS!$B$92,0),0),0) -> 9208 | AC22: =IFERROR(IF(28>=4,ROUND(85000/12*ASSUMPTIONS!$B$92,0),0),0) -> 9208 | AD22: =IFERROR(IF(29>=4,ROUND(85000/12*ASSUMPTIONS!$B$92,0),0),0) -> 9208 | AE22: =IFERROR(IF(30>=4,ROUND(85000/12*ASSUMPTIONS!$B$92,0),0),0) -> 9208 | AF22: =IFERROR(IF(31>=4,ROUND(85000/12*ASSUMPTIONS!$B$92,0),0),0) -> 9208 | AG22: =IFERROR(IF(32>=4,ROUND(85000/12*ASSUMPTIONS!$B$92,0),0),0) -> 9208 | AH22: =IFERROR(IF(33>=4,ROUND(85000/12*ASSUMPTIONS!$B$92,0),0),0) -> 9208 | AI22: =IFERROR(IF(34>=4,ROUND(85000/12*ASSUMPTIONS!$B$92,0),0),0) -> 9208 | AJ22: =IFERROR(IF(35>=4,ROUND(85000/12*ASSUMPTIONS!$B$92,0),0),0) -> 9208 | AK22: =IFERROR(IF(36>=4,ROUND(85000/12*ASSUMPTIONS!$B$92,0),0),0) -> 9208
A23: AE #2 | B23: =IFERROR(IF(1>=8,ROUND(85000/12*ASSUMPTIONS!$B$92,0),0),0) -> 0 | C23: =IFERROR(IF(2>=8,ROUND(85000/12*ASSUMPTIONS!$B$92,0),0),0) -> 0 | D23: =IFERROR(IF(3>=8,ROUND(85000/12*ASSUMPTIONS!$B$92,0),0),0) -> 0 | E23: =IFERROR(IF(4>=8,ROUND(85000/12*ASSUMPTIONS!$B$92,0),0),0) -> 0 | F23: =IFERROR(IF(5>=8,ROUND(85000/12*ASSUMPTIONS!$B$92,0),0),0) -> 0 | G23: =IFERROR(IF(6>=8,ROUND(85000/12*ASSUMPTIONS!$B$92,0),0),0) -> 0 | H23: =IFERROR(IF(7>=8,ROUND(85000/12*ASSUMPTIONS!$B$92,0),0),0) -> 0 | I23: =IFERROR(IF(8>=8,ROUND(85000/12*ASSUMPTIONS!$B$92,0),0),0) -> 9208 | J23: =IFERROR(IF(9>=8,ROUND(85000/12*ASSUMPTIONS!$B$92,0),0),0) -> 9208 | K23: =IFERROR(IF(10>=8,ROUND(85000/12*ASSUMPTIONS!$B$92,0),0),0) -> 9208 | L23: =IFERROR(IF(11>=8,ROUND(85000/12*ASSUMPTIONS!$B$92,0),0),0) -> 9208 | M23: =IFERROR(IF(12>=8,ROUND(85000/12*ASSUMPTIONS!$B$92,0),0),0) -> 9208 | N23: =IFERROR(IF(13>=8,ROUND(85000/12*ASSUMPTIONS!$B$92,0),0),0) -> 9208 | O23: =IFERROR(IF(14>=8,ROUND(85000/12*ASSUMPTIONS!$B$92,0),0),0) -> 9208 | P23: =IFERROR(IF(15>=8,ROUND(85000/12*ASSUMPTIONS!$B$92,0),0),0) -> 9208 | Q23: =IFERROR(IF(16>=8,ROUND(85000/12*ASSUMPTIONS!$B$92,0),0),0) -> 9208 | R23: =IFERROR(IF(17>=8,ROUND(85000/12*ASSUMPTIONS!$B$92,0),0),0) -> 9208 | S23: =IFERROR(IF(18>=8,ROUND(85000/12*ASSUMPTIONS!$B$92,0),0),0) -> 9208 | T23: =IFERROR(IF(19>=8,ROUND(85000/12*ASSUMPTIONS!$B$92,0),0),0) -> 9208 | U23: =IFERROR(IF(20>=8,ROUND(85000/12*ASSUMPTIONS!$B$92,0),0),0) -> 9208 | V23: =IFERROR(IF(21>=8,ROUND(85000/12*ASSUMPTIONS!$B$92,0),0),0) -> 9208 | W23: =IFERROR(IF(22>=8,ROUND(85000/12*ASSUMPTIONS!$B$92,0),0),0) -> 9208 | X23: =IFERROR(IF(23>=8,ROUND(85000/12*ASSUMPTIONS!$B$92,0),0),0) -> 9208 | Y23: =IFERROR(IF(24>=8,ROUND(85000/12*ASSUMPTIONS!$B$92,0),0),0) -> 9208 | Z23: =IFERROR(IF(25>=8,ROUND(85000/12*ASSUMPTIONS!$B$92,0),0),0) -> 9208 | AA23: =IFERROR(IF(26>=8,ROUND(85000/12*ASSUMPTIONS!$B$92,0),0),0) -> 9208 | AB23: =IFERROR(IF(27>=8,ROUND(85000/12*ASSUMPTIONS!$B$92,0),0),0) -> 9208 | AC23: =IFERROR(IF(28>=8,ROUND(85000/12*ASSUMPTIONS!$B$92,0),0),0) -> 9208 | AD23: =IFERROR(IF(29>=8,ROUND(85000/12*ASSUMPTIONS!$B$92,0),0),0) -> 9208 | AE23: =IFERROR(IF(30>=8,ROUND(85000/12*ASSUMPTIONS!$B$92,0),0),0) -> 9208 | AF23: =IFERROR(IF(31>=8,ROUND(85000/12*ASSUMPTIONS!$B$92,0),0),0) -> 9208 | AG23: =IFERROR(IF(32>=8,ROUND(85000/12*ASSUMPTIONS!$B$92,0),0),0) -> 9208 | AH23: =IFERROR(IF(33>=8,ROUND(85000/12*ASSUMPTIONS!$B$92,0),0),0) -> 9208 | AI23: =IFERROR(IF(34>=8,ROUND(85000/12*ASSUMPTIONS!$B$92,0),0),0) -> 9208 | AJ23: =IFERROR(IF(35>=8,ROUND(85000/12*ASSUMPTIONS!$B$92,0),0),0) -> 9208 | AK23: =IFERROR(IF(36>=8,ROUND(85000/12*ASSUMPTIONS!$B$92,0),0),0) -> 9208
A24: SDR | B24: =IFERROR(IF(1>=6,ROUND(55000/12*ASSUMPTIONS!$B$92,0),0),0) -> 0 | C24: =IFERROR(IF(2>=6,ROUND(55000/12*ASSUMPTIONS!$B$92,0),0),0) -> 0 | D24: =IFERROR(IF(3>=6,ROUND(55000/12*ASSUMPTIONS!$B$92,0),0),0) -> 0 | E24: =IFERROR(IF(4>=6,ROUND(55000/12*ASSUMPTIONS!$B$92,0),0),0) -> 0 | F24: =IFERROR(IF(5>=6,ROUND(55000/12*ASSUMPTIONS!$B$92,0),0),0) -> 0 | G24: =IFERROR(IF(6>=6,ROUND(55000/12*ASSUMPTIONS!$B$92,0),0),0) -> 5958 | H24: =IFERROR(IF(7>=6,ROUND(55000/12*ASSUMPTIONS!$B$92,0),0),0) -> 5958 | I24: =IFERROR(IF(8>=6,ROUND(55000/12*ASSUMPTIONS!$B$92,0),0),0) -> 5958 | J24: =IFERROR(IF(9>=6,ROUND(55000/12*ASSUMPTIONS!$B$92,0),0),0) -> 5958 | K24: =IFERROR(IF(10>=6,ROUND(55000/12*ASSUMPTIONS!$B$92,0),0),0) -> 5958 | L24: =IFERROR(IF(11>=6,ROUND(55000/12*ASSUMPTIONS!$B$92,0),0),0) -> 5958 | M24: =IFERROR(IF(12>=6,ROUND(55000/12*ASSUMPTIONS!$B$92,0),0),0) -> 5958 | N24: =IFERROR(IF(13>=6,ROUND(55000/12*ASSUMPTIONS!$B$92,0),0),0) -> 5958 | O24: =IFERROR(IF(14>=6,ROUND(55000/12*ASSUMPTIONS!$B$92,0),0),0) -> 5958 | P24: =IFERROR(IF(15>=6,ROUND(55000/12*ASSUMPTIONS!$B$92,0),0),0) -> 5958 | Q24: =IFERROR(IF(16>=6,ROUND(55000/12*ASSUMPTIONS!$B$92,0),0),0) -> 5958 | R24: =IFERROR(IF(17>=6,ROUND(55000/12*ASSUMPTIONS!$B$92,0),0),0) -> 5958 | S24: =IFERROR(IF(18>=6,ROUND(55000/12*ASSUMPTIONS!$B$92,0),0),0) -> 5958 | T24: =IFERROR(IF(19>=6,ROUND(55000/12*ASSUMPTIONS!$B$92,0),0),0) -> 5958 | U24: =IFERROR(IF(20>=6,ROUND(55000/12*ASSUMPTIONS!$B$92,0),0),0) -> 5958 | V24: =IFERROR(IF(21>=6,ROUND(55000/12*ASSUMPTIONS!$B$92,0),0),0) -> 5958 | W24: =IFERROR(IF(22>=6,ROUND(55000/12*ASSUMPTIONS!$B$92,0),0),0) -> 5958 | X24: =IFERROR(IF(23>=6,ROUND(55000/12*ASSUMPTIONS!$B$92,0),0),0) -> 5958 | Y24: =IFERROR(IF(24>=6,ROUND(55000/12*ASSUMPTIONS!$B$92,0),0),0) -> 5958 | Z24: =IFERROR(IF(25>=6,ROUND(55000/12*ASSUMPTIONS!$B$92,0),0),0) -> 5958 | AA24: =IFERROR(IF(26>=6,ROUND(55000/12*ASSUMPTIONS!$B$92,0),0),0) -> 5958 | AB24: =IFERROR(IF(27>=6,ROUND(55000/12*ASSUMPTIONS!$B$92,0),0),0) -> 5958 | AC24: =IFERROR(IF(28>=6,ROUND(55000/12*ASSUMPTIONS!$B$92,0),0),0) -> 5958 | AD24: =IFERROR(IF(29>=6,ROUND(55000/12*ASSUMPTIONS!$B$92,0),0),0) -> 5958 | AE24: =IFERROR(IF(30>=6,ROUND(55000/12*ASSUMPTIONS!$B$92,0),0),0) -> 5958 | AF24: =IFERROR(IF(31>=6,ROUND(55000/12*ASSUMPTIONS!$B$92,0),0),0) -> 5958 | AG24: =IFERROR(IF(32>=6,ROUND(55000/12*ASSUMPTIONS!$B$92,0),0),0) -> 5958 | AH24: =IFERROR(IF(33>=6,ROUND(55000/12*ASSUMPTIONS!$B$92,0),0),0) -> 5958 | AI24: =IFERROR(IF(34>=6,ROUND(55000/12*ASSUMPTIONS!$B$92,0),0),0) -> 5958 | AJ24: =IFERROR(IF(35>=6,ROUND(55000/12*ASSUMPTIONS!$B$92,0),0),0) -> 5958 | AK24: =IFERROR(IF(36>=6,ROUND(55000/12*ASSUMPTIONS!$B$92,0),0),0) -> 5958
A25: Total SALES ($) | B25: =SUM(B21:B24) -> 10833 | C25: =SUM(C21:C24) -> 10833 | D25: =SUM(D21:D24) -> 10833 | E25: =SUM(E21:E24) -> 20041 | F25: =SUM(F21:F24) -> 20041 | G25: =SUM(G21:G24) -> 25999 | H25: =SUM(H21:H24) -> 25999 | I25: =SUM(I21:I24) -> 35207 | ... AK25: =SUM(AK21:AK24) -> 35207
A26: MARKETING
A27: Marketing Lead | B27: =IFERROR(IF(1>=3,ROUND(95000/12*ASSUMPTIONS!$B$92,0),0),0) -> 0 | C27: =IFERROR(IF(2>=3,ROUND(95000/12*ASSUMPTIONS!$B$92,0),0),0) -> 0 | D27: =IFERROR(IF(3>=3,ROUND(95000/12*ASSUMPTIONS!$B$92,0),0),0) -> 10292 | E27: =IFERROR(IF(4>=3,ROUND(95000/12*ASSUMPTIONS!$B$92,0),0),0) -> 10292 | F27: =IFERROR(IF(5>=3,ROUND(95000/12*ASSUMPTIONS!$B$92,0),0),0) -> 10292 | G27: =IFERROR(IF(6>=3,ROUND(95000/12*ASSUMPTIONS!$B$92,0),0),0) -> 10292 | H27: =IFERROR(IF(7>=3,ROUND(95000/12*ASSUMPTIONS!$B$92,0),0),0) -> 10292 | I27: =IFERROR(IF(8>=3,ROUND(95000/12*ASSUMPTIONS!$B$92,0),0),0) -> 10292 | J27: =IFERROR(IF(9>=3,ROUND(95000/12*ASSUMPTIONS!$B$92,0),0),0) -> 10292 | K27: =IFERROR(IF(10>=3,ROUND(95000/12*ASSUMPTIONS!$B$92,0),0),0) -> 10292 | L27: =IFERROR(IF(11>=3,ROUND(95000/12*ASSUMPTIONS!$B$92,0),0),0) -> 10292 | M27: =IFERROR(IF(12>=3,ROUND(95000/12*ASSUMPTIONS!$B$92,0),0),0) -> 10292 | N27: =IFERROR(IF(13>=3,ROUND(95000/12*ASSUMPTIONS!$B$92,0),0),0) -> 10292 | O27: =IFERROR(IF(14>=3,ROUND(95000/12*ASSUMPTIONS!$B$92,0),0),0) -> 10292 | P27: =IFERROR(IF(15>=3,ROUND(95000/12*ASSUMPTIONS!$B$92,0),0),0) -> 10292 | Q27: =IFERROR(IF(16>=3,ROUND(95000/12*ASSUMPTIONS!$B$92,0),0),0) -> 10292 | R27: =IFERROR(IF(17>=3,ROUND(95000/12*ASSUMPTIONS!$B$92,0),0),0) -> 10292 | S27: =IFERROR(IF(18>=3,ROUND(95000/12*ASSUMPTIONS!$B$92,0),0),0) -> 10292 | T27: =IFERROR(IF(19>=3,ROUND(95000/12*ASSUMPTIONS!$B$92,0),0),0) -> 10292 | U27: =IFERROR(IF(20>=3,ROUND(95000/12*ASSUMPTIONS!$B$92,0),0),0) -> 10292 | V27: =IFERROR(IF(21>=3,ROUND(95000/12*ASSUMPTIONS!$B$92,0),0),0) -> 10292 | W27: =IFERROR(IF(22>=3,ROUND(95000/12*ASSUMPTIONS!$B$92,0),0),0) -> 10292 | X27: =IFERROR(IF(23>=3,ROUND(95000/12*ASSUMPTIONS!$B$92,0),0),0) -> 10292 | Y27: =IFERROR(IF(24>=3,ROUND(95000/12*ASSUMPTIONS!$B$92,0),0),0) -> 10292 | Z27: =IFERROR(IF(25>=3,ROUND(95000/12*ASSUMPTIONS!$B$92,0),0),0) -> 10292 | AA27: =IFERROR(IF(26>=3,ROUND(95000/12*ASSUMPTIONS!$B$92,0),0),0) -> 10292 | AB27: =IFERROR(IF(27>=3,ROUND(95000/12*ASSUMPTIONS!$B$92,0),0),0) -> 10292 | AC27: =IFERROR(IF(28>=3,ROUND(95000/12*ASSUMPTIONS!$B$92,0),0),0) -> 10292 | AD27: =IFERROR(IF(29>=3,ROUND(95000/12*ASSUMPTIONS!$B$92,0),0),0) -> 10292 | AE27: =IFERROR(IF(30>=3,ROUND(95000/12*ASSUMPTIONS!$B$92,0),0),0) -> 10292 | AF27: =IFERROR(IF(31>=3,ROUND(95000/12*ASSUMPTIONS!$B$92,0),0),0) -> 10292 | AG27: =IFERROR(IF(32>=3,ROUND(95000/12*ASSUMPTIONS!$B$92,0),0),0) -> 10292 | AH27: =IFERROR(IF(33>=3,ROUND(95000/12*ASSUMPTIONS!$B$92,0),0),0) -> 10292 | AI27: =IFERROR(IF(34>=3,ROUND(95000/12*ASSUMPTIONS!$B$92,0),0),0) -> 10292 | AJ27: =IFERROR(IF(35>=3,ROUND(95000/12*ASSUMPTIONS!$B$92,0),0),0) -> 10292 | AK27: =IFERROR(IF(36>=3,ROUND(95000/12*ASSUMPTIONS!$B$92,0),0),0) -> 10292
A28: Growth | B28: =IFERROR(IF(1>=6,ROUND(80000/12*ASSUMPTIONS!$B$92,0),0),0) -> 0 | C28: =IFERROR(IF(2>=6,ROUND(80000/12*ASSUMPTIONS!$B$92,0),0),0) -> 0 | D28: =IFERROR(IF(3>=6,ROUND(80000/12*ASSUMPTIONS!$B$92,0),0),0) -> 0 | E28: =IFERROR(IF(4>=6,ROUND(80000/12*ASSUMPTIONS!$B$92,0),0),0) -> 0 | F28: =IFERROR(IF(5>=6,ROUND(80000/12*ASSUMPTIONS!$B$92,0),0),0) -> 0 | G28: =IFERROR(IF(6>=6,ROUND(80000/12*ASSUMPTIONS!$B$92,0),0),0) -> 8667 | H28: =IFERROR(IF(7>=6,ROUND(80000/12*ASSUMPTIONS!$B$92,0),0),0) -> 8667 | I28: =IFERROR(IF(8>=6,ROUND(80000/12*ASSUMPTIONS!$B$92,0),0),0) -> 8667 | J28: =IFERROR(IF(9>=6,ROUND(80000/12*ASSUMPTIONS!$B$92,0),0),0) -> 8667 | K28: =IFERROR(IF(10>=6,ROUND(80000/12*ASSUMPTIONS!$B$92,0),0),0) -> 8667 | L28: =IFERROR(IF(11>=6,ROUND(80000/12*ASSUMPTIONS!$B$92,0),0),0) -> 8667 | M28: =IFERROR(IF(12>=6,ROUND(80000/12*ASSUMPTIONS!$B$92,0),0),0) -> 8667 | N28: =IFERROR(IF(13>=6,ROUND(80000/12*ASSUMPTIONS!$B$92,0),0),0) -> 8667 | O28: =IFERROR(IF(14>=6,ROUND(80000/12*ASSUMPTIONS!$B$92,0),0),0) -> 8667 | P28: =IFERROR(IF(15>=6,ROUND(80000/12*ASSUMPTIONS!$B$92,0),0),0) -> 8667 | Q28: =IFERROR(IF(16>=6,ROUND(80000/12*ASSUMPTIONS!$B$92,0),0),0) -> 8667 | R28: =IFERROR(IF(17>=6,ROUND(80000/12*ASSUMPTIONS!$B$92,0),0),0) -> 8667 | S28: =IFERROR(IF(18>=6,ROUND(80000/12*ASSUMPTIONS!$B$92,0),0),0) -> 8667 | T28: =IFERROR(IF(19>=6,ROUND(80000/12*ASSUMPTIONS!$B$92,0),0),0) -> 8667 | U28: =IFERROR(IF(20>=6,ROUND(80000/12*ASSUMPTIONS!$B$92,0),0),0) -> 8667 | V28: =IFERROR(IF(21>=6,ROUND(80000/12*ASSUMPTIONS!$B$92,0),0),0) -> 8667 | W28: =IFERROR(IF(22>=6,ROUND(80000/12*ASSUMPTIONS!$B$92,0),0),0) -> 8667 | X28: =IFERROR(IF(23>=6,ROUND(80000/12*ASSUMPTIONS!$B$92,0),0),0) -> 8667 | Y28: =IFERROR(IF(24>=6,ROUND(80000/12*ASSUMPTIONS!$B$92,0),0),0) -> 8667 | Z28: =IFERROR(IF(25>=6,ROUND(80000/12*ASSUMPTIONS!$B$92,0),0),0) -> 8667 | AA28: =IFERROR(IF(26>=6,ROUND(80000/12*ASSUMPTIONS!$B$92,0),0),0) -> 8667 | AB28: =IFERROR(IF(27>=6,ROUND(80000/12*ASSUMPTIONS!$B$92,0),0),0) -> 8667 | AC28: =IFERROR(IF(28>=6,ROUND(80000/12*ASSUMPTIONS!$B$92,0),0),0) -> 8667 | AD28: =IFERROR(IF(29>=6,ROUND(80000/12*ASSUMPTIONS!$B$92,0),0),0) -> 8667 | AE28: =IFERROR(IF(30>=6,ROUND(80000/12*ASSUMPTIONS!$B$92,0),0),0) -> 8667 | AF28: =IFERROR(IF(31>=6,ROUND(80000/12*ASSUMPTIONS!$B$92,0),0),0) -> 8667 | AG28: =IFERROR(IF(32>=6,ROUND(80000/12*ASSUMPTIONS!$B$92,0),0),0) -> 8667 | AH28: =IFERROR(IF(33>=6,ROUND(80000/12*ASSUMPTIONS!$B$92,0),0),0) -> 8667 | AI28: =IFERROR(IF(34>=6,ROUND(80000/12*ASSUMPTIONS!$B$92,0),0),0) -> 8667 | AJ28: =IFERROR(IF(35>=6,ROUND(80000/12*ASSUMPTIONS!$B$92,0),0),0) -> 8667 | AK28: =IFERROR(IF(36>=6,ROUND(80000/12*ASSUMPTIONS!$B$92,0),0),0) -> 8667
A29: Total MARKETING ($) | B29: =SUM(B27:B28) -> 0 | C29: =SUM(C27:C28) -> 0 | D29: =SUM(D27:D28) -> 10292 | E29: =SUM(E27:E28) -> 10292 | F29: =SUM(F27:F28) -> 10292 | G29: =SUM(G27:G28) -> 18959 | H29: =SUM(H27:H28) -> 18959 | I29: =SUM(I27:I28) -> 18959 | ... AK29: =SUM(AK27:AK28) -> 18959
A30: CUSTOMER SUCCESS
A31: CS Lead | B31: =IFERROR(IF(1>=4,ROUND(80000/12*ASSUMPTIONS!$B$92,0),0),0) -> 0 | C31: =IFERROR(IF(2>=4,ROUND(80000/12*ASSUMPTIONS!$B$92,0),0),0) -> 0 | D31: =IFERROR(IF(3>=4,ROUND(80000/12*ASSUMPTIONS!$B$92,0),0),0) -> 0 | E31: =IFERROR(IF(4>=4,ROUND(80000/12*ASSUMPTIONS!$B$92,0),0),0) -> 8667 | F31: =IFERROR(IF(5>=4,ROUND(80000/12*ASSUMPTIONS!$B$92,0),0),0) -> 8667 | G31: =IFERROR(IF(6>=4,ROUND(80000/12*ASSUMPTIONS!$B$92,0),0),0) -> 8667 | H31: =IFERROR(IF(7>=4,ROUND(80000/12*ASSUMPTIONS!$B$92,0),0),0) -> 8667 | I31: =IFERROR(IF(8>=4,ROUND(80000/12*ASSUMPTIONS!$B$92,0),0),0) -> 8667 | J31: =IFERROR(IF(9>=4,ROUND(80000/12*ASSUMPTIONS!$B$92,0),0),0) -> 8667 | K31: =IFERROR(IF(10>=4,ROUND(80000/12*ASSUMPTIONS!$B$92,0),0),0) -> 8667 | L31: =IFERROR(IF(11>=4,ROUND(80000/12*ASSUMPTIONS!$B$92,0),0),0) -> 8667 | M31: =IFERROR(IF(12>=4,ROUND(80000/12*ASSUMPTIONS!$B$92,0),0),0) -> 8667 | N31: =IFERROR(IF(13>=4,ROUND(80000/12*ASSUMPTIONS!$B$92,0),0),0) -> 8667 | O31: =IFERROR(IF(14>=4,ROUND(80000/12*ASSUMPTIONS!$B$92,0),0),0) -> 8667 | P31: =IFERROR(IF(15>=4,ROUND(80000/12*ASSUMPTIONS!$B$92,0),0),0) -> 8667 | Q31: =IFERROR(IF(16>=4,ROUND(80000/12*ASSUMPTIONS!$B$92,0),0),0) -> 8667 | R31: =IFERROR(IF(17>=4,ROUND(80000/12*ASSUMPTIONS!$B$92,0),0),0) -> 8667 | S31: =IFERROR(IF(18>=4,ROUND(80000/12*ASSUMPTIONS!$B$92,0),0),0) -> 8667 | T31: =IFERROR(IF(19>=4,ROUND(80000/12*ASSUMPTIONS!$B$92,0),0),0) -> 8667 | U31: =IFERROR(IF(20>=4,ROUND(80000/12*ASSUMPTIONS!$B$92,0),0),0) -> 8667 | V31: =IFERROR(IF(21>=4,ROUND(80000/12*ASSUMPTIONS!$B$92,0),0),0) -> 8667 | W31: =IFERROR(IF(22>=4,ROUND(80000/12*ASSUMPTIONS!$B$92,0),0),0) -> 8667 | X31: =IFERROR(IF(23>=4,ROUND(80000/12*ASSUMPTIONS!$B$92,0),0),0) -> 8667 | Y31: =IFERROR(IF(24>=4,ROUND(80000/12*ASSUMPTIONS!$B$92,0),0),0) -> 8667 | Z31: =IFERROR(IF(25>=4,ROUND(80000/12*ASSUMPTIONS!$B$92,0),0),0) -> 8667 | AA31: =IFERROR(IF(26>=4,ROUND(80000/12*ASSUMPTIONS!$B$92,0),0),0) -> 8667 | AB31: =IFERROR(IF(27>=4,ROUND(80000/12*ASSUMPTIONS!$B$92,0),0),0) -> 8667 | AC31: =IFERROR(IF(28>=4,ROUND(80000/12*ASSUMPTIONS!$B$92,0),0),0) -> 8667 | AD31: =IFERROR(IF(29>=4,ROUND(80000/12*ASSUMPTIONS!$B$92,0),0),0) -> 8667 | AE31: =IFERROR(IF(30>=4,ROUND(80000/12*ASSUMPTIONS!$B$92,0),0),0) -> 8667 | AF31: =IFERROR(IF(31>=4,ROUND(80000/12*ASSUMPTIONS!$B$92,0),0),0) -> 8667 | AG31: =IFERROR(IF(32>=4,ROUND(80000/12*ASSUMPTIONS!$B$92,0),0),0) -> 8667 | AH31: =IFERROR(IF(33>=4,ROUND(80000/12*ASSUMPTIONS!$B$92,0),0),0) -> 8667 | AI31: =IFERROR(IF(34>=4,ROUND(80000/12*ASSUMPTIONS!$B$92,0),0),0) -> 8667 | AJ31: =IFERROR(IF(35>=4,ROUND(80000/12*ASSUMPTIONS!$B$92,0),0),0) -> 8667 | AK31: =IFERROR(IF(36>=4,ROUND(80000/12*ASSUMPTIONS!$B$92,0),0),0) -> 8667
