Workbook

Sheet COVER
B2: Raise Ready
B3: Personal Finance Workbook
B4: Your complete financial picture in one spreadsheet
B7: HOW TO USE THIS WORKBOOK
B9: Step 01: SETUP | C9: Fill in your income, assets, debts, and monthly expenses on the SETUP tab. Every yellow cell is yours to edit.
B10: Step 02: BUDGET | C10: Review your auto-generated 50/30/20 budget allocation. Adjust category amounts to match your spending.
B11: Step 03: DEBT | C11: See your debt payoff timeline and compare Avalanche vs Snowball strategies.
B12: Step 04: HOUSING | C12: Run Rent vs Buy analysis and check mortgage affordability.
B13: Step 05: INVEST | C13: Model portfolio growth over 10, 20, 30 years with different return assumptions.
B14: Step 06: RETIRE | C14: Calculate your retirement number and see if you are on track.
B15: Step 07: WEALTH | C15: Review your complete net worth dashboard and asset allocation.
B16: Step 08: SUMMARY | C16: See your full financial health score and action items.
B19: COLOUR GUIDE
B20: Blue text = your inputs (edit these)
B21: Black text = formulas (do not edit)
B22: Green text = cross-sheet links
B23: Yellow background = input cells

Sheet SETUP
B1: SETUP — Your Financial Profile
B2: Fill in all yellow cells with your personal data. These flow into every other sheet.
B4: PERSONAL INFORMATION
B5: Name | C5: Your Name
B6: Age | C6: 30
B7: Target Retirement Age | C7: 65
B8: Country | C8: US
B9: Filing Status | C9: Single
B11: INCOME
B12: Gross Annual Salary | C12: 75000
B13: Freelance / Side Income (annual) | C13: 0
B14: Other Income (annual) | C14: 0
B15: Effective Tax Rate (%) | C15: 0.25
B17: Total Gross Income | C17: =C12+C13+C14 -> 75000
B18: Annual Tax | C18: =C17*C15 -> 18750
B19: Net Annual Income | C19: =C17-C18 -> 56250
B20: Net Monthly Income | C20: =C19/12 -> 4687.5
B22: ASSETS
B23: Cash & Savings | C23: 15000
B24: Investments & Stocks | C24: 25000
B25: Retirement Accounts | C25: 45000
B26: Real Estate Value | C26: 0
B27: Vehicles | C27: 12000
B28: Other Assets | C28: 0
B29: Total Assets | C29: =SUM(C23:C28) -> 97000
B31: DEBTS
B32: Debt Type | C32: Balance | D32: APR %
B33: Credit Cards | C33: 5000 | D33: 0.219
B34: Student Loans | C34: 25000 | D34: 0.055
B35: Car Loan | C35: 8000 | D35: 0.069
B36: Mortgage | C36: 0 | D36: 0.065
B37: Personal Loans | C37: 0 | D37: 0.1
B38: Other Debt | C38: 0 | D38: 0.08
B39: Total Debt | C39: =SUM(C33:C38) -> 38000
B41: MONTHLY EXPENSES
B42: Category | C42: Amount | D42: Type
B43: Rent / Mortgage Payment | C43: 1500 | D43: Need
B44: Utilities | C44: 200 | D44: Need
B45: Groceries | C45: 400 | D45: Need
B46: Transportation | C46: 250 | D46: Need
...

Sheet BUDGET
B1: BUDGET — 50/30/20 Allocation
B2: Auto-calculated from your SETUP inputs. Shows target vs actual spending by category.
B4: Net Monthly Income | C4: =SETUP!C20 -> 4687.5
B6: Category | C6: Target % | D6: Target $ | E6: Actual $ | F6: Variance
B7: NEEDS | C7: 50% | D7: =C4*C7 -> 2343.75 | E7: =SETUP!C43+SETUP!C44+SETUP!C45+SETUP!C46+SETUP!C47+SETUP!C48 -> 3000 | F7: =D7-E7 -> -656.25
B9: WANTS | C9: 30% | D9: =C4*C9 -> 1406.25 | E9: =SETUP!C49+SETUP!C50+SETUP!C51+SETUP!C52+SETUP!C53+SETUP!C54 -> 905 | F9: =D9-E9 -> 501.25
B11: SAVINGS & DEBT REPAYMENT | C11: 20% | D11: =C4*C11 -> 937.5 | E11: =SETUP!C55+SETUP!C56+SETUP!C57 -> 1100 | F11: =D11-E11 -> -162.5
B13: Savings Rate | C13: =IF(C4>0,E11/C4,0) -> 0.23466667

Sheet DEBT PAYOFF
B1: DEBT PAYOFF — Avalanche vs Snowball
B2: Shows your debt-to-income ratio and compares payoff strategies.
B4: DEBT OVERVIEW
B5: Debt | C5: Balance | D5: APR | E5: Min Payment | F5: Monthly Interest | G5: Payoff Order (Avalanche)
B6: =SETUP!B33 -> Credit Cards | C6: =SETUP!C33 -> 5000 | D6: =SETUP!D33 -> 0.219 | E6: =IF(C6>0,MAX(C6*D6/12,25),0) -> 91.25 | F6: =C6*D6/12 -> 91.25 | G6: =RANK(D6,D$6:D$11,0) -> 1
B7: =SETUP!B34 -> Student Loans | C7: =SETUP!C34 -> 25000 | D7: =SETUP!D34 -> 0.055 | E7: =IF(C7>0,MAX(C7*D7/12,25),0) -> 114.58333 | F7: =C7*D7/12 -> 114.58333 | G7: =RANK(D7,D$6:D$11,0) -> 6
B8: =SETUP!B35 -> Car Loan | C8: =SETUP!C35 -> 8000 | D8: =SETUP!D35 -> 0.069 | E8: =IF(C8>0,MAX(C8*D8/12,25),0) -> 46 | F8: =C8*D8/12 -> 46 | G8: =RANK(D8,D$6:D$11,0) -> 4
B9: =SETUP!B36 -> Mortgage | C9: =SETUP!C36 -> 0 | D9: =SETUP!D36 -> 0.065 | E9: =IF(C9>0,MAX(C9*D9/12,25),0) -> 0 | F9: =C9*D9/12 -> 0 | G9: =RANK(D9,D$6:D$11,0) -> 5
B10: =SETUP!B37 -> Personal Loans | C10: =SETUP!C37 -> 0 | D10: =SETUP!D37 -> 0.1 | E10: =IF(C10>0,MAX(C10*D10/12,25),0) -> 0 | F10: =C10*D10/12 -> 0 | G10: =RANK(D10,D$6:D$11,0) -> 2
B11: =SETUP!B38 -> Other Debt | C11: =SETUP!C38 -> 0 | D11: =SETUP!D38 -> 0.08 | E11: =IF(C11>0,MAX(C11*D11/12,25),0) -> 0 | F11: =C11*D11/12 -> 0 | G11: =RANK(D11,D$6:D$11,0) -> 3
B13: Total Debt | C13: =SUM(C6:C11) -> 38000
B14: Total Minimum Payments | E14: =SUM(E6:E11) -> 251.83333
B15: Monthly Interest Cost | F15: =SUM(F6:F11) -> 251.83333
B17: KEY RATIOS
B18: Debt-to-Income Ratio | C18: =IF(SETUP!C17>0,C13/SETUP!C17,0) -> 0.50666667 | D18: Target: below 36%
B19: Debt-to-Asset Ratio | C19: =IF(SETUP!C29>0,C13/SETUP!C29,0) -> 0.39175258

Sheet HOUSING
B1: HOUSING — Rent vs Buy Analysis
B2: Compare renting vs buying. Yellow cells = your inputs.
B4: CURRENT RENT SCENARIO
B5: Monthly Rent | C5: 1500
B6: Annual Rent Increase | C6: 0.03
B7: Annual Rent (Year 1) | C7: =C5*12 -> 18000
B9: BUY SCENARIO
B10: Home Price | C10: 350000
B11: Down Payment (%) | C11: 0.2
B12: Mortgage Rate | C12: 0.065
B13: Mortgage Term (years) | C13: 30
B14: Annual Property Tax Rate | C14: 0.012
B15: Annual Insurance | C15: 1800
B16: Monthly HOA | C16: 200
B17: Annual Maintenance (%) | C17: 0.01
B19: CALCULATED MORTGAGE
B20: Down Payment ($) | C20: =C10*C11 -> 70000
B21: Loan Amount | C21: =C10-C20 -> 280000
B22: Monthly Mortgage Payment | C22: =IF(C12>0,-PMT(C12/12,C13*12,C21),0) -> 1769.7905
B23: Monthly Property Tax | C23: =C10*C14/12 -> 350
B24: Monthly Insurance | C24: =C15/12 -> 150
B25: Monthly Maintenance | C25: =C10*C17/12 -> 291.66667
B26: Total Monthly Housing Cost (Buy) | C26: =C22+C23+C24+C16+C25 -> 2761.4571
B28: AFFORDABILITY CHECK
B29: Housing-to-Income Ratio | C29: =IF(SETUP!C20>0,C26/SETUP!C20,0) -> 0.58911085 | D29: Guideline: below 28%
B30: Monthly Savings vs Renting | C30: =C5-C26 -> -1261.4571

Sheet INVEST
B1: INVEST — Growth Projections
B2: See how your investments grow over time with different return assumptions.
B4: INVESTMENT INPUTS
B5: Current Investment Portfolio | C5: =SETUP!C24 -> 25000
B6: Monthly Contribution | C6: 500
B7: Expected Annual Return (%) | C7: 0.08
B9: PORTFOLIO GROWTH
B10: Years | C10: Conservative (6%) | D10: Moderate (8%) | E10: Aggressive (10%) | F10: Your Assumption
B11: 5 | C11: =FV(0.06/12,5*12,-C6,-C5) -> 68606.269 | D11: =FV(0.08/12,5*12,-C6,-C5) -> 73984.571 | E11: =FV(0.1/12,5*12,-C6,-C5) -> 79851.259 | F11: =FV(C7/12,5*12,-C6,-C5) -> 73984.571
B12: 10 | C12: =FV(0.06/12,10*12,-C6,-C5) -> 127424.59 | D12: =FV(0.08/12,10*12,-C6,-C5) -> 146964.02 | E12: =FV(0.1/12,10*12,-C6,-C5) -> 170098.53 | F12: =FV(C7/12,10*12,-C6,-C5) -> 146964.02
B13: 15 | C13: =FV(0.06/12,15*12,-C6,-C5) -> 206761.7 | D13: =FV(0.08/12,15*12,-C6,-C5) -> 255692.15 | E13: =FV(0.1/12,15*12,-C6,-C5) -> 318583.16 | F13: =FV(C7/12,15*12,-C6,-C5) -> 255692.15
B14: 20 | C14: =FV(0.06/12,20*12,-C6,-C5) -> 313775.56 | D14: =FV(0.08/12,20*12,-C6,-C5) -> 417680.28 | E14: =FV(0.1/12,20*12,-C6,-C5) -> 562886.26 | F14: =FV(C7/12,20*12,-C6,-C5) -> 417680.28
B15: 25 | C15: =FV(0.06/12,25*12,-C6,-C5) -> 458121.23 | D15: =FV(0.08/12,25*12,-C6,-C5) -> 659017.6 | E15: =FV(0.1/12,25*12,-C6,-C5) -> 964840.33 | F15: =FV(C7/12,25*12,-C6,-C5) -> 659017.6
B16: 30 | C16: =FV(0.06/12,30*12,-C6,-C5) -> 652821.9 | D16: =FV(0.08/12,30*12,-C6,-C5) -> 1018573 | E16: =FV(0.1/12,30*12,-C6,-C5) -> 1626178.9 | F16: =FV(C7/12,30*12,-C6,-C5) -> 1018573
B18: Total Contributions (30yr) | C18: =C5+C6*12*30 -> 205000
B19: Growth from Returns (30yr) | C19: =F16-C18 -> 813572.97

Sheet RETIRE
B1: RETIRE — Retirement Planning
B2: Are you on track? Based on the 25x rule (annual expenses x 25).
B4: RETIREMENT INPUTS
B5: Current Age | C5: =SETUP!C6 -> 30
B6: Target Retirement Age | C6: =SETUP!C7 -> 65
B7: Years to Retirement | C7: =C6-C5 -> 35
B8: Current Retirement Savings | C8: =SETUP!C25 -> 45000
B9: Monthly Retirement Contribution | C9: 400
B10: Employer Match (monthly) | C10: 200
B11: Expected Return | C11: 0.07
B13: RETIREMENT TARGET
B14: Annual Expenses (current) | C14: =SETUP!C58*12 -> 60060
B15: Retirement Number (25x Rule) | C15: =C14*25 -> 1501500
B17: PROJECTED SAVINGS AT RETIREMENT
B18: Projected Retirement Savings | C18: =IF(C7>0,FV(C11/12,C7*12,-(C9+C10),-C8),C8) -> 1598409.6
B19: Retirement Gap / Surplus | C19: =C18-C15 -> 96909.594
B20: On Track? | C20: =IF(C19>=0,"Yes - on track","Gap - increase savings") -> Yes - on track

Sheet WEALTH
B1: WEALTH — Net Worth Dashboard
B2: Your complete financial snapshot. All data auto-populated from SETUP.
B4: ASSETS
B5: Category | C5: Value | D5: % of Total
B6: Cash & Savings | C6: =SETUP!C23 -> 15000 | D6: =IF(SETUP!C29>0,C6/SETUP!C29,0) -> 0.15463918
B7: Investments & Stocks | C7: =SETUP!C24 -> 25000 | D7: =IF(SETUP!C29>0,C7/SETUP!C29,0) -> 0.25773196
B8: Retirement Accounts | C8: =SETUP!C25 -> 45000 | D8: =IF(SETUP!C29>0,C8/SETUP!C29,0) -> 0.46391753
B9: Real Estate | C9: =SETUP!C26 -> 0 | D9: =IF(SETUP!C29>0,C9/SETUP!C29,0) -> 0
B10: Vehicles | C10: =SETUP!C27 -> 12000 | D10: =IF(SETUP!C29>0,C10/SETUP!C29,0) -> 0.12371134
B11: Other Assets | C11: =SETUP!C28 -> 0 | D11: =IF(SETUP!C29>0,C11/SETUP!C29,0) -> 0
B12: Total Assets | C12: =SUM(C6:C11) -> 97000
B14: LIABILITIES
B15: Total Debt | C15: =SETUP!C39 -> 38000
B17: NET WORTH
B18: Net Worth | C18: =C12-C15 -> 59000
B20: Asset-to-Liability Ratio | C20: =IF(C15>0,C12/C15,0) -> 2.5526316 | D20: Above 2.0x = healthy

Sheet SUMMARY
B1: FINANCIAL HEALTH SUMMARY
B2: All metrics auto-calculated. Green = healthy, needs attention otherwise.
B4: Metric | C4: Value | D4: Status
B5: Net Monthly Income | C5: =SETUP!C20 -> 4687.5
B6: Monthly Expenses | C6: =SETUP!C58 -> 5005
B7: Monthly Surplus | C7: =SETUP!C59 -> -317.5 | D7: =IF(SETUP!C59>=0,"Positive","Negative - overspending") -> Negative - overspending
B8: Savings Rate | C8: =BUDGET!C13 -> 0.23466667 | D8: =IF(BUDGET!C13>=0.2,"20%+ target met","Below 20% target") -> 20%+ target met
B9: Total Assets | C9: =WEALTH!C12 -> 97000
B10: Total Debt | C10: =SETUP!C39 -> 38000
B11: Net Worth | C11: =WEALTH!C18 -> 59000 | D11: =IF(WEALTH!C18>=0,"Positive","Negative net worth") -> Positive
B12: Debt-to-Income | C12: ='DEBT PAYOFF'!C18 -> 0.50666667 | D12: =IF('DEBT PAYOFF'!C18<=0.36,"Healthy (<36%)","High (>36%)") -> High (>36%)
B13: Housing-to-Income | C13: =HOUSING!C29 -> 0.58911085 | D13: =IF(HOUSING!C29<=0.28,"Affordable (<28%)","Stretched (>28%)") -> Stretched (>28%)
B14: Retirement On Track? | C14: =RETIRE!C20 -> Yes - on track | D14: =RETIRE!C20 -> Yes - on track
B15: Retirement Gap | C15: =RETIRE!C19 -> 96909.594 | D15: =IF(RETIRE!C19>=0,"Surplus","Shortfall") -> Surplus
B16: Projected Portfolio (30yr) | C16: =INVEST!F16 -> 1018573
B19: Built with Raise Ready | raisereadybook.com
